Workbook

Sheet Dashboard
A1: 📊 POÄNGUPPFÖLJNING REHAB 2026 — DASHBOARD
A2: {="Sammanfattning alla enheter — Actual vs Budget (Jan–"&INDEX('Enheterna AO VGR'!B2:M2,MATCH(2,1/('Enheterna AO VGR'!B3:M3>0)))&" 2026)"} -> Sammanfattning alla enheter — Actual vs Budget (Jan–Apr 2026)
A4: 🎯 ÖVERGRIPANDE KPI:ER (YTD 2026)
A6: TOTALT ALLA ENHETER | B6: YTD Actual | C6: YTD Budget | D6: Avvikelse | E6: Uppfyllnadsgrad | F6: Senaste mån trend
A7: Stor-GBG (8 enheter) | B7: {=SUMPRODUCT(('Enheterna AO VGR'!B3:M3)*('Enheterna AO VGR'!B3:M3>0))} -> 24943 | C7: {=SUMPRODUCT(('Enheterna AO VGR'!B4:M4)*('Enheterna AO VGR'!B3:M3>0))} -> 29816 | D7: =B7-C7 -> -4873 | E7: =IFERROR(B7/C7,0) -> 0.83656426 | F7: {=IFERROR(INDEX('Enheterna AO VGR'!B3:M3,MATCH(2,1/('Enheterna AO VGR'!B3:M3>0)))-INDEX('Enheterna AO VGR'!B3:M3,MATCH(2,1/('Enheterna AO VGR'!B3:M3>0))-1),0)} -> -602
A8: Tätort (6 enheter) | B8: {=SUMPRODUCT(('Enheterna AO VGR'!B9:M9)*('Enheterna AO VGR'!B9:M9>0))} -> 27496 | C8: {=SUMPRODUCT(('Enheterna AO VGR'!B10:M10)*('Enheterna AO VGR'!B9:M9>0))} -> 30821 | D8: =B8-C8 -> -3325 | E8: =IFERROR(B8/C8,0) -> 0.89211901 | F8: {=IFERROR(INDEX('Enheterna AO VGR'!B9:M9,MATCH(2,1/('Enheterna AO VGR'!B9:M9>0)))-INDEX('Enheterna AO VGR'!B9:M9,MATCH(2,1/('Enheterna AO VGR'!B9:M9>0))-1),0)} -> -73
A11: 🏢 DETALJERAD UPPFÖLJNING PER ENHET
A13: Enhet | B13: ='Enheterna AO VGR'!B2 -> Jan | C13: ='Enheterna AO VGR'!C2 -> Feb | D13: ='Enheterna AO VGR'!D2 -> Mar | E13: ='Enheterna AO VGR'!E2 -> Apr | F13: ='Enheterna AO VGR'!F2 -> Maj | G13: ='Enheterna AO VGR'!G2 -> Jun | H13: ='Enheterna AO VGR'!H2 -> Jul | I13: ='Enheterna AO VGR'!I2 -> Aug | ... M13: ='Enheterna AO VGR'!M2 -> Dec | N13: YTD Actual | O13: YTD Budget | P13: YTD Avvikelse | Q13: Uppfyllnad % | R13: Årsbudget
A14: Frölunda Torg | B14: =IF('Enheterna AO VGR'!B16=0,"",'Enheterna AO VGR'!B16) -> 783 | C14: =IF('Enheterna AO VGR'!C16=0,"",'Enheterna AO VGR'!C16) -> 900 | D14: =IF('Enheterna AO VGR'!D16=0,"",'Enheterna AO VGR'!D16) -> 883 | E14: =IF('Enheterna AO VGR'!E16=0,"",'Enheterna AO VGR'!E16) -> 828 | F14: =IF('Enheterna AO VGR'!F16=0,"",'Enheterna AO VGR'!F16) | G14: =IF('Enheterna AO VGR'!G16=0,"",'Enheterna AO VGR'!G16) | H14: =IF('Enheterna AO VGR'!H16=0,"",'Enheterna AO VGR'!H16) | I14: =IF('Enheterna AO VGR'!I16=0,"",'Enheterna AO VGR'!I16) | ... M14: =IF('Enheterna AO VGR'!M16=0,"",'Enheterna AO VGR'!M16) | N14: =SUM('Enheterna AO VGR'!B16:M16) -> 3394 | O14: {=SUMPRODUCT(('Enheterna AO VGR'!B17:M17)*('Enheterna AO VGR'!B16:M16>0))} -> 4368 | P14: =N14-O14 -> -974 | Q14: =IFERROR(N14/O14,0) -> 0.77701465 | R14: =SUM('Enheterna AO VGR'!B17:M17) -> 12218
A15: Grimmered | B15: =IF('Enheterna AO VGR'!B22=0,"",'Enheterna AO VGR'!B22) -> 754 | C15: =IF('Enheterna AO VGR'!C22=0,"",'Enheterna AO VGR'!C22) -> 884 | D15: =IF('Enheterna AO VGR'!D22=0,"",'Enheterna AO VGR'!D22) -> 1064 | E15: =IF('Enheterna AO VGR'!E22=0,"",'Enheterna AO VGR'!E22) -> 1072 | F15: =IF('Enheterna AO VGR'!F22=0,"",'Enheterna AO VGR'!F22) | G15: =IF('Enheterna AO VGR'!G22=0,"",'Enheterna AO VGR'!G22) | H15: =IF('Enheterna AO VGR'!H22=0,"",'Enheterna AO VGR'!H22) | I15: =IF('Enheterna AO VGR'!I22=0,"",'Enheterna AO VGR'!I22) | ... M15: =IF('Enheterna AO VGR'!M22=0,"",'Enheterna AO VGR'!M22) | N15: =SUM('Enheterna AO VGR'!B22:M22) -> 3774 | O15: {=SUMPRODUCT(('Enheterna AO VGR'!B23:M23)*('Enheterna AO VGR'!B22:M22>0))} -> 4115 | P15: =N15-O15 -> -341 | Q15: =IFERROR(N15/O15,0) -> 0.91713244 | R15: =SUM('Enheterna AO VGR'!B23:M23) -> 11295
A16: Majorna | B16: =IF('Enheterna AO VGR'!B28=0,"",'Enheterna AO VGR'!B28) -> 894 | C16: =IF('Enheterna AO VGR'!C28=0,"",'Enheterna AO VGR'!C28) -> 962 | D16: =IF('Enheterna AO VGR'!D28=0,"",'Enheterna AO VGR'!D28) -> 1003 | E16: =IF('Enheterna AO VGR'!E28=0,"",'Enheterna AO VGR'!E28) -> 836 | F16: =IF('Enheterna AO VGR'!F28=0,"",'Enheterna AO VGR'!F28) | G16: =IF('Enheterna AO VGR'!G28=0,"",'Enheterna AO VGR'!G28) | H16: =IF('Enheterna AO VGR'!H28=0,"",'Enheterna AO VGR'!H28) | I16: =IF('Enheterna AO VGR'!I28=0,"",'Enheterna AO VGR'!I28) | ... M16: =IF('Enheterna AO VGR'!M28=0,"",'Enheterna AO VGR'!M28) | N16: =SUM('Enheterna AO VGR'!B28:M28) -> 3695 | O16: {=SUMPRODUCT(('Enheterna AO VGR'!B29:M29)*('Enheterna AO VGR'!B28:M28>0))} -> 4548 | P16: =N16-O16 -> -853 | Q16: =IFERROR(N16/O16,0) -> 0.81244503 | R16: =SUM('Enheterna AO VGR'!B29:M29) -> 12836
A17: Pedagogen Park | B17: =IF('Enheterna AO VGR'!B34=0,"",'Enheterna AO VGR'!B34) -> 478 | C17: =IF('Enheterna AO VGR'!C34=0,"",'Enheterna AO VGR'!C34) -> 532 | D17: =IF('Enheterna AO VGR'!D34=0,"",'Enheterna AO VGR'!D34) -> 789 | E17: =IF('Enheterna AO VGR'!E34=0,"",'Enheterna AO VGR'!E34) -> 680 | F17: =IF('Enheterna AO VGR'!F34=0,"",'Enheterna AO VGR'!F34) | G17: =IF('Enheterna AO VGR'!G34=0,"",'Enheterna AO VGR'!G34) | H17: =IF('Enheterna AO VGR'!H34=0,"",'Enheterna AO VGR'!H34) | I17: =IF('Enheterna AO VGR'!I34=0,"",'Enheterna AO VGR'!I34) | ... M17: =IF('Enheterna AO VGR'!M34=0,"",'Enheterna AO VGR'!M34) | N17: =SUM('Enheterna AO VGR'!B34:M34) -> 2479 | O17: {=SUMPRODUCT(('Enheterna AO VGR'!B35:M35)*('Enheterna AO VGR'!B34:M34>0))} -> 2725 | P17: =N17-O17 -> -246 | Q17: =IFERROR(N17/O17,0) -> 0.90972477 | R17: =SUM('Enheterna AO VGR'!B35:M35) -> 8580
A18: Åby | B18: =IF('Enheterna AO VGR'!B40=0,"",'Enheterna AO VGR'!B40) -> 926 | C18: =IF('Enheterna AO VGR'!C40=0,"",'Enheterna AO VGR'!C40) -> 1054 | D18: =IF('Enheterna AO VGR'!D40=0,"",'Enheterna AO VGR'!D40) -> 1103 | E18: =IF('Enheterna AO VGR'!E40=0,"",'Enheterna AO VGR'!E40) -> 941 | F18: =IF('Enheterna AO VGR'!F40=0,"",'Enheterna AO VGR'!F40) | G18: =IF('Enheterna AO VGR'!G40=0,"",'Enheterna AO VGR'!G40) | H18: =IF('Enheterna AO VGR'!H40=0,"",'Enheterna AO VGR'!H40) | I18: =IF('Enheterna AO VGR'!I40=0,"",'Enheterna AO VGR'!I40) | ... M18: =IF('Enheterna AO VGR'!M40=0,"",'Enheterna AO VGR'!M40) | N18: =SUM('Enheterna AO VGR'!B40:M40) -> 4024 | O18: {=SUMPRODUCT(('Enheterna AO VGR'!B41:M41)*('Enheterna AO VGR'!B40:M40>0))} -> 4340 | P18: =N18-O18 -> -316 | Q18: =IFERROR(N18/O18,0) -> 0.92718894 | R18: =SUM('Enheterna AO VGR'!B41:M41) -> 12486
A19: Olskroken | B19: =IF('Enheterna AO VGR'!B46=0,"",'Enheterna AO VGR'!B46) -> 554 | C19: =IF('Enheterna AO VGR'!C46=0,"",'Enheterna AO VGR'!C46) -> 488 | D19: =IF('Enheterna AO VGR'!D46=0,"",'Enheterna AO VGR'!D46) -> 628 | E19: =IF('Enheterna AO VGR'!E46=0,"",'Enheterna AO VGR'!E46) -> 754 | F19: =IF('Enheterna AO VGR'!F46=0,"",'Enheterna AO VGR'!F46) | G19: =IF('Enheterna AO VGR'!G46=0,"",'Enheterna AO VGR'!G46) | H19: =IF('Enheterna AO VGR'!H46=0,"",'Enheterna AO VGR'!H46) | I19: =IF('Enheterna AO VGR'!I46=0,"",'Enheterna AO VGR'!I46) | ... M19: =IF('Enheterna AO VGR'!M46=0,"",'Enheterna AO VGR'!M46) | N19: =SUM('Enheterna AO VGR'!B46:M46) -> 2424 | O19: {=SUMPRODUCT(('Enheterna AO VGR'!B47:M47)*('Enheterna AO VGR'!B46:M46>0))} -> 2935 | P19: =N19-O19 -> -511 | Q19: =IFERROR(N19/O19,0) -> 0.82589438 | R19: =SUM('Enheterna AO VGR'!B47:M47) -> 8760
A20: Avenyn | B20: =IF('Enheterna AO VGR'!B52=0,"",'Enheterna AO VGR'!B52) -> 886 | C20: =IF('Enheterna AO VGR'!C52=0,"",'Enheterna AO VGR'!C52) -> 910 | D20: =IF('Enheterna AO VGR'!D52=0,"",'Enheterna AO VGR'!D52) -> 1253 | E20: =IF('Enheterna AO VGR'!E52=0,"",'Enheterna AO VGR'!E52) -> 997 | F20: =IF('Enheterna AO VGR'!F52=0,"",'Enheterna AO VGR'!F52) | G20: =IF('Enheterna AO VGR'!G52=0,"",'Enheterna AO VGR'!G52) | H20: =IF('Enheterna AO VGR'!H52=0,"",'Enheterna AO VGR'!H52) | I20: =IF('Enheterna AO VGR'!I52=0,"",'Enheterna AO VGR'!I52) | ... M20: =IF('Enheterna AO VGR'!M52=0,"",'Enheterna AO VGR'!M52) | N20: =SUM('Enheterna AO VGR'!B52:M52) -> 4046 | O20: {=SUMPRODUCT(('Enheterna AO VGR'!B53:M53)*('Enheterna AO VGR'!B52:M52>0))} -> 4805 | P20: =N20-O20 -> -759 | Q20: =IFERROR(N20/O20,0) -> 0.84203954 | R20: =SUM('Enheterna AO VGR'!B53:M53) -> 14495
A21: Karlastaden | B21: =IF('Enheterna AO VGR'!B58=0,"",'Enheterna AO VGR'!B58) -> 226 | C21: =IF('Enheterna AO VGR'!C58=0,"",'Enheterna AO VGR'!C58) -> 244 | D21: =IF('Enheterna AO VGR'!D58=0,"",'Enheterna AO VGR'!D58) -> 312 | E21: =IF('Enheterna AO VGR'!E58=0,"",'Enheterna AO VGR'!E58) -> 325 | F21: =IF('Enheterna AO VGR'!F58=0,"",'Enheterna AO VGR'!F58) | G21: =IF('Enheterna AO VGR'!G58=0,"",'Enheterna AO VGR'!G58) | H21: =IF('Enheterna AO VGR'!H58=0,"",'Enheterna AO VGR'!H58) | I21: =IF('Enheterna AO VGR'!I58=0,"",'Enheterna AO VGR'!I58) | ... M21: =IF('Enheterna AO VGR'!M58=0,"",'Enheterna AO VGR'!M58) | N21: =SUM('Enheterna AO VGR'!B58:M58) -> 1107 | O21: {=SUMPRODUCT(('Enheterna AO VGR'!B59:M59)*('Enheterna AO VGR'!B58:M58>0))} -> 1980 | P21: =N21-O21 -> -873 | Q21: =IFERROR(N21/O21,0) -> 0.55909091 | R21: =SUM('Enheterna AO VGR'!B59:M59) -> 5562
A22: Tanum och Fjällbacka | B22: =IF('Enheterna AO VGR'!B64=0,"",'Enheterna AO VGR'!B64) -> 1084 | C22: =IF('Enheterna AO VGR'!C64=0,"",'Enheterna AO VGR'!C64) -> 1229 | D22: =IF('Enheterna AO VGR'!D64=0,"",'Enheterna AO VGR'!D64) -> 1389 | E22: =IF('Enheterna AO VGR'!E64=0,"",'Enheterna AO VGR'!E64) -> 1281 | F22: =IF('Enheterna AO VGR'!F64=0,"",'Enheterna AO VGR'!F64) | G22: =IF('Enheterna AO VGR'!G64=0,"",'Enheterna AO VGR'!G64) | H22: =IF('Enheterna AO VGR'!H64=0,"",'Enheterna AO VGR'!H64) | I22: =IF('Enheterna AO VGR'!I64=0,"",'Enheterna AO VGR'!I64) | ... M22: =IF('Enheterna AO VGR'!M64=0,"",'Enheterna AO VGR'!M64) | N22: =SUM('Enheterna AO VGR'!B64:M64) -> 4983 | O22: {=SUMPRODUCT(('Enheterna AO VGR'!B65:M65)*('Enheterna AO VGR'!B64:M64>0))} -> 4394 | P22: =N22-O22 -> 589 | Q22: =IFERROR(N22/O22,0) -> 1.1340464 | R22: =SUM('Enheterna AO VGR'!B65:M65) -> 12786
A23: Brålanda-Torpa | B23: =IF('Enheterna AO VGR'!B70=0,"",'Enheterna AO VGR'!B70) -> 958 | C23: =IF('Enheterna AO VGR'!C70=0,"",'Enheterna AO VGR'!C70) -> 1192 | D23: =IF('Enheterna AO VGR'!D70=0,"",'Enheterna AO VGR'!D70) -> 1076 | E23: =IF('Enheterna AO VGR'!E70=0,"",'Enheterna AO VGR'!E70) -> 1291 | F23: =IF('Enheterna AO VGR'!F70=0,"",'Enheterna AO VGR'!F70) | G23: =IF('Enheterna AO VGR'!G70=0,"",'Enheterna AO VGR'!G70) | H23: =IF('Enheterna AO VGR'!H70=0,"",'Enheterna AO VGR'!H70) | I23: =IF('Enheterna AO VGR'!I70=0,"",'Enheterna AO VGR'!I70) | ... M23: =IF('Enheterna AO VGR'!M70=0,"",'Enheterna AO VGR'!M70) | N23: =SUM('Enheterna AO VGR'!B70:M70) -> 4517 | O23: {=SUMPRODUCT(('Enheterna AO VGR'!B71:M71)*('Enheterna AO VGR'!B70:M70>0))} -> 4985 | P23: =N23-O23 -> -468 | Q23: =IFERROR(N23/O23,0) -> 0.90611836 | R23: =SUM('Enheterna AO VGR'!B71:M71) -> 15655
A24: Noltrop | B24: =IF('Enheterna AO VGR'!B76=0,"",'Enheterna AO VGR'!B76) -> 1371 | C24: =IF('Enheterna AO VGR'!C76=0,"",'Enheterna AO VGR'!C76) -> 1606 | D24: =IF('Enheterna AO VGR'!D76=0,"",'Enheterna AO VGR'!D76) -> 2057 | E24: =IF('Enheterna AO VGR'!E76=0,"",'Enheterna AO VGR'!E76) -> 2018 | F24: =IF('Enheterna AO VGR'!F76=0,"",'Enheterna AO VGR'!F76) | G24: =IF('Enheterna AO VGR'!G76=0,"",'Enheterna AO VGR'!G76) | H24: =IF('Enheterna AO VGR'!H76=0,"",'Enheterna AO VGR'!H76) | I24: =IF('Enheterna AO VGR'!I76=0,"",'Enheterna AO VGR'!I76) | ... M24: =IF('Enheterna AO VGR'!M76=0,"",'Enheterna AO VGR'!M76) | N24: =SUM('Enheterna AO VGR'!B76:M76) -> 7052 | O24: {=SUMPRODUCT(('Enheterna AO VGR'!B77:M77)*('Enheterna AO VGR'!B76:M76>0))} -> 7315 | P24: =N24-O24 -> -263 | Q24: =IFERROR(N24/O24,0) -> 0.96404648 | R24: =SUM('Enheterna AO VGR'!B77:M77) -> 21955
A25: Lilla Edet | B25: =IF('Enheterna AO VGR'!B82=0,"",'Enheterna AO VGR'!B82) -> 718 | C25: =IF('Enheterna AO VGR'!C82=0,"",'Enheterna AO VGR'!C82) -> 526 | D25: =IF('Enheterna AO VGR'!D82=0,"",'Enheterna AO VGR'!D82) -> 528 | E25: =IF('Enheterna AO VGR'!E82=0,"",'Enheterna AO VGR'!E82) -> 509 | F25: =IF('Enheterna AO VGR'!F82=0,"",'Enheterna AO VGR'!F82) | G25: =IF('Enheterna AO VGR'!G82=0,"",'Enheterna AO VGR'!G82) | H25: =IF('Enheterna AO VGR'!H82=0,"",'Enheterna AO VGR'!H82) | I25: =IF('Enheterna AO VGR'!I82=0,"",'Enheterna AO VGR'!I82) | ... M25: =IF('Enheterna AO VGR'!M82=0,"",'Enheterna AO VGR'!M82) | N25: =SUM('Enheterna AO VGR'!B82:M82) -> 2281 | O25: {=SUMPRODUCT(('Enheterna AO VGR'!B83:M83)*('Enheterna AO VGR'!B82:M82>0))} -> 3638 | P25: =N25-O25 -> -1357 | Q25: =IFERROR(N25/O25,0) -> 0.62699285 | R25: =SUM('Enheterna AO VGR'!B83:M83) -> 9870
A26: Stavre | B26: =IF('Enheterna AO VGR'!B88=0,"",'Enheterna AO VGR'!B88) -> 924 | C26: =IF('Enheterna AO VGR'!C88=0,"",'Enheterna AO VGR'!C88) -> 959 | D26: =IF('Enheterna AO VGR'!D88=0,"",'Enheterna AO VGR'!D88) -> 1203 | E26: =IF('Enheterna AO VGR'!E88=0,"",'Enheterna AO VGR'!E88) -> 1146 | F26: =IF('Enheterna AO VGR'!F88=0,"",'Enheterna AO VGR'!F88) | G26: =IF('Enheterna AO VGR'!G88=0,"",'Enheterna AO VGR'!G88) | H26: =IF('Enheterna AO VGR'!H88=0,"",'Enheterna AO VGR'!H88) | I26: =IF('Enheterna AO VGR'!I88=0,"",'Enheterna AO VGR'!I88) | ... M26: =IF('Enheterna AO VGR'!M88=0,"",'Enheterna AO VGR'!M88) | N26: =SUM('Enheterna AO VGR'!B88:M88) -> 4232 | O26: {=SUMPRODUCT(('Enheterna AO VGR'!B89:M89)*('Enheterna AO VGR'!B88:M88>0))} -> 4340 | P26: =N26-O26 -> -108 | Q26: =IFERROR(N26/O26,0) -> 0.97511521 | R26: =SUM('Enheterna AO VGR'!B89:M89) -> 12486
A27: Åmål | B27: =IF('Enheterna AO VGR'!B94=0,"",'Enheterna AO VGR'!B94) -> 934 | C27: =IF('Enheterna AO VGR'!C94=0,"",'Enheterna AO VGR'!C94) -> 1058 | D27: =IF('Enheterna AO VGR'!D94=0,"",'Enheterna AO VGR'!D94) -> 1252 | E27: =IF('Enheterna AO VGR'!E94=0,"",'Enheterna AO VGR'!E94) -> 1187 | F27: =IF('Enheterna AO VGR'!F94=0,"",'Enheterna AO VGR'!F94) | G27: =IF('Enheterna AO VGR'!G94=0,"",'Enheterna AO VGR'!G94) | H27: =IF('Enheterna AO VGR'!H94=0,"",'Enheterna AO VGR'!H94) | I27: =IF('Enheterna AO VGR'!I94=0,"",'Enheterna AO VGR'!I94) | ... M27: =IF('Enheterna AO VGR'!M94=0,"",'Enheterna AO VGR'!M94) | N27: =SUM('Enheterna AO VGR'!B94:M94) -> 4431 | O27: {=SUMPRODUCT(('Enheterna AO VGR'!B95:M95)*('Enheterna AO VGR'!B94:M94>0))} -> 6149 | P27: =N27-O27 -> -1718 | Q27: =IFERROR(N27/O27,0) -> 0.72060498 | R27: =SUM('Enheterna AO VGR'!B95:M95) -> 16692
A29: TOTALT ALLA ENHETER | B29: =SUM(B14:B27) -> 11490 | C29: =SUM(C14:C27) -> 12544 | D29: =SUM(D14:D27) -> 14540 | E29: =SUM(E14:E27) -> 13865 | F29: =SUM(F14:F27) -> 0 | G29: =SUM(G14:G27) -> 0 | H29: =SUM(H14:H27) -> 0 | I29: =SUM(I14:I27) -> 0 | ... P29: =SUM(P14:P27) -> -8198 | Q29: =IFERROR(N29/O29,0) -> 0.86480202 | R29: =SUM(R14:R27) -> 175676
A32: 📈 EKONOMISKA NYCKELTAL (KPI:er)
A34: Bästa enhet (YTD uppfyllnad) | B34: =INDEX(A14:A27,MATCH(MAX(Q14:Q27),Q14:Q27,0)) -> Tanum och Fjällbacka | C34: =MAX(Q14:Q27) -> 1.1340464
A35: Sämsta enhet (YTD uppfyllnad) | B35: =INDEX(A14:A27,MATCH(MIN(Q14:Q27),Q14:Q27,0)) -> Karlastaden | C35: =MIN(Q14:Q27) -> 0.55909091
A37: Genomsnittlig uppfyllnadsgrad | B37: =AVERAGE(Q14:Q27) -> 0.84981821
A38: Median uppfyllnadsgrad | B38: =MEDIAN(Q14:Q27) -> 0.87407895
A40: Enheter över budget (YTD) | B40: =COUNTIF(Q14:Q27,">="&1) -> 1 | C40: av 14
A41: Enheter under budget (YTD) | B41: =COUNTIF(Q14:Q27,"<"&1) -> 13 | C41: av 14
A45: Total YTD avvikelse (poäng) | B45: =P29 -> -8198
A46: Årsbudget totalt | B46: =R29 -> 175676
A47: YTD vs Årsbudget | B47: =N29/R29 -> 0.29849837
A96: 👥 ALLA MEDARBETARE — sortering styrs av månadsväljaren
B98: Välj månad: → | C98: Mar | D98: ← Klicka och välj månad (Jan–Dec eller YTD)
A99: ="🏆 TOP 20 — "&$C$98 -> 🏆 TOP 20 — Mar
A101: # | B101: Namn | C101: Enhet | D101: =$C$98&" poäng" -> Mar poäng | E101: YTD
A102: 1 | B102: =IFERROR(INDEX($A$221:$A$301,MATCH(LARGE($Q$221:$Q$301,1),$Q$221:$Q$301,0)),"") -> Cecilia Lilja | C102: =IFERROR(INDEX($B$221:$B$301,MATCH(LARGE($Q$221:$Q$301,1),$Q$221:$Q$301,0)),"") -> Stavre | D102: =IFERROR(INDEX($P$221:$P$301,MATCH(LARGE($Q$221:$Q$301,1),$Q$221:$Q$301,0)),0) -> 358 | E102: =IFERROR(INDEX($O$221:$O$301,MATCH(LARGE($Q$221:$Q$301,1),$Q$221:$Q$301,0)),0) -> 1083
A103: 2 | B103: =IFERROR(INDEX($A$221:$A$301,MATCH(LARGE($Q$221:$Q$301,2),$Q$221:$Q$301,0)),"") -> Sanna Åstrand | C103: =IFERROR(INDEX($B$221:$B$301,MATCH(LARGE($Q$221:$Q$301,2),$Q$221:$Q$301,0)),"") -> Noltrop | D103: =IFERROR(INDEX($P$221:$P$301,MATCH(LARGE($Q$221:$Q$301,2),$Q$221:$Q$301,0)),0) -> 355 | E103: =IFERROR(INDEX($O$221:$O$301,MATCH(LARGE($Q$221:$Q$301,2),$Q$221:$Q$301,0)),0) -> 1189
A104: 3 | B104: =IFERROR(INDEX($A$221:$A$301,MATCH(LARGE($Q$221:$Q$301,3),$Q$221:$Q$301,0)),"") -> Ruurd Visser | C104: =IFERROR(INDEX($B$221:$B$301,MATCH(LARGE($Q$221:$Q$301,3),$Q$221:$Q$301,0)),"") -> Åmål | D104: =IFERROR(INDEX($P$221:$P$301,MATCH(LARGE($Q$221:$Q$301,3),$Q$221:$Q$301,0)),0) -> 353 | E104: =IFERROR(INDEX($O$221:$O$301,MATCH(LARGE($Q$221:$Q$301,3),$Q$221:$Q$301,0)),0) -> 1074
...

Sheet Prognos April
A1: 📈 PROGNOS APRIL 2026
A2: Baserat på 14 av 20 arbetsdagar registrerade (6 dagar kvar)
A4: 🎯 ANTAGANDEN
A5: Arbetsdagar april totalt | B5: 20
A6: Arbetsdagar gjorda | B6: 14
A7: Arbetsdagar kvar | B7: =B5-B6 -> 6
A8: Arbetsdagar Q1 | B8: 63
A10: 🏢 PROGNOS PER ENHET
A12: Enhet | B12: April hittills | C12: Q1 Actual | D12: Dagstakt april | E12: Dagstakt Q1 | F12: Blandad takt | G12: Prognos 6 dagar | H12: Prognos april | I12: Budget april | J12: Avvikelse | K12: Uppfyllnad %
A13: Frölunda Torg | B13: ='Enheterna AO VGR'!E16 -> 828 | C13: =SUM('Enheterna AO VGR'!B16:D16) -> 2566 | D13: =B13/$B$6 -> 59.142857 | E13: =C13/$B$8 -> 40.730159 | F13: =(D13+E13)/2 -> 49.936508 | G13: =F13*$B$7 -> 299.61905 | H13: =B13+G13 -> 1127.619 | I13: ='Enheterna AO VGR'!E17 -> 1066 | J13: =H13-I13 -> 61.619048 | K13: =H13/I13 -> 1.057804
A14: Grimmered | B14: ='Enheterna AO VGR'!E22 -> 1072 | C14: =SUM('Enheterna AO VGR'!B22:D22) -> 2702 | D14: =B14/$B$6 -> 76.571429 | E14: =C14/$B$8 -> 42.888889 | F14: =(D14+E14)/2 -> 59.730159 | G14: =F14*$B$7 -> 358.38095 | H14: =B14+G14 -> 1430.381 | I14: ='Enheterna AO VGR'!E23 -> 1020 | J14: =H14-I14 -> 410.38095 | K14: =H14/I14 -> 1.4023343
A15: Majorna | B15: ='Enheterna AO VGR'!E28 -> 836 | C15: =SUM('Enheterna AO VGR'!B28:D28) -> 2859 | D15: =B15/$B$6 -> 59.714286 | E15: =C15/$B$8 -> 45.380952 | F15: =(D15+E15)/2 -> 52.547619 | G15: =F15*$B$7 -> 315.28571 | H15: =B15+G15 -> 1151.2857 | I15: ='Enheterna AO VGR'!E29 -> 1232 | J15: =H15-I15 -> -80.714286 | K15: =H15/I15 -> 0.93448516
A16: Pedagogen Park | B16: ='Enheterna AO VGR'!E34 -> 680 | C16: =SUM('Enheterna AO VGR'!B34:D34) -> 1799 | D16: =B16/$B$6 -> 48.571429 | E16: =C16/$B$8 -> 28.555556 | F16: =(D16+E16)/2 -> 38.563492 | G16: =F16*$B$7 -> 231.38095 | H16: =B16+G16 -> 911.38095 | I16: ='Enheterna AO VGR'!E35 -> 735 | J16: =H16-I16 -> 176.38095 | K16: =H16/I16 -> 1.2399741
A17: Åby | B17: ='Enheterna AO VGR'!E40 -> 941 | C17: =SUM('Enheterna AO VGR'!B40:D40) -> 3083 | D17: =B17/$B$6 -> 67.214286 | E17: =C17/$B$8 -> 48.936508 | F17: =(D17+E17)/2 -> 58.075397 | G17: =F17*$B$7 -> 348.45238 | H17: =B17+G17 -> 1289.4524 | I17: ='Enheterna AO VGR'!E41 -> 1050 | J17: =H17-I17 -> 239.45238 | K17: =H17/I17 -> 1.2280499
A18: Olskroken | B18: ='Enheterna AO VGR'!E46 -> 754 | C18: =SUM('Enheterna AO VGR'!B46:D46) -> 1670 | D18: =B18/$B$6 -> 53.857143 | E18: =C18/$B$8 -> 26.507937 | F18: =(D18+E18)/2 -> 40.18254 | G18: =F18*$B$7 -> 241.09524 | H18: =B18+G18 -> 995.09524 | I18: ='Enheterna AO VGR'!E47 -> 805 | J18: =H18-I18 -> 190.09524 | K18: =H18/I18 -> 1.2361432
A19: Avenyn | B19: ='Enheterna AO VGR'!E52 -> 997 | C19: =SUM('Enheterna AO VGR'!B52:D52) -> 3049 | D19: =B19/$B$6 -> 71.214286 | E19: =C19/$B$8 -> 48.396825 | F19: =(D19+E19)/2 -> 59.805556 | G19: =F19*$B$7 -> 358.83333 | H19: =B19+G19 -> 1355.8333 | I19: ='Enheterna AO VGR'!E53 -> 1180 | J19: =H19-I19 -> 175.83333 | K19: =H19/I19 -> 1.1490113
A20: Karlastaden | B20: ='Enheterna AO VGR'!E58 -> 325 | C20: =SUM('Enheterna AO VGR'!B58:D58) -> 782 | D20: =B20/$B$6 -> 23.214286 | E20: =C20/$B$8 -> 12.412698 | F20: =(D20+E20)/2 -> 17.813492 | G20: =F20*$B$7 -> 106.88095 | H20: =B20+G20 -> 431.88095 | I20: ='Enheterna AO VGR'!E59 -> 520 | J20: =H20-I20 -> -88.119048 | K20: =H20/I20 -> 0.83054029
A21: Tanum och Fjällbacka | B21: ='Enheterna AO VGR'!E64 -> 1281 | C21: =SUM('Enheterna AO VGR'!B64:D64) -> 3702 | D21: =B21/$B$6 -> 91.5 | E21: =C21/$B$8 -> 58.761905 | F21: =(D21+E21)/2 -> 75.130952 | G21: =F21*$B$7 -> 450.78571 | H21: =B21+G21 -> 1731.7857 | I21: ='Enheterna AO VGR'!E65 -> 1126 | J21: =H21-I21 -> 605.78571 | K21: =H21/I21 -> 1.537998
A22: Brålanda-Torpa | B22: ='Enheterna AO VGR'!E70 -> 1291 | C22: =SUM('Enheterna AO VGR'!B70:D70) -> 3226 | D22: =B22/$B$6 -> 92.214286 | E22: =C22/$B$8 -> 51.206349 | F22: =(D22+E22)/2 -> 71.710317 | G22: =F22*$B$7 -> 430.2619 | H22: =B22+G22 -> 1721.2619 | I22: ='Enheterna AO VGR'!E71 -> 1210 | J22: =H22-I22 -> 511.2619 | K22: =H22/I22 -> 1.4225305
A23: Noltrop | B23: ='Enheterna AO VGR'!E76 -> 2018 | C23: =SUM('Enheterna AO VGR'!B76:D76) -> 5034 | D23: =B23/$B$6 -> 144.14286 | E23: =C23/$B$8 -> 79.904762 | F23: =(D23+E23)/2 -> 112.02381 | G23: =F23*$B$7 -> 672.14286 | H23: =B23+G23 -> 2690.1429 | I23: ='Enheterna AO VGR'!E77 -> 1923 | J23: =H23-I23 -> 767.14286 | K23: =H23/I23 -> 1.3989302
A24: Lilla Edet | B24: ='Enheterna AO VGR'!E82 -> 509 | C24: =SUM('Enheterna AO VGR'!B82:D82) -> 1772 | D24: =B24/$B$6 -> 36.357143 | E24: =C24/$B$8 -> 28.126984 | F24: =(D24+E24)/2 -> 32.242063 | G24: =F24*$B$7 -> 193.45238 | H24: =B24+G24 -> 702.45238 | I24: ='Enheterna AO VGR'!E83 -> 924 | J24: =H24-I24 -> -221.54762 | K24: =H24/I24 -> 0.76022985
A25: Stavre | B25: ='Enheterna AO VGR'!E88 -> 1146 | C25: =SUM('Enheterna AO VGR'!B88:D88) -> 3086 | D25: =B25/$B$6 -> 81.857143 | E25: =C25/$B$8 -> 48.984127 | F25: =(D25+E25)/2 -> 65.420635 | G25: =F25*$B$7 -> 392.52381 | H25: =B25+G25 -> 1538.5238 | I25: ='Enheterna AO VGR'!E89 -> 1050 | J25: =H25-I25 -> 488.52381 | K25: =H25/I25 -> 1.4652608
A26: Åmål | B26: ='Enheterna AO VGR'!E94 -> 1187 | C26: =SUM('Enheterna AO VGR'!B94:D94) -> 3244 | D26: =B26/$B$6 -> 84.785714 | E26: =C26/$B$8 -> 51.492063 | F26: =(D26+E26)/2 -> 68.138889 | G26: =F26*$B$7 -> 408.83333 | H26: =B26+G26 -> 1595.8333 | I26: ='Enheterna AO VGR'!E95 -> 1495 | J26: =H26-I26 -> 100.83333 | K26: =H26/I26 -> 1.067447
A28: TOTALT ALLA ENHETER | B28: =SUM(B13:B26) -> 13865 | C28: =SUM(C13:C26) -> 38574 | D28: =B28/$B$6 -> 990.35714 | E28: =C28/$B$8 -> 612.28571 | F28: =(D28+E28)/2 -> 801.32143 | G28: =SUM(G13:G26) -> 4807.9286 | H28: =SUM(H13:H26) -> 18672.929 | I28: =SUM(I13:I26) -> 15336 | J28: =H28-I28 -> 3336.9286 | K28: =H28/I28 -> 1.2175879
A30: 📊 SAMMANFATTNING
A32: Prognos april (totalt) | B32: =H28 -> 18672.929
A33: Budget april | B33: =I28 -> 15336
A34: Avvikelse | B34: =J28 -> 3336.9286
A35: Uppfyllnadsgrad | B35: =K28 -> 1.2175879
A37: Enheter över budget | B37: =COUNTIF(K13:K26,">=1") -> 11
A38: Enheter under budget | B38: =COUNTIF(K13:K26,"<1") -> 3
A39: Bästa enhet | B39: =INDEX(A13:A26,MATCH(MAX(K13:K26),K13:K26,0)) -> Tanum och Fjällbacka
A40: Sämsta enhet | B40: =INDEX(A13:A26,MATCH(MIN(K13:K26),K13:K26,0)) -> Lilla Edet

Sheet Enheterna AO VGR
A1: Uttag poäng datum; | B1: 46063 | C1: 46086 | D1: 46106
A2: Skillnad poäng (ACT) och poäng (Budget) Stor-GBG | B2: Jan | C2: Feb | D2: Mar | E2: Apr | F2: Maj | G2: Jun | H2: Jul | I2: Aug | J2: Sep | K2: Okt | L2: Nov | M2: Dec
A3: Poäng ACTUAL | B3: =B16+B22+B28+B34+B40+B46+B52+B58 -> 5501 | C3: =C16+C22+C28+C34+C40+C46+C52+C58 -> 5974 | D3: =D16+D22+D28+D34+D40+D46+D52+D58 -> 7035 | E3: =E16+E22+E28+E34+E40+E46+E52+E58 -> 6433 | F3: =F16+F22+F28+F34+F40+F46+F52+F58 -> 0 | G3: =G16+G22+G28+G34+G40+G46+G52+G58 -> 0 | H3: =H16+H22+H28+H34+H40+H46+H52+H58 -> 0 | I3: =I16+I22+I28+I34+I40+I46+I52+I58 -> 0 | ... M3: =M16+M22+M28+M34+M40+M46+M52+M58 -> 0
A4: Poäng Budget | B4: =B17+B23+B29+B35+B41+B47+B53+B59 -> 6849 | C4: =C17+C23+C29+C35+C41+C47+C53+C59 -> 7385 | D4: =D17+D23+D29+D35+D41+D47+D53+D59 -> 7974 | E4: =E17+E23+E29+E35+E41+E47+E53+E59 -> 7608 | F4: =F17+F23+F29+F35+F41+F47+F53+F59 -> 7968 | G4: =G17+G23+G29+G35+G41+G47+G53+G59 -> 7390 | H4: =H17+H23+H29+H35+H41+H47+H53+H59 -> 3621 | I4: =I17+I23+I29+I35+I41+I47+I53+I59 -> 5280 | ... M4: =M17+M23+M29+M35+M41+M47+M53+M59 -> 7005
A5: Skillnad | B5: =B3-B4 -> -1348 | C5: =C3-C4 -> -1411 | D5: =D3-D4 -> -939 | E5: =E3-E4 -> -1175 | F5: =F3-F4 -> -7968 | G5: =G3-G4 -> -7390 | H5: =H3-H4 -> -3621 | I5: =I3-I4 -> -5280 | ... M5: =M3-M4 -> -7005
A6: % avvik mot Budget | B6: =SUM(B5/B4) -> -0.19681705 | C6: =SUM(C5/C4) -> -0.19106297 | D6: =SUM(D5/D4) -> -0.11775771 | E6: =SUM(E5/E4) -> -0.15444269 | F6: =SUM(F5/F4) -> -1 | G6: =SUM(G5/G4) -> -1 | H6: =SUM(H5/H4) -> -1 | I6: =SUM(I5/I4) -> -1 | ... M6: =SUM(M5/M4) -> -1
A8: Skillnad poäng (ACT) och poäng (Budget) Tätort | B8: Jan | C8: Feb | D8: Mar | E8: Apr | F8: Maj | G8: Jun | H8: Jul | I8: Aug | J8: Sep | K8: Okt | L8: Nov | M8: Dec
A9: Poäng ACTUAL | B9: =B64+B70+B76+B82+B88+B94 -> 5989 | C9: =C64+C70+C76+C82+C88+C94 -> 6570 | D9: =D64+D70+D76+D82+D88+D94 -> 7505 | E9: =E64+E70+E76+E82+E88+E94 -> 7432 | F9: =F64+F70+F76+F82+F88+F94 -> 0 | G9: =G64+G70+G76+G82+G88+G94 -> 0 | H9: =H64+H70+H76+H82+H88+H94 -> 0 | I9: =I64+I70+I76+I82+I88+I94 -> 0 | ... M9: =M64+M70+M76+M82+M88+M94 -> 0
A10: Poäng Budget | B10: =B65+B71+B77+B83+B89+B95 -> 7192 | C10: =C65+C71+C77+C83+C89+C95 -> 7683 | D10: =D65+D71+D77+D83+D89+D95 -> 8218 | E10: =E65+E71+E77+E83+E89+E95 -> 7728 | F10: =F65+F71+F77+F83+F89+F95 -> 7960 | G10: =G65+G71+G77+G83+G89+G95 -> 6596 | H10: =H65+H71+H77+H83+H89+H95 -> 3844 | I10: =I65+I71+I77+I83+I89+I95 -> 6062 | ... M10: =M65+M71+M77+M83+M89+M95 -> 7805
A11: Skillnad | B11: =B9-B10 -> -1203 | C11: =C9-C10 -> -1113 | D11: =D9-D10 -> -713 | E11: =E9-E10 -> -296 | F11: =F9-F10 -> -7960 | G11: =G9-G10 -> -6596 | H11: =H9-H10 -> -3844 | I11: =I9-I10 -> -6062 | ... M11: =M9-M10 -> -7805
A12: % avvik mot Budget | B12: =SUM(B11/B10) -> -0.16726919 | C12: =SUM(C11/C10) -> -0.14486529 | D12: =SUM(D11/D10) -> -0.086760769 | E12: =SUM(E11/E10) -> -0.038302277 | F12: =SUM(F11/F10) -> -1 | G12: =SUM(G11/G10) -> -1 | H12: =SUM(H11/H10) -> -1 | I12: =SUM(I11/I10) -> -1 | ... M12: =SUM(M11/M10) -> -1
A14: Enheterna;
A15: Frölunda Torget | B15: Jan | C15: Feb | D15: Mar | E15: Apr | F15: Maj | G15: Jun | H15: Jul | I15: Aug | J15: Sep | K15: Okt | L15: Nov | M15: Dec
A16: Poäng ACTUAL | B16: ='Frölunda Torg'!B18 -> 783 | C16: ='Frölunda Torg'!C18 -> 900 | D16: ='Frölunda Torg'!D18 -> 883 | E16: ='Frölunda Torg'!E18 -> 828 | F16: ='Frölunda Torg'!F18 -> 0 | G16: ='Frölunda Torg'!G18 -> 0 | H16: ='Frölunda Torg'!H18 -> 0 | I16: ='Frölunda Torg'!I18 -> 0 | ... M16: ='Frölunda Torg'!M18 -> 0
A17: Poäng Budget | B17: ='Frölunda Torg'!B39 -> 1120 | C17: ='Frölunda Torg'!C39 -> 1076 | D17: ='Frölunda Torg'!D39 -> 1106 | E17: ='Frölunda Torg'!E39 -> 1066 | F17: ='Frölunda Torg'!F39 -> 1076 | G17: ='Frölunda Torg'!G39 -> 1010 | H17: ='Frölunda Torg'!H39 -> 456 | I17: ='Frölunda Torg'!I39 -> 720 | ... M17: ='Frölunda Torg'!M39 -> 1040
A18: Skillnad | B18: =B16-B17 -> -337 | C18: =C16-C17 -> -176 | D18: =D16-D17 -> -223 | E18: =E16-E17 -> -238 | F18: =F16-F17 -> -1076 | G18: =G16-G17 -> -1010 | H18: =H16-H17 -> -456 | I18: =I16-I17 -> -720 | ... M18: =M16-M17 -> -1040
A19: % avvik mot Budget | B19: =SUM(B18/B17) -> -0.30089286 | C19: =SUM(C18/C17) -> -0.16356877 | D19: =SUM(D18/D17) -> -0.20162749 | E19: =SUM(E18/E17) -> -0.22326454 | F19: =SUM(F18/F17) -> -1 | G19: =SUM(G18/G17) -> -1 | H19: =SUM(H18/H17) -> -1 | I19: =SUM(I18/I17) -> -1 | ... M19: =SUM(M18/M17) -> -1
A21: Grimmered | B21: Jan | C21: Feb | D21: Mar | E21: Apr | F21: Maj | G21: Jun | H21: Jul | I21: Aug | J21: Sep | K21: Okt | L21: Nov | M21: Dec
A22: Poäng ACTUAL | B22: =SUM(Grimmered!B18) -> 754 | C22: =SUM(Grimmered!C18) -> 884 | D22: =SUM(Grimmered!D18) -> 1064 | E22: =SUM(Grimmered!E18) -> 1072 | F22: =SUM(Grimmered!F18) -> 0 | G22: =SUM(Grimmered!G18) -> 0 | H22: =SUM(Grimmered!H18) -> 0 | I22: =SUM(Grimmered!I18) -> 0 | ... M22: =SUM(Grimmered!M18) -> 0
A23: Poäng Budget | B23: =SUM(Grimmered!B39) -> 1005 | C23: =SUM(Grimmered!C39) -> 1045 | D23: =SUM(Grimmered!D39) -> 1045 | E23: =SUM(Grimmered!E39) -> 1020 | F23: =SUM(Grimmered!F39) -> 1025 | G23: =SUM(Grimmered!G39) -> 1045 | H23: =SUM(Grimmered!H39) -> 500 | I23: =SUM(Grimmered!I39) -> 530 | ... M23: =SUM(Grimmered!M39) -> 960
A24: Skillnad | B24: =B22-B23 -> -251 | C24: =C22-C23 -> -161 | D24: =D22-D23 -> 19 | E24: =E22-E23 -> 52 | F24: =F22-F23 -> -1025 | G24: =G22-G23 -> -1045 | H24: =H22-H23 -> -500 | I24: =I22-I23 -> -530 | ... M24: =M22-M23 -> -960
A25: % avvik mot Budget | B25: =SUM(B24/B23) -> -0.24975124 | C25: =SUM(C24/C23) -> -0.15406699 | D25: =SUM(D24/D23) -> 0.018181818 | E25: =SUM(E24/E23) -> 0.050980392 | F25: =SUM(F24/F23) -> -1 | G25: =SUM(G24/G23) -> -1 | H25: =SUM(H24/H23) -> -1 | I25: =SUM(I24/I23) -> -1 | ... M25: =SUM(M24/M23) -> -1
A27: Majorna | B27: Jan | C27: Feb | D27: Mar | E27: Apr | F27: Maj | G27: Jun | H27: Jul | I27: Aug | J27: Sep | K27: Okt | L27: Nov | M27: Dec
A28: Poäng ACTUAL | B28: =SUM(Majorna!B18) -> 894 | C28: =SUM(Majorna!C18) -> 962 | D28: =SUM(Majorna!D18) -> 1003 | E28: =SUM(Majorna!E18) -> 836 | F28: =SUM(Majorna!F18) -> 0 | G28: =SUM(Majorna!G18) -> 0 | H28: =SUM(Majorna!H18) -> 0 | I28: =SUM(Majorna!I18) -> 0 | ... M28: =SUM(Majorna!M18) -> 0
A29: Poäng Budget | B29: =SUM(Majorna!B39) -> 987 | C29: =SUM(Majorna!C39) -> 1132 | D29: =SUM(Majorna!D39) -> 1197 | E29: =SUM(Majorna!E39) -> 1232 | F29: =SUM(Majorna!F39) -> 1242 | G29: =SUM(Majorna!G39) -> 1020 | H29: =SUM(Majorna!H39) -> 560 | I29: =SUM(Majorna!I39) -> 660 | ... M29: =SUM(Majorna!M39) -> 1050
A30: Skillnad | B30: =B28-B29 -> -93 | C30: =C28-C29 -> -170 | D30: =D28-D29 -> -194 | E30: =E28-E29 -> -396 | F30: =F28-F29 -> -1242 | G30: =G28-G29 -> -1020 | H30: =H28-H29 -> -560 | I30: =I28-I29 -> -660 | ... M30: =M28-M29 -> -1050
A31: % avvik mot Budget | B31: =SUM(B30/B29) -> -0.094224924 | C31: =SUM(C30/C29) -> -0.15017668 | D31: =SUM(D30/D29) -> -0.16207185 | E31: =SUM(E30/E29) -> -0.32142857 | F31: =SUM(F30/F29) -> -1 | G31: =SUM(G30/G29) -> -1 | H31: =SUM(H30/H29) -> -1 | I31: =SUM(I30/I29) -> -1 | ... M31: =SUM(M30/M29) -> -1
A33: Pedagogen Park | B33: Jan | C33: Feb | D33: Mar | E33: Apr | F33: Maj | G33: Jun | H33: Jul | I33: Aug | J33: Sep | K33: Okt | L33: Nov | M33: Dec
A34: Poäng ACTUAL | B34: ='Pedagogen Park'!B18 -> 478 | C34: ='Pedagogen Park'!C18 -> 532 | D34: ='Pedagogen Park'!D18 -> 789 | E34: ='Pedagogen Park'!E18 -> 680 | F34: ='Pedagogen Park'!F18 -> 0 | G34: ='Pedagogen Park'!G18 -> 0 | H34: ='Pedagogen Park'!H18 -> 0 | I34: ='Pedagogen Park'!I18 -> 0 | ... M34: ='Pedagogen Park'!M18 -> 0
A35: Poäng Budget | B35: ='Pedagogen Park'!B39 -> 600 | C35: ='Pedagogen Park'!C39 -> 660 | D35: ='Pedagogen Park'!D39 -> 730 | E35: ='Pedagogen Park'!E39 -> 735 | F35: ='Pedagogen Park'!F39 -> 760 | G35: ='Pedagogen Park'!G39 -> 800 | H35: ='Pedagogen Park'!H39 -> 600 | I35: ='Pedagogen Park'!I39 -> 660 | ... M35: ='Pedagogen Park'!M39 -> 675
A36: Skillnad | B36: =B34-B35 -> -122 | C36: =C34-C35 -> -128 | D36: =D34-D35 -> 59 | E36: =E34-E35 -> -55 | F36: =F34-F35 -> -760 | G36: =G34-G35 -> -800 | H36: =H34-H35 -> -600 | I36: =I34-I35 -> -660 | ... M36: =M34-M35 -> -675
A37: % avvik mot Budget | B37: =SUM(B36/B35) -> -0.20333333 | C37: =SUM(C36/C35) -> -0.19393939 | D37: =SUM(D36/D35) -> 0.080821918 | E37: =SUM(E36/E35) -> -0.074829932 | F37: =SUM(F36/F35) -> -1 | G37: =SUM(G36/G35) -> -1 | H37: =SUM(H36/H35) -> -1 | I37: =SUM(I36/I35) -> -1 | ... M37: =SUM(M36/M35) -> -1
A39: Åby | B39: Jan | C39: Feb | D39: Mar | E39: Apr | F39: Maj | G39: Jun | H39: Jul | I39: Aug | J39: Sep | K39: Okt | L39: Nov | M39: Dec
A40: Poäng ACTUAL | B40: =SUM(Åby!B18) -> 926 | C40: =SUM(Åby!C18) -> 1054 | D40: =SUM(Åby!D18) -> 1103 | E40: =SUM(Åby!E18) -> 941 | F40: =SUM(Åby!F18) -> 0 | G40: =SUM(Åby!G18) -> 0 | H40: =SUM(Åby!H18) -> 0 | I40: =SUM(Åby!I18) -> 0 | ... M40: =SUM(Åby!M18) -> 0
A41: Poäng Budget | B41: =SUM(Åby!B39) -> 890 | C41: =SUM(Åby!C39) -> 1105 | D41: =SUM(Åby!D39) -> 1295 | E41: =SUM(Åby!E39) -> 1050 | F41: =SUM(Åby!F39) -> 1180 | G41: =SUM(Åby!G39) -> 890 | H41: =SUM(Åby!H39) -> 240 | I41: =SUM(Åby!I39) -> 1040 | ... M41: =SUM(Åby!M39) -> 1040
A42: Skillnad | B42: =B40-B41 -> 36 | C42: =C40-C41 -> -51 | D42: =D40-D41 -> -192 | E42: =E40-E41 -> -109 | F42: =F40-F41 -> -1180 | G42: =G40-G41 -> -890 | H42: =H40-H41 -> -240 | I42: =I40-I41 -> -1040 | ... M42: =M40-M41 -> -1040
A43: % avvik mot Budget | B43: =SUM(B42/B41) -> 0.040449438 | C43: =SUM(C42/C41) -> -0.046153846 | D43: =SUM(D42/D41) -> -0.14826255 | E43: =SUM(E42/E41) -> -0.10380952 | F43: =SUM(F42/F41) -> -1 | G43: =SUM(G42/G41) -> -1 | H43: =SUM(H42/H41) -> -1 | I43: =SUM(I42/I41) -> -1 | ... M43: =SUM(M42/M41) -> -1
A45: Olskroken | B45: Jan | C45: Feb | D45: Mar | E45: Apr | F45: Maj | G45: Jun | H45: Jul | I45: Aug | J45: Sep | K45: Okt | L45: Nov | M45: Dec
A46: Poäng ACTUAL | B46: =SUM(Olskroken!B18) -> 554 | C46: =SUM(Olskroken!C18) -> 488 | D46: =SUM(Olskroken!D18) -> 628 | E46: =SUM(Olskroken!E18) -> 754 | F46: =SUM(Olskroken!F18) -> 0 | G46: =SUM(Olskroken!G18) -> 0 | H46: =SUM(Olskroken!H18) -> 0 | I46: =SUM(Olskroken!I18) -> 0 | ... M46: =SUM(Olskroken!M18) -> 0
A47: Poäng Budget | B47: =SUM(Olskroken!B39) -> 625 | C47: =SUM(Olskroken!C39) -> 710 | D47: =SUM(Olskroken!D39) -> 795 | E47: =SUM(Olskroken!E39) -> 805 | F47: =SUM(Olskroken!F39) -> 875 | G47: =SUM(Olskroken!G39) -> 845 | H47: =SUM(Olskroken!H39) -> 380 | I47: =SUM(Olskroken!I39) -> 545 | ... M47: =SUM(Olskroken!M39) -> 660
...

Sheet Frölunda Torg
A1: Uttag poäng datum; | B1: 46063 | C1: 46086
B2: Jan | C2: Feb | D2: Mar | E2: Apr | F2: Maj | G2: Jun | H2: Jul | I2: Aug | J2: Sep | K2: Okt | L2: Nov | M2: Dec
B3: Actual | C3: Actual | D3: Actual | E3: Actual | F3: Actual | G3: Actual | H3: Actual | I3: Actual | J3: Actual | K3: Actual | L3: Actual | M3: Actual
A4: Pontus Berglund | B4: 138 | C4: 82
A5: Anders Esko | B5: 178 | C5: 156 | D5: 188 | E5: 181
A6: Albert Lindström | B6: 112 | C6: 179 | D6: 184 | E6: 141
A7: Rana Baratifar | B7: 91 | C7: 164 | D7: 145 | E7: 154
A8: Annelie Corell | B8: 139 | C8: 190 | D8: 194 | E8: 164
A9: Louise From | B9: 125 | C9: 52
A10: Simon Lageson | C10: 77 | D10: 172 | E10: 188
B18: =SUM(B4:B17) -> 783 | C18: =SUM(C4:C17) -> 900 | D18: =SUM(D4:D17) -> 883 | E18: =SUM(E4:E17) -> 828 | F18: =SUM(F4:F17) -> 0 | G18: =SUM(G4:G17) -> 0 | H18: =SUM(H4:H17) -> 0 | I18: =SUM(I4:I17) -> 0 | ... M18: =SUM(M4:M17) -> 0
B20: Jan | C20: Feb | D20: Mar | E20: Apr | F20: Maj | G20: Jun | H20: Jul | I20: Aug | J20: Sep | K20: Okt | L20: Nov | M20: Dec
B21: Diff | C21: Diff | D21: Diff | E21: Diff | F21: Diff | G21: Diff | H21: Diff | I21: Diff | J21: Diff | K21: Diff | L21: Diff | M21: Diff
A22: Pontus Berglund | B22: =SUM(B4-B40) -> -82 | C22: =SUM(C4-C40) -> -48 | D22: =SUM(D4-D40) -> -140 | E22: =SUM(E4-E40) -> -130 | F22: =SUM(F4-F40) -> 0 | G22: =SUM(G4-G40) -> 0 | H22: =SUM(H4-H40) -> 0 | I22: =SUM(I4-I40) -> 0 | ... M22: =SUM(M4-M40) -> 0
A23: Anders Esko | B23: =SUM(B5-B41) -> -42 | C23: =SUM(C5-C41) -> -74 | D23: =SUM(D5-D41) -> -42 | E23: =SUM(E5-E41) -> -49 | F23: =SUM(F5-F41) -> -230 | G23: =SUM(G5-G41) -> -120 | H23: =SUM(H5-H41) -> -180 | I23: =SUM(I5-I41) -> -120 | ... M23: =SUM(M5-M41) -> -200
A24: Albert Lindström | B24: =SUM(B6-B42) -> -98 | C24: =SUM(C6-C42) -> -51 | D24: =SUM(D6-D42) -> -46 | E24: =SUM(E6-E42) -> -79 | F24: =SUM(F6-F42) -> -220 | G24: =SUM(G6-G42) -> -220 | H24: =SUM(H6-H42) -> 0 | I24: =SUM(I6-I42) -> -220 | ... M24: =SUM(M6-M42) -> -190
A25: Rana Baratifar | B25: =SUM(B7-B43) -> -99 | C25: =SUM(C7-C43) -> -26 | D25: =SUM(D7-D43) -> -65 | E25: =SUM(E7-E43) -> -46 | F25: =SUM(F7-F43) -> -210 | G25: =SUM(G7-G43) -> -210 | H25: =SUM(H7-H43) -> -180 | I25: =SUM(I7-I43) -> 0 | ... M25: =SUM(M7-M43) -> -200
A26: Annelie Corell | B26: =SUM(B8-B44) -> -51 | C26: =SUM(C8-C44) -> -10 | D26: =SUM(D8-D44) -> -6 | E26: =SUM(E8-E44) -> -26 | F26: =SUM(F8-F44) -> -200 | G26: =SUM(G8-G44) -> -200 | H26: =SUM(H8-H44) -> 0 | I26: =SUM(I8-I44) -> -200 | ... M26: =SUM(M8-M44) -> -190
A27: Louise From | B27: =SUM(B9-B45) -> 35 | C27: =SUM(C9-C45) -> -44 | D27: =SUM(D9-D45) -> -96 | E27: =SUM(E9-E45) -> -96 | F27: =SUM(F9-F45) -> -96 | G27: =SUM(G9-G45) -> -80 | H27: =SUM(H9-H45) -> -96 | I27: =SUM(I9-I45) -> 0 | ... M27: =SUM(M9-M45) -> -80
A28: Simon Lageson | B28: =SUM(B10-B46) -> 0 | C28: =SUM(C10-C46) -> 77 | D28: =SUM(D10-D46) -> 172 | E28: =SUM(E10-E46) -> 188 | F28: =SUM(F10-F46) -> -120 | G28: =SUM(G10-G46) -> -180 | H28: =SUM(H10-H46) -> 0 | I28: =SUM(I10-I46) -> -180 | ... M28: =SUM(M10-M46) -> -180
B29: =SUM(B11-B47) -> 0 | C29: =SUM(C11-C47) -> 0 | D29: =SUM(D11-D47) -> 0 | E29: =SUM(E11-E47) -> 0 | F29: =SUM(F11-F47) -> 0 | G29: =SUM(G11-G47) -> 0 | H29: =SUM(H11-H47) -> 0 | I29: =SUM(I11-I47) -> 0 | ... M29: =SUM(M11-M47) -> 0
B30: =SUM(B12-B48) -> 0 | C30: =SUM(C12-C48) -> 0 | D30: =SUM(D12-D48) -> 0 | E30: =SUM(E12-E48) -> 0 | F30: =SUM(F12-F48) -> 0 | G30: =SUM(G12-G48) -> 0 | H30: =SUM(H12-H48) -> 0 | I30: =SUM(I12-I48) -> 0 | ... M30: =SUM(M12-M48) -> 0
B31: =SUM(B13-B49) -> 0 | C31: =SUM(C13-C49) -> 0 | D31: =SUM(D13-D49) -> 0 | E31: =SUM(E13-E49) -> 0 | F31: =SUM(F13-F49) -> 0 | G31: =SUM(G13-G49) -> 0 | H31: =SUM(H13-H49) -> 0 | I31: =SUM(I13-I49) -> 0 | ... M31: =SUM(M13-M49) -> 0
B32: =SUM(B14-B50) -> 0 | C32: =SUM(C14-C50) -> 0 | D32: =SUM(D14-D50) -> 0 | E32: =SUM(E14-E50) -> 0 | F32: =SUM(F14-F50) -> 0 | G32: =SUM(G14-G50) -> 0 | H32: =SUM(H14-H50) -> 0 | I32: =SUM(I14-I50) -> 0 | ... M32: =SUM(M14-M50) -> 0
B33: =SUM(B15-B51) -> 0 | C33: =SUM(C15-C51) -> 0 | D33: =SUM(D15-D51) -> 0 | E33: =SUM(E15-E51) -> 0 | F33: =SUM(F15-F51) -> 0 | G33: =SUM(G15-G51) -> 0 | H33: =SUM(H15-H51) -> 0 | I33: =SUM(I15-I51) -> 0 | ... M33: =SUM(M15-M51) -> 0
B34: =SUM(B16-B52) -> 0 | C34: =SUM(C16-C52) -> 0 | D34: =SUM(D16-D52) -> 0 | E34: =SUM(E16-E52) -> 0 | F34: =SUM(F16-F52) -> 0 | G34: =SUM(G16-G52) -> 0 | H34: =SUM(H16-H52) -> 0 | I34: =SUM(I16-I52) -> 0 | ... M34: =SUM(M16-M52) -> 0
B35: =SUM(B17-B53) -> 0 | C35: =SUM(C17-C53) -> 0 | D35: =SUM(D17-D53) -> 0 | E35: =SUM(E17-E53) -> 0 | F35: =SUM(F17-F53) -> 0 | G35: =SUM(G17-G53) -> 0 | H35: =SUM(H17-H53) -> 0 | I35: =SUM(I17-I53) -> 0 | ... M35: =SUM(M17-M53) -> 0
B36: =SUM(B22:B35) -> -337 | C36: =SUM(C22:C35) -> -176 | D36: =SUM(D22:D35) -> -223 | E36: =SUM(E22:E35) -> -238 | F36: =SUM(F22:F35) -> -1076 | G36: =SUM(G22:G35) -> -1010 | H36: =SUM(H22:H35) -> -456 | I36: =SUM(I22:I35) -> -720 | ... M36: =SUM(M22:M35) -> -1040
B38: Budget | C38: Budget | D38: Budget | E38: Budget | F38: Budget | G38: Budget | H38: Budget | I38: Budget | J38: Budget | K38: Budget | L38: Budget | M38: Budget
A39: ÅRSBUDGET POÄNG 2026 = | B39: =SUM(B40:B46) -> 1120 | C39: =SUM(C40:C46) -> 1076 | D39: =SUM(D40:D46) -> 1106 | E39: =SUM(E40:E46) -> 1066 | F39: =SUM(F40:F46) -> 1076 | G39: =SUM(G40:G46) -> 1010 | H39: =SUM(H40:H46) -> 456 | I39: =SUM(I40:I46) -> 720 | ... M39: =SUM(M40:M46) -> 1040
A40: Pontus Berglund | B40: 220 | C40: 130 | D40: 140 | E40: 130
A41: Anders Esko | B41: 220 | C41: 230 | D41: 230 | E41: 230 | F41: 230 | G41: 120 | H41: 180 | I41: 120 | J41: 230 | K41: 230 | L41: 230 | M41: 200
A42: Albert Lindström | B42: 210 | C42: 230 | D42: 230 | E42: 220 | F42: 220 | G42: 220 | H42: 0 | I42: 220 | J42: 230 | K42: 230 | L42: 230 | M42: 190
A43: Rana Baratifar | B43: 190 | C43: 190 | D43: 210 | E43: 200 | F43: 210 | G43: 210 | H43: 180 | I43: 0 | J43: 220 | K43: 230 | L43: 230 | M43: 200
A44: Annelie Corell | B44: 190 | C44: 200 | D44: 200 | E44: 190 | F44: 200 | G44: 200 | H44: 0 | I44: 200 | J44: 200 | K44: 200 | L44: 200 | M44: 190
A45: Louise From | B45: 90 | C45: 96 | D45: 96 | E45: 96 | F45: 96 | G45: 80 | H45: 96 | I45: 0 | J45: 96 | K45: 96 | L45: 96 | M45: 80
A46: Simon Lageson | F46: 120 | G46: 180 | H46: 0 | I46: 180 | J46: 200 | K46: 200 | L46: 200 | M46: 180

Sheet Grimmered
A1: Uttag poäng datum; | B1: 46081 | C1: 46086 | D1: 46106
B2: Jan | C2: Feb | D2: Mar | E2: Apr | F2: Maj | G2: Jun | H2: Jul | I2: Aug | J2: Sep | K2: Okt | L2: Nov | M2: Dec
A3: Ta ut från Verksamhetsportalen: | B3: Actual | C3: Actual | D3: Actual | E3: Actual | F3: Actual | G3: Actual | H3: Actual | I3: Actual | J3: Actual | K3: Actual | L3: Actual | M3: Actual
A4: Malin Svensson | B4: 83 | C4: 157 | D4: 164 | E4: 159
A5: Hanna Bovin | B5: 179 | C5: 199 | D5: 250 | E5: 283
A6: Patricia Palada | B6: 195 | C6: 261 | D6: 217 | E6: 227
A7: Caroline Möller | B7: 114 | C7: 97 | D7: 179 | E7: 170
A8: Emma Lisjö | B8: 183 | C8: 170 | D8: 254 | E8: 166
A9: Pontus Berglund | E9: 67
B18: =SUM(B4:B17) -> 754 | C18: =SUM(C4:C17) -> 884 | D18: =SUM(D4:D17) -> 1064 | E18: =SUM(E4:E17) -> 1072 | F18: =SUM(F4:F17) -> 0 | G18: =SUM(G4:G17) -> 0 | H18: =SUM(H4:H17) -> 0 | I18: =SUM(I4:I17) -> 0 | ... M18: =SUM(M4:M17) -> 0
B20: Jan | C20: Feb | D20: Mar | E20: Apr | F20: Maj | G20: Jun | H20: Jul | I20: Aug | J20: Sep | K20: Okt | L20: Nov | M20: Dec
B21: Diff | C21: Diff | D21: Diff | E21: Diff | F21: Diff | G21: Diff | H21: Diff | I21: Diff | J21: Diff | K21: Diff | L21: Diff | M21: Diff
A22: Malin | B22: =SUM(B4-B40) -> -107 | C22: =SUM(C4-C40) -> -33 | D22: =SUM(D4-D40) -> -26 | E22: =SUM(E4-E40) -> -31 | F22: =SUM(F4-F40) -> -190 | G22: =SUM(G4-G40) -> -190 | H22: =SUM(H4-H40) -> 0 | I22: =SUM(I4-I40) -> -190 | ... M22: =SUM(M4-M40) -> -190
A23: Hanna | B23: =SUM(B5-B41) -> -41 | C23: =SUM(C5-C41) -> -31 | D23: =SUM(D5-D41) -> 20 | E23: =SUM(E5-E41) -> 63 | F23: =SUM(F5-F41) -> -220 | G23: =SUM(G5-G41) -> -230 | H23: =SUM(H5-H41) -> -210 | I23: =SUM(I5-I41) -> 0 | ... M23: =SUM(M5-M41) -> -190
A24: Patricia | B24: =SUM(B6-B42) -> -25 | C24: =SUM(C6-C42) -> 31 | D24: =SUM(D6-D42) -> -13 | E24: =SUM(E6-E42) -> 7 | F24: =SUM(F6-F42) -> -220 | G24: =SUM(G6-G42) -> -230 | H24: =SUM(H6-H42) -> 0 | I24: =SUM(I6-I42) -> -230 | ... M24: =SUM(M6-M42) -> -200
A25: Caroline | B25: =SUM(B7-B43) -> -61 | C25: =SUM(C7-C43) -> -98 | D25: =SUM(D7-D43) -> -16 | E25: =SUM(E7-E43) -> -20 | F25: =SUM(F7-F43) -> -195 | G25: =SUM(G7-G43) -> -195 | H25: =SUM(H7-H43) -> -180 | I25: =SUM(I7-I43) -> 0 | ... M25: =SUM(M7-M43) -> -180
A26: Emma | B26: =SUM(B8-B44) -> -17 | C26: =SUM(C8-C44) -> -30 | D26: =SUM(D8-D44) -> 54 | E26: =SUM(E8-E44) -> -34 | F26: =SUM(F8-F44) -> -200 | G26: =SUM(G8-G44) -> -200 | H26: =SUM(H8-H44) -> -110 | I26: =SUM(I8-I44) -> -110 | ... M26: =SUM(M8-M44) -> -200
B27: =SUM(B9-B45) -> 0 | C27: =SUM(C9-C45) -> 0 | D27: =SUM(D9-D45) -> 0 | E27: =SUM(E9-E45) -> 67 | F27: =SUM(F9-F45) -> 0 | G27: =SUM(G9-G45) -> 0 | H27: =SUM(H9-H45) -> 0 | I27: =SUM(I9-I45) -> 0 | ... M27: =SUM(M9-M45) -> 0
B28: =SUM(B10-B46) -> 0 | C28: =SUM(C10-C46) -> 0 | D28: =SUM(D10-D46) -> 0 | E28: =SUM(E10-E46) -> 0 | F28: =SUM(F10-F46) -> 0 | G28: =SUM(G10-G46) -> 0 | H28: =SUM(H10-H46) -> 0 | I28: =SUM(I10-I46) -> 0 | ... M28: =SUM(M10-M46) -> 0
B29: =SUM(B11-B47) -> 0 | C29: =SUM(C11-C47) -> 0 | D29: =SUM(D11-D47) -> 0 | E29: =SUM(E11-E47) -> 0 | F29: =SUM(F11-F47) -> 0 | G29: =SUM(G11-G47) -> 0 | H29: =SUM(H11-H47) -> 0 | I29: =SUM(I11-I47) -> 0 | ... M29: =SUM(M11-M47) -> 0
B30: =SUM(B12-B48) -> 0 | C30: =SUM(C12-C48) -> 0 | D30: =SUM(D12-D48) -> 0 | E30: 0 | F30: =SUM(F12-F48) -> 0 | G30: =SUM(G12-G48) -> 0 | H30: =SUM(H12-H48) -> 0 | I30: =SUM(I12-I48) -> 0 | J30: =SUM(J12-J48) -> 0 | K30: =SUM(K12-K48) -> 0 | L30: =SUM(L12-L48) -> 0 | M30: =SUM(M12-M48) -> 0
B31: =SUM(B13-B49) -> 0 | C31: =SUM(C13-C49) -> 0 | D31: =SUM(D13-D49) -> 0 | E31: =SUM(E13-E49) -> 0 | F31: =SUM(F13-F49) -> 0 | G31: =SUM(G13-G49) -> 0 | H31: =SUM(H13-H49) -> 0 | I31: =SUM(I13-I49) -> 0 | ... M31: =SUM(M13-M49) -> 0
B32: =SUM(B14-B50) -> 0 | C32: =SUM(C14-C50) -> 0 | D32: =SUM(D14-D50) -> 0 | E32: =SUM(E14-E50) -> 0 | F32: =SUM(F14-F50) -> 0 | G32: =SUM(G14-G50) -> 0 | H32: =SUM(H14-H50) -> 0 | I32: =SUM(I14-I50) -> 0 | ... M32: =SUM(M14-M50) -> 0
B33: =SUM(B15-B51) -> 0 | C33: =SUM(C15-C51) -> 0 | D33: =SUM(D15-D51) -> 0 | E33: =SUM(E15-E51) -> 0 | F33: =SUM(F15-F51) -> 0 | G33: =SUM(G15-G51) -> 0 | H33: =SUM(H15-H51) -> 0 | I33: =SUM(I15-I51) -> 0 | ... M33: =SUM(M15-M51) -> 0
B34: =SUM(B16-B52) -> 0 | C34: =SUM(C16-C52) -> 0 | D34: =SUM(D16-D52) -> 0 | E34: =SUM(E16-E52) -> 0 | F34: =SUM(F16-F52) -> 0 | G34: =SUM(G16-G52) -> 0 | H34: =SUM(H16-H52) -> 0 | I34: =SUM(I16-I52) -> 0 | ... M34: =SUM(M16-M52) -> 0
B35: =SUM(B17-B53) -> 0 | C35: =SUM(C17-C53) -> 0 | D35: =SUM(D17-D53) -> 0 | E35: =SUM(E17-E53) -> 0 | F35: =SUM(F17-F53) -> 0 | G35: =SUM(G17-G53) -> 0 | H35: =SUM(H17-H53) -> 0 | I35: =SUM(I17-I53) -> 0 | ... M35: =SUM(M17-M53) -> 0
B36: =SUM(B22:B35) -> -251 | C36: =SUM(C22:C35) -> -161 | D36: =SUM(D22:D35) -> 19 | E36: =SUM(E22:E35) -> 52 | F36: =SUM(F22:F35) -> -1025 | G36: =SUM(G22:G35) -> -1045 | H36: =SUM(H22:H35) -> -500 | I36: =SUM(I22:I35) -> -530 | ... M36: =SUM(M22:M35) -> -960
B38: Budget | C38: Budget | D38: Budget | E38: Budget | F38: Budget | G38: Budget | H38: Budget | I38: Budget | J38: Budget | K38: Budget | L38: Budget | M38: Budget
A39: ÅRSBUDGET POÄNG 2026 = | B39: =SUM(B40:B47) -> 1005 | C39: =SUM(C40:C47) -> 1045 | D39: =SUM(D40:D47) -> 1045 | E39: =SUM(E40:E47) -> 1020 | F39: =SUM(F40:F47) -> 1025 | G39: =SUM(G40:G47) -> 1045 | H39: =SUM(H40:H47) -> 500 | I39: =SUM(I40:I47) -> 530 | ... M39: =SUM(M40:M47) -> 960
A40: Malin | B40: 190 | C40: 190 | D40: 190 | E40: 190 | F40: 190 | G40: 190 | H40: 0 | I40: 190 | J40: 190 | K40: 190 | L40: 190 | M40: 190
A41: Hanna | B41: 220 | C41: 230 | D41: 230 | E41: 220 | F41: 220 | G41: 230 | H41: 210 | I41: 0 | J41: 230 | K41: 230 | L41: 230 | M41: 190
A42: Patricia | B42: 220 | C42: 230 | D42: 230 | E42: 220 | F42: 220 | G42: 230 | H42: 0 | I42: 230 | J42: 230 | K42: 230 | L42: 230 | M42: 200
A43: Caroline | B43: 175 | C43: 195 | D43: 195 | E43: 190 | F43: 195 | G43: 195 | H43: 180 | I43: 0 | J43: 190 | K43: 190 | L43: 190 | M43: 180
A44: Emma | B44: 200 | C44: 200 | D44: 200 | E44: 200 | F44: 200 | G44: 200 | H44: 110 | I44: 110 | J44: 200 | K44: 200 | L44: 200 | M44: 200

Sheet Majorna
A1: Uttag poäng datum; | B1: 46063 | C1: 46086
B2: Jan | C2: Feb | D2: Mar | E2: Apr | F2: Maj | G2: Jun | H2: Jul | I2: Aug | J2: Sep | K2: Okt | L2: Nov | M2: Dec
A3: Ta ut från Verksamhetsportalen: | B3: Actual | C3: Actual | D3: Actual | E3: Actual | F3: Actual | G3: Actual | H3: Actual | I3: Actual | J3: Actual | K3: Actual | L3: Actual | M3: Actual
A4: Anna-Karin Book | B4: 186 | C4: 206 | D4: 165 | E4: 168
A5: Caroline | B5: 170 | C5: 144 | D5: 186 | E5: 67
A6: Mattias | B6: 151 | C6: 163 | D6: 216 | E6: 169
A7: Anna-Karin S | B7: 211 | C7: 232 | D7: 202 | E7: 224
A8: Lena | B8: 88 | C8: 103 | D8: 110 | E8: 108
A9: Helen/Ny FT | B9: 88 | C9: 114 | D9: 124 | E9: 34
A10: Fanny | E10: 61
A11: Maja | E11: 5
B18: =SUM(B4:B17) -> 894 | C18: =SUM(C4:C17) -> 962 | D18: =SUM(D4:D17) -> 1003 | E18: =SUM(E4:E17) -> 836 | F18: =SUM(F4:F17) -> 0 | G18: =SUM(G4:G17) -> 0 | H18: =SUM(H4:H17) -> 0 | I18: =SUM(I4:I17) -> 0 | ... M18: =SUM(M4:M17) -> 0
B20: Jan | C20: Feb | D20: Mar | E20: Apr | F20: Maj | G20: Jun | H20: Jul | I20: Aug | J20: Sep | K20: Okt | L20: Nov | M20: Dec
B21: Diff | C21: Diff | D21: Diff | E21: Diff | F21: Diff | G21: Diff | H21: Diff | I21: Diff | J21: Diff | K21: Diff | L21: Diff | M21: Diff
A22: Anna-Karin Book | B22: =SUM(B4-B40) -> -6 | C22: =SUM(C4-C40) -> 14 | D22: =SUM(D4-D40) -> -27 | E22: =SUM(E4-E40) -> -24 | F22: =SUM(F4-F40) -> -192 | G22: =SUM(G4-G40) -> -150 | H22: =SUM(H4-H40) -> -100 | I22: =SUM(I4-I40) -> -100 | ... M22: =SUM(M4-M40) -> -165
A23: Caroline | B23: =SUM(B5-B41) -> 0 | C23: =SUM(C5-C41) -> -46 | D23: =SUM(D5-D41) -> -9 | E23: =SUM(E5-E41) -> -123 | F23: =SUM(F5-F41) -> -190 | G23: =SUM(G5-G41) -> -190 | H23: =SUM(H5-H41) -> -90 | I23: =SUM(I5-I41) -> -90 | ... M23: =SUM(M5-M41) -> -165
A24: Mattias | B24: =SUM(B6-B42) -> -64 | C24: =SUM(C6-C42) -> -57 | D24: =SUM(D6-D42) -> -24 | E24: =SUM(E6-E42) -> -71 | F24: =SUM(F6-F42) -> -240 | G24: =SUM(G6-G42) -> -230 | H24: =SUM(H6-H42) -> -60 | I24: =SUM(I6-I42) -> -120 | ... M24: =SUM(M6-M42) -> -200
A25: Anna-Karin S | B25: =SUM(B7-B43) -> 51 | C25: =SUM(C7-C43) -> -8 | D25: =SUM(D7-D43) -> -38 | E25: =SUM(E7-E43) -> -16 | F25: =SUM(F7-F43) -> -240 | G25: =SUM(G7-G43) -> -120 | H25: =SUM(H7-H43) -> -120 | I25: =SUM(I7-I43) -> -120 | ... M25: =SUM(M7-M43) -> -190
A26: Lena | B26: =SUM(B8-B44) -> -72 | C26: =SUM(C8-C44) -> -67 | D26: =SUM(D8-D44) -> -70 | E26: =SUM(E8-E44) -> -72 | F26: =SUM(F8-F44) -> -180 | G26: =SUM(G8-G44) -> -130 | H26: =SUM(H8-H44) -> -90 | I26: =SUM(I8-I44) -> -130 | ... M26: =SUM(M8-M44) -> -150
A27: Helen/Ny FT | B27: =SUM(B9-B45) -> -2 | C27: =SUM(C9-C45) -> -6 | D27: =SUM(D9-D45) -> -26 | E27: =SUM(E9-E45) -> -156 | F27: =SUM(F9-F45) -> -200 | G27: =SUM(G9-G45) -> -200 | H27: =SUM(H9-H45) -> -100 | I27: =SUM(I9-I45) -> -100 | ... M27: =SUM(M9-M45) -> -180
B28: =SUM(B10-B46) -> 0 | C28: =SUM(C10-C46) -> 0 | D28: =SUM(D10-D46) -> 0 | E28: =SUM(E10-E46) -> 61 | F28: =SUM(F10-F46) -> 0 | G28: =SUM(G10-G46) -> 0 | H28: =SUM(H10-H46) -> 0 | I28: =SUM(I10-I46) -> 0 | ... M28: =SUM(M10-M46) -> 0
B29: =SUM(B11-B47) -> 0 | C29: =SUM(C11-C47) -> 0 | D29: =SUM(D11-D47) -> 0 | E29: =SUM(E11-E47) -> 5 | F29: =SUM(F11-F47) -> 0 | G29: =SUM(G11-G47) -> 0 | H29: =SUM(H11-H47) -> 0 | I29: =SUM(I11-I47) -> 0 | ... M29: =SUM(M11-M47) -> 0
B30: =SUM(B12-B48) -> 0 | C30: =SUM(C12-C48) -> 0 | D30: =SUM(D12-D48) -> 0 | E30: =SUM(E12-E48) -> 0 | F30: =SUM(F12-F48) -> 0 | G30: =SUM(G12-G48) -> 0 | H30: =SUM(H12-H48) -> 0 | I30: =SUM(I12-I48) -> 0 | ... M30: =SUM(M12-M48) -> 0
B31: =SUM(B13-B49) -> 0 | C31: =SUM(C13-C49) -> 0 | D31: =SUM(D13-D49) -> 0 | E31: =SUM(E13-E49) -> 0 | F31: =SUM(F13-F49) -> 0 | G31: =SUM(G13-G49) -> 0 | H31: =SUM(H13-H49) -> 0 | I31: =SUM(I13-I49) -> 0 | ... M31: =SUM(M13-M49) -> 0
B32: =SUM(B14-B50) -> 0 | C32: =SUM(C14-C50) -> 0 | D32: =SUM(D14-D50) -> 0 | E32: =SUM(E14-E50) -> 0 | F32: =SUM(F14-F50) -> 0 | G32: =SUM(G14-G50) -> 0 | H32: =SUM(H14-H50) -> 0 | I32: =SUM(I14-I50) -> 0 | ... M32: =SUM(M14-M50) -> 0
B33: =SUM(B15-B51) -> 0 | C33: =SUM(C15-C51) -> 0 | D33: =SUM(D15-D51) -> 0 | E33: =SUM(E15-E51) -> 0 | F33: =SUM(F15-F51) -> 0 | G33: =SUM(G15-G51) -> 0 | H33: =SUM(H15-H51) -> 0 | I33: =SUM(I15-I51) -> 0 | ... M33: =SUM(M15-M51) -> 0
B34: =SUM(B16-B52) -> 0 | C34: =SUM(C16-C52) -> 0 | D34: =SUM(D16-D52) -> 0 | E34: =SUM(E16-E52) -> 0 | F34: =SUM(F16-F52) -> 0 | G34: =SUM(G16-G52) -> 0 | H34: =SUM(H16-H52) -> 0 | I34: =SUM(I16-I52) -> 0 | ... M34: =SUM(M16-M52) -> 0
B35: =SUM(B17-B53) -> 0 | C35: =SUM(C17-C53) -> 0 | D35: =SUM(D17-D53) -> 0 | E35: =SUM(E17-E53) -> 0 | F35: =SUM(F17-F53) -> 0 | G35: =SUM(G17-G53) -> 0 | H35: =SUM(H17-H53) -> 0 | I35: =SUM(I17-I53) -> 0 | ... M35: =SUM(M17-M53) -> 0
B36: =SUM(B22:B35) -> -93 | C36: =SUM(C22:C35) -> -170 | D36: =SUM(D22:D35) -> -194 | E36: =SUM(E22:E35) -> -396 | F36: =SUM(F22:F35) -> -1242 | G36: =SUM(G22:G35) -> -1020 | H36: =SUM(H22:H35) -> -560 | I36: =SUM(I22:I35) -> -660 | ... M36: =SUM(M22:M35) -> -1050
B38: Budget | C38: Budget | D38: Budget | E38: Budget | F38: Budget | G38: Budget | H38: Budget | I38: Budget | J38: Budget | K38: Budget | L38: Budget | M38: Budget
A39: ÅRSBUDGET POÄNG 2026 = | B39: =SUM(B40:B53) -> 987 | C39: =SUM(C40:C53) -> 1132 | D39: =SUM(D40:D53) -> 1197 | E39: =SUM(E40:E53) -> 1232 | F39: =SUM(F40:F53) -> 1242 | G39: =SUM(G40:G53) -> 1020 | H39: =SUM(H40:H53) -> 560 | I39: =SUM(I40:I53) -> 660 | ... M39: =SUM(M40:M53) -> 1050
A40: Anna-Karin Book | B40: 192 | C40: 192 | D40: 192 | E40: 192 | F40: 192 | G40: 150 | H40: 100 | I40: 100 | J40: 192 | K40: 192 | L40: 192 | M40: 165
A41: Caroline | B41: 170 | C41: 190 | D41: 195 | E41: 190 | F41: 190 | G41: 190 | H41: 90 | I41: 90 | J41: 190 | K41: 190 | L41: 190 | M41: 165
A42: Mattias | B42: 215 | C42: 220 | D42: 240 | E42: 240 | F42: 240 | G42: 230 | H42: 60 | I42: 120 | J42: 240 | K42: 240 | L42: 240 | M42: 200
A43: Anna-Karin S | B43: 160 | C43: 240 | D43: 240 | E43: 240 | F43: 240 | G43: 120 | H43: 120 | I43: 120 | J43: 240 | K43: 240 | L43: 240 | M43: 190
A44: Lena | B44: 160 | C44: 170 | D44: 180 | E44: 180 | F44: 180 | G44: 130 | H44: 90 | I44: 130 | J44: 180 | K44: 180 | L44: 180 | M44: 150
A45: Helen/Ny FT | B45: 90 | C45: 120 | D45: 150 | E45: 190 | F45: 200 | G45: 200 | H45: 100 | I45: 100 | J45: 210 | K45: 210 | L45: 210 | M45: 180

Sheet Pedagogen Park
A1: Uttag poäng datum; | B1: 46081 | C1: 46086 | D1: 46106
B2: Jan | C2: Feb | D2: Mar | E2: Apr | F2: Maj | G2: Jun | H2: Jul | I2: Aug | J2: Sep | K2: Okt | L2: Nov | M2: Dec
A3: Ta ut från Verksamhetsportalen: | B3: Actual | C3: Actual | D3: Actual | E3: Actual | F3: Actual | G3: Actual | H3: Actual | I3: Actual | J3: Actual | K3: Actual | L3: Actual | M3: Actual | N3: Kommentarer;
A4: Arvid Lennartsson | B4: 101 | C4: 140 | D4: 145 | E4: 186
A5: Charlotte Alderblad | B5: 167 | C5: 171 | D5: 187 | E5: 209
A6: Ida Hasselholm | B6: 111 | C6: 54 | D6: 202 | E6: 142
A7: Matilda Saukkorripi | B7: 99 | C7: 167 | D7: 255 | E7: 143
A8: Lisa T
B18: =SUM(B4:B17) -> 478 | C18: =SUM(C4:C17) -> 532 | D18: =SUM(D4:D17) -> 789 | E18: =SUM(E4:E17) -> 680 | F18: =SUM(F4:F17) -> 0 | G18: =SUM(G4:G17) -> 0 | H18: =SUM(H4:H17) -> 0 | I18: =SUM(I4:I17) -> 0 | ... M18: =SUM(M4:M17) -> 0
B20: Jan | C20: Feb | D20: Mar | E20: Apr | F20: Maj | G20: Jun | H20: Jul | I20: Aug | J20: Sep | K20: Okt | L20: Nov | M20: Dec
B21: DIFF | C21: DIFF | D21: DIFF | E21: DIFF | F21: DIFF | G21: DIFF | H21: DIFF | I21: DIFF | J21: DIFF | K21: DIFF | L21: DIFF | M21: DIFF | N21: Kommentarer;
A22: Arvid Lennartsson | B22: =SUM(B4-B40) -> 1 | C22: =SUM(C4-C40) -> 40 | D22: =SUM(D4-D40) -> 95 | E22: =SUM(E4-E40) -> 146 | F22: =SUM(F4-F40) -> -50 | G22: =SUM(G4-G40) -> -140 | H22: =SUM(H4-H40) -> -200 | I22: =SUM(I4-I40) -> -200 | ... M22: =SUM(M4-M40) -> -70
A23: Charlotte Alderblad | B23: =SUM(B5-B41) -> -43 | C23: =SUM(C5-C41) -> -69 | D23: =SUM(D5-D41) -> -53 | E23: =SUM(E5-E41) -> -11 | F23: =SUM(F5-F41) -> -220 | G23: =SUM(G5-G41) -> -220 | H23: =SUM(H5-H41) -> -240 | I23: =SUM(I5-I41) -> 0 | ... M23: =SUM(M5-M41) -> -170
A24: Ida Hasselholm | B24: =SUM(B6-B42) -> 11 | C24: =SUM(C6-C42) -> -66 | D24: =SUM(D6-D42) -> -38 | E24: =SUM(E6-E42) -> -68 | F24: =SUM(F6-F42) -> -210 | G24: =SUM(G6-G42) -> -200 | H24: =SUM(H6-H42) -> -160 | I24: =SUM(I6-I42) -> -220 | ... M24: =SUM(M6-M42) -> -200
A25: Matilda Saukkorripi | B25: =SUM(B7-B43) -> -91 | C25: =SUM(C7-C43) -> -33 | D25: =SUM(D7-D43) -> 55 | E25: =SUM(E7-E43) -> -57 | F25: =SUM(F7-F43) -> -200 | G25: =SUM(G7-G43) -> -200 | H25: =SUM(H7-H43) -> 0 | I25: =SUM(I7-I43) -> -200 | ... M25: =SUM(M7-M43) -> -170
A26: Lisa T | B26: =SUM(B8-B44) -> 0 | C26: =SUM(C8-C44) -> 0 | D26: =SUM(D8-D44) -> 0 | E26: =SUM(E8-E44) -> -65 | F26: =SUM(F8-F44) -> -80 | G26: =SUM(G8-G44) -> -40 | H26: =SUM(H8-H44) -> 0 | I26: =SUM(I8-I44) -> -40 | ... M26: =SUM(M8-M44) -> -65
B27: =SUM(B9-B45) -> 0 | C27: =SUM(C9-C45) -> 0 | D27: =SUM(D9-D45) -> 0 | E27: =SUM(E9-E45) -> 0 | F27: =SUM(F9-F45) -> 0 | G27: =SUM(G9-G45) -> 0 | H27: =SUM(H9-H45) -> 0 | I27: =SUM(I9-I45) -> 0 | ... M27: =SUM(M9-M45) -> 0
B28: =SUM(B10-B46) -> 0 | C28: =SUM(C10-C46) -> 0 | D28: =SUM(D10-D46) -> 0 | E28: =SUM(E10-E46) -> 0 | F28: =SUM(F10-F46) -> 0 | G28: =SUM(G10-G46) -> 0 | H28: =SUM(H10-H46) -> 0 | I28: =SUM(I10-I46) -> 0 | ... M28: =SUM(M10-M46) -> 0
B29: =SUM(B11-B47) -> 0 | C29: =SUM(C11-C47) -> 0 | D29: =SUM(D11-D47) -> 0 | E29: =SUM(E11-E47) -> 0 | F29: =SUM(F11-F47) -> 0 | G29: =SUM(G11-G47) -> 0 | H29: =SUM(H11-H47) -> 0 | I29: =SUM(I11-I47) -> 0 | ... M29: =SUM(M11-M47) -> 0
B30: =SUM(B12-B48) -> 0 | C30: =SUM(C12-C48) -> 0 | D30: =SUM(D12-D48) -> 0 | E30: =SUM(E12-E48) -> 0 | F30: =SUM(F12-F48) -> 0 | G30: =SUM(G12-G48) -> 0 | H30: =SUM(H12-H48) -> 0 | I30: =SUM(I12-I48) -> 0 | ... M30: =SUM(M12-M48) -> 0
B31: =SUM(B13-B49) -> 0 | C31: =SUM(C13-C49) -> 0 | D31: =SUM(D13-D49) -> 0 | E31: =SUM(E13-E49) -> 0 | F31: =SUM(F13-F49) -> 0 | G31: =SUM(G13-G49) -> 0 | H31: =SUM(H13-H49) -> 0 | I31: =SUM(I13-I49) -> 0 | ... M31: =SUM(M13-M49) -> 0
B32: =SUM(B14-B50) -> 0 | C32: =SUM(C14-C50) -> 0 | D32: =SUM(D14-D50) -> 0 | E32: =SUM(E14-E50) -> 0 | F32: =SUM(F14-F50) -> 0 | G32: =SUM(G14-G50) -> 0 | H32: =SUM(H14-H50) -> 0 | I32: =SUM(I14-I50) -> 0 | ... M32: =SUM(M14-M50) -> 0
B33: =SUM(B15-B51) -> 0 | C33: =SUM(C15-C51) -> 0 | D33: =SUM(D15-D51) -> 0 | E33: =SUM(E15-E51) -> 0 | F33: =SUM(F15-F51) -> 0 | G33: =SUM(G15-G51) -> 0 | H33: =SUM(H15-H51) -> 0 | I33: =SUM(I15-I51) -> 0 | ... M33: =SUM(M15-M51) -> 0
B34: =SUM(B16-B52) -> 0 | C34: =SUM(C16-C52) -> 0 | D34: =SUM(D16-D52) -> 0 | E34: =SUM(E16-E52) -> 0 | F34: =SUM(F16-F52) -> 0 | G34: =SUM(G16-G52) -> 0 | H34: =SUM(H16-H52) -> 0 | I34: =SUM(I16-I52) -> 0 | ... M34: =SUM(M16-M52) -> 0
B35: =SUM(B17-B53) -> 0 | C35: =SUM(C17-C53) -> 0 | D35: =SUM(D17-D53) -> 0 | E35: =SUM(E17-E53) -> 0 | F35: =SUM(F17-F53) -> 0 | G35: =SUM(G17-G53) -> 0 | H35: =SUM(H17-H53) -> 0 | I35: =SUM(I17-I53) -> 0 | ... M35: =SUM(M17-M53) -> 0
B36: =SUM(B22:B35) -> -122 | C36: =SUM(C22:C35) -> -128 | D36: =SUM(D22:D35) -> 59 | E36: =SUM(E22:E35) -> -55 | F36: =SUM(F22:F35) -> -760 | G36: =SUM(G22:G35) -> -800 | H36: =SUM(H22:H35) -> -600 | I36: =SUM(I22:I35) -> -660 | ... M36: =SUM(M22:M35) -> -675
B38: Budget | C38: Budget | D38: Budget | E38: Budget | F38: Budget | G38: Budget | H38: Budget | I38: Budget | J38: Budget | K38: Budget | L38: Budget | M38: Budget
A39: ÅRSBUDGET POÄNG 2026 = | B39: =SUM(B40:B44) -> 600 | C39: =SUM(C40:C44) -> 660 | D39: =SUM(D40:D44) -> 730 | E39: =SUM(E40:E44) -> 735 | F39: =SUM(F40:F44) -> 760 | G39: =SUM(G40:G44) -> 800 | H39: =SUM(H40:H44) -> 600 | I39: =SUM(I40:I44) -> 660 | ... M39: =SUM(M40:M44) -> 675
A40: Arvid Lennartsson | B40: 100 | C40: 100 | D40: 50 | E40: 40 | F40: 50 | G40: 140 | H40: 200 | I40: 200 | J40: 100 | K40: 100 | L40: 100 | M40: 70
A41: Charlotte Alderblad | B41: 210 | C41: 240 | D41: 240 | E41: 220 | F41: 220 | G41: 220 | H41: 240 | I41: 0 | J41: 200 | K41: 200 | L41: 200 | M41: 170
A42: Ida Hasselholm | B42: 100 | C42: 120 | D42: 240 | E42: 210 | F42: 210 | G42: 200 | H42: 160 | I42: 220 | J42: 220 | K42: 220 | L42: 220 | M42: 200
A43: Matilda Saukkorripi | B43: 190 | C43: 200 | D43: 200 | E43: 200 | F43: 200 | G43: 200 | H43: 0 | I43: 200 | J43: 200 | K43: 200 | L43: 200 | M43: 170
A44: Lisa T | E44: 65 | F44: 80 | G44: 40 | H44: 0 | I44: 40 | J44: 40 | K44: 80 | L44: 80 | M44: 65

Sheet Åby
A1: Uttag poäng datum; | B1: 46063 | C1: 46086
B2: Jan | C2: Feb | D2: Mar | E2: Apr | F2: Maj | G2: Jun | H2: Jul | I2: Aug | J2: Sep | K2: Okt | L2: Nov | M2: Dec
A3: Ta ut från Verksamhetsportalen: | B3: Actual | C3: Actual | D3: Actual | E3: Actual | F3: Actual | G3: Actual | H3: Actual | I3: Actual | J3: Actual | K3: Actual | L3: Actual | M3: Actual
A4: Anna Abrahamsson | B4: 176 | C4: 133 | D4: 180 | E4: 208
A5: Caroline Lindahl | B5: 204 | C5: 199 | D5: 219 | E5: 154
A6: Catarina Engström | B6: 190 | C6: 251 | D6: 278 | E6: 169
A7: Lisa Torell
A8: Michaela Voeler | B8: 204 | C8: 207 | D8: 178 | E8: 219
A9: Lisa Edvardsson | B9: 147 | C9: 264 | D9: 248 | E9: 191
A10: Anna-Klara Å | B10: 5
B18: =SUM(B4:B17) -> 926 | C18: =SUM(C4:C17) -> 1054 | D18: =SUM(D4:D17) -> 1103 | E18: =SUM(E4:E17) -> 941 | F18: =SUM(F4:F17) -> 0 | G18: =SUM(G4:G17) -> 0 | H18: =SUM(H4:H17) -> 0 | I18: =SUM(I4:I17) -> 0 | ... M18: =SUM(M4:M17) -> 0
B20: Jan | C20: Feb | D20: Mar | E20: Apr | F20: Maj | G20: Jun | H20: Jul | I20: Aug | J20: Sep | K20: Okt | L20: Nov | M20: Dec
B21: Diff | C21: Diff | D21: Diff | E21: Diff | F21: Diff | G21: Diff | H21: Diff | I21: Diff | J21: Diff | K21: Diff | L21: Diff | M21: Diff
A22: Anna Abrahamsson | B22: =SUM(B4-B40) -> -14 | C22: =SUM(C4-C40) -> -71 | D22: =SUM(D4-D40) -> 26 | E22: =SUM(E4-E40) -> 16 | F22: =SUM(F4-F40) -> -192 | G22: =SUM(G4-G40) -> -143 | H22: =SUM(H4-H40) -> -102 | I22: =SUM(I4-I40) -> -153 | ... M22: =SUM(M4-M40) -> -144
A23: Caroline Lindahl | B23: =SUM(B5-B41) -> 41 | C23: =SUM(C5-C41) -> 55 | D23: =SUM(D5-D41) -> 27 | E23: =SUM(E5-E41) -> 0 | F23: =SUM(F5-F41) -> -190 | G23: =SUM(G5-G41) -> -170 | H23: =SUM(H5-H41) -> -48 | I23: =SUM(I5-I41) -> -96 | ... M23: =SUM(M5-M41) -> -144
