Workbook
Name Utsnitt_ACG_casemix: #N/A
Name Utsnitt_Antal_listade_pat: #N/A
Name Utsnitt_Intäkter___listad_pat: #N/A
Name Utsnitt_Medical_staff_cost___listad_pat: #N/A
Name Utsnitt_Other_direct_costs___listad_pat: #N/A
Name Utsnitt_Stor_GBG_AO: #N/A

Sheet Resultat-VC (3)
A1: Source.Name | B1: CG Item | C1: Column2 | D1: Column3 | E1: Selected Period | F1: Selected Period_1 | G1: Selected Period_2 | H1: Selected Period_3 | I1: Selected Period_4 | J1: Selected Period_5 | K1: Selected Period_6 | L1: Selected Period_7 | M1: Selected Period_8 | N1: Selected Period_9 | O1: Selected Period_10 | P1: Selected Period_11 | Q1: Selected Period_12 | R1: Selected Period_13 | S1: Selected Period_14 | T1: Selected Period_15 | U1: Selected Period_16 | V1: Selected Period_17 | W1: Selected Period_18 | X1: Selected Period_19 | Y1: Selected Period_20 | Z1: Selected Period_21 | AA1: Selected Period_22 | AB1: Selected Period_23 | AC1: Selected Period_24 | AD1: Selected Period_25
A2: 015.xlsx | B2: Year Month No | E2: 202312 | F2: 202401 | G2: 202402 | H2: 202403 | I2: 202404 | J2: 202405 | K2: 202406 | L2: 202407 | M2: 202408 | N2: 202409 | O2: 202410 | P2: 202411 | Q2: 202412 | R2: 202501 | S2: 202502 | T2: 202503 | U2: 202504 | V2: 202505 | W2: 202506 | X2: 202507 | Y2: 202508 | Z2: 202509 | AA2: 202510 | AB2: 202511 | AC2: 202512 | AD2: 202601
A3: 015.xlsx | B3: Scenario | E3: Actual | F3: Actual | G3: Actual | H3: Actual | I3: Actual | J3: Actual | K3: Actual | L3: Actual | M3: Actual | N3: Actual | O3: Actual | P3: Actual | Q3: Actual | R3: Actual | S3: Actual | T3: Actual | U3: Actual | V3: Actual | W3: Actual | X3: Actual | Y3: Actual | Z3: Actual | AA3: Actual | AB3: Actual | AC3: Actual | AD3: Actual
A4: 015.xlsx | B4: ElementName | C4: Reference Account | D4: Cluster | E4: Profit and Loss Table | F4: Profit and Loss Table | G4: Profit and Loss Table | H4: Profit and Loss Table | I4: Profit and Loss Table | J4: Profit and Loss Table | K4: Profit and Loss Table | L4: Profit and Loss Table | M4: Profit and Loss Table | N4: Profit and Loss Table | O4: Profit and Loss Table | P4: Profit and Loss Table | Q4: Profit and Loss Table | R4: Profit and Loss Table | S4: Profit and Loss Table | T4: Profit and Loss Table | U4: Profit and Loss Table | V4: Profit and Loss Table | W4: Profit and Loss Table | X4: Profit and Loss Table | Y4: Profit and Loss Table | Z4: Profit and Loss Table | AA4: Profit and Loss Table | AB4: Profit and Loss Table | AC4: Profit and Loss Table | AD4: Profit and Loss Table
A5: 015.xlsx | B5: Revenue | C5: Total | L5: 17900 | M5: -0.5 | N5: 49657.22 | O5: 134821.97 | P5: 191819.63 | Q5: 174736.02 | R5: 231650.33 | S5: 230589.78 | T5: 256219.36 | U5: 274278.18 | V5: 270523.18 | W5: 329856.16 | X5: 373500.85 | Y5: 390490.68 | Z5: 406486.25 | AA5: 433006.53 | AB5: 569810.34 | AC5: 540626.52 | AD5: 540246.35
A6: 015.xlsx | B6: Revenue | C6: Revenues | D6: Total | N6: 49657.22 | O6: 103571.97 | P6: 160069.63 | Q6: 158485.96 | R6: 202669.33 | S6: 229839.78 | T6: 254769.36 | U6: 274278.18 | V6: 270523.18 | W6: 329856.16 | X6: 373500.85 | Y6: 389990.68 | Z6: 406736.25 | AA6: 432042.53 | AB6: 569809.84 | AC6: 539564.02 | AD6: 537543.24
A7: 015.xlsx | B7: Revenue | C7: Revenues | D7: RG Huvudintäkter | N7: 42957.22 | O7: 87371.97 | P7: 149764.63 | Q7: 157005.96 | R7: 202669.33 | S7: 224834.78 | T7: 248373.36 | U7: 275498.18 | V7: 275498.18 | W7: 330771.16 | X7: 333083.85 | Y7: 381700.68 | Z7: 395221.25 | AA7: 407547.53 | AB7: 476681.84 | AC7: 525489.02 | AD7: 520984.24
A8: 015.xlsx | B8: Revenue | C8: Revenues | D8: Patientintäkter | N8: 6700 | O8: 16200 | P8: 10305 | Q8: 1480 | R8: 0 | S8: 5005 | T8: 6396 | U8: -1220 | V8: -4975 | W8: -915 | X8: 40417 | Y8: 8290 | Z8: 11515 | AA8: 24495 | AB8: 28180 | AC8: 14075 | AD8: 16559
A9: 015.xlsx | B9: Revenue | C9: Revenues | D9: Övriga intäkter | AB9: 64948
A10: 015.xlsx | B10: Revenue | C10: Other revenues | D10: Total | L10: 17900 | M10: -0.5 | O10: 31250 | P10: 31750 | Q10: 16250.06 | R10: 28981 | S10: 750 | T10: 1450 | Y10: 500 | Z10: -250 | AA10: 964 | AB10: 0.5 | AC10: 1062.5 | AD10: 2703.11
A11: 015.xlsx | B11: COGS | C11: Total | I11: -90679.8 | J11: -101126.21 | K11: -99615.21 | L11: -100860.21 | M11: -176307.24 | N11: -670610.11 | O11: -730350.46 | P11: -860951.32 | Q11: -1046134.9 | R11: -760570 | S11: -721653.37 | T11: -647256.52 | U11: -748203.19 | V11: -699197.42 | W11: -846891.93 | X11: -742923.78 | Y11: -806606.7 | Z11: -683240.2 | AA11: -779287.23 | AB11: -670913.99 | AC11: -646508.28 | AD11: -702478.73
A12: 015.xlsx | B12: COGS | C12: Medical staff | D12: Total | I12: -90679.8 | J12: -101126.21 | K12: -99615.21 | L12: -100860.21 | M12: -176307.24 | N12: -587574.45 | O12: -631054.06 | P12: -792145.81 | Q12: -1001478.6 | R12: -635308.02 | S12: -644869.24 | T12: -469462.36 | U12: -770294.22 | V12: -606283.24 | W12: -749676.94 | X12: -648318.2 | Y12: -735801.19 | Z12: -558198.34 | AA12: -659107.97 | AB12: -523949.07 | AC12: -518894.56 | AD12: -548991.86
A13: 015.xlsx | B13: COGS | C13: Other direct costs | D13: Total | L13: 0 | M13: 0 | N13: -83035.66 | O13: -99296.4 | P13: -68805.51 | Q13: -44656.31 | R13: -125261.98 | S13: -76784.13 | T13: -177794.16 | U13: 22091.03 | V13: -92914.18 | W13: -97214.99 | X13: -94605.58 | Y13: -70805.51 | Z13: -125041.86 | AA13: -120179.26 | AB13: -146964.92 | AC13: -127613.72 | AD13: -153486.87
A14: 015.xlsx | B14: Gross Profit | C14: Total | I14: -90679.8 | J14: -101126.21 | K14: -99615.21 | L14: -82960.21 | M14: -176307.74 | N14: -620952.89 | O14: -595528.49 | P14: -669131.69 | Q14: -871398.9 | R14: -528919.67 | S14: -491063.59 | T14: -391037.16 | U14: -473925.01 | V14: -428674.24 | W14: -517035.77 | X14: -369422.93 | Y14: -416116.02 | Z14: -276753.95 | AA14: -346280.7 | AB14: -101103.65 | AC14: -105881.76 | AD14: -162232.38
A15: 015.xlsx | B15: OPEX | C15: Total | F15: 0 | G15: 0 | H15: 36 | I15: 2771.16 | J15: -6605 | K15: -4966.17 | L15: -72402.87 | M15: 0 | N15: -739493.87 | O15: -515692.41 | P15: -270226.33 | Q15: -354261.63 | R15: -370328.32 | S15: -397390.89 | T15: -378383.51 | U15: -326828.4 | V15: -375946.74 | W15: -407136.25 | X15: -335336.29 | Y15: -349598.39 | Z15: -288249.93 | AA15: -242432.78 | AB15: -280032.5 | AC15: -250202.84 | AD15: -259066.8
A16: 015.xlsx | B16: OPEX | C16: Operating expenses | D16: Total | F16: 0 | G16: 0 | H16: 36 | I16: 2771.16 | J16: -6605 | K16: -4966.17 | L16: -72402.87 | M16: 0 | N16: -612869.53 | O16: -443080.07 | P16: -243817.99 | Q16: -319963.13 | R16: -355467.98 | S16: -382982.55 | T16: -363975.17 | U16: -312420.06 | V16: -361538.4 | W16: -392727.91 | X16: -320927.95 | Y16: -326180.13 | Z16: -287269.93 | AA16: -249858.58 | AB16: -284637.73 | AC16: -257089.93 | AD16: -246358.03
A17: 015.xlsx | B17: OPEX | C17: Overhead costs | D17: Total | K17: 0 | L17: 0 | N17: -126624.34 | O17: -72612.34 | P17: -26408.34 | Q17: -34298.5 | R17: -14860.34 | S17: -14408.34 | T17: -14408.34 | U17: -14408.34 | V17: -14408.34 | W17: -14408.34 | X17: -14408.34 | Y17: -23418.26 | Z17: -980 | AA17: 7425.8 | AB17: 4605.23 | AC17: 6887.09 | AD17: -12708.77
A18: 015.xlsx | B18: EBITDA1 | C18: Total | F18: 0 | G18: 0 | H18: 36 | I18: -87908.64 | J18: -107731.21 | K18: -104581.38 | L18: -155363.08 | M18: -176307.74 | N18: -1360446.8 | O18: -1111220.9 | P18: -939358.02 | Q18: -1225660.5 | R18: -899247.99 | S18: -888454.48 | T18: -769420.67 | U18: -800753.41 | V18: -804620.98 | W18: -924172.02 | X18: -704759.22 | Y18: -765714.41 | Z18: -565003.88 | AA18: -588713.48 | AB18: -381136.15 | AC18: -356084.6 | AD18: -421299.18
A19: 015.xlsx | B19: EBITDA2 | C19: Total | F19: 0 | G19: 0 | H19: 36 | I19: -87908.64 | J19: -107731.21 | K19: -104581.38 | L19: -155363.08 | M19: -176307.74 | N19: -1360446.8 | O19: -1111220.9 | P19: -939358.02 | Q19: -1225660.5 | R19: -899247.99 | S19: -888454.48 | T19: -769420.67 | U19: -800753.41 | V19: -804620.98 | W19: -924172.02 | X19: -704759.22 | Y19: -765714.41 | Z19: -565003.88 | AA19: -588713.48 | AB19: -381136.15 | AC19: -356084.6 | AD19: -421299.18
A20: 015.xlsx | B20: Adjustments historical | C20: Total | E20: 0 | F20: 0 | G20: 0 | H20: 0 | I20: 0 | J20: 0 | K20: 0 | L20: 0 | M20: 0 | N20: 0 | O20: 0 | P20: 0 | Q20: 0 | R20: 0 | S20: 0 | T20: 0 | U20: 0 | V20: 0 | W20: 0 | X20: 0 | Y20: 0 | Z20: 0 | AA20: 0 | AB20: 0 | AC20: 0 | AD20: 0
A21: 015.xlsx | B21: EBITDA2 (adjusted) | C21: Total | E21: 0 | F21: 0 | G21: 0 | H21: 36 | I21: -87908.64 | J21: -107731.21 | K21: -104581.38 | L21: -155363.08 | M21: -176307.74 | N21: -1360446.8 | O21: -1111220.9 | P21: -939358.02 | Q21: -1225660.5 | R21: -899247.99 | S21: -888454.48 | T21: -769420.67 | U21: -800753.41 | V21: -804620.98 | W21: -924172.02 | X21: -704759.22 | Y21: -765714.41 | Z21: -565003.88 | AA21: -588713.48 | AB21: -381136.15 | AC21: -356084.6 | AD21: -421299.18
A22: 015.xlsx | B22: Depreciation & Amortisation | C22: Total | O22: -8313 | P22: -8313 | Q22: -8313 | R22: -8313 | S22: -8313 | T22: -7759 | U22: -8868 | V22: -9145 | W22: -8298 | X22: -8297 | Y22: -8298 | Z22: -8297 | AA22: -8298 | AB22: -8297 | AC22: -8298 | AD22: -8297
A23: 015.xlsx | B23: Financial Items | C23: Total | J23: -66.79 | O23: -275
A24: 015.xlsx | B24: Total | C24: Total | F24: 0 | G24: 0 | H24: 36 | I24: -87908.64 | J24: -107798 | K24: -104581.38 | L24: -155363.08 | M24: -176307.74 | N24: -1360446.8 | O24: -1119808.9 | P24: -947671.02 | Q24: -1233973.5 | R24: -907560.99 | S24: -896767.48 | T24: -777179.67 | U24: -809621.41 | V24: -813765.98 | W24: -932470.02 | X24: -713056.22 | Y24: -774012.41 | Z24: -573300.88 | AA24: -597011.48 | AB24: -389433.15 | AC24: -364382.6 | AD24: -429596.18
A25: 015.xlsx | B25: Total
A26: 015.xlsx
A27: 015.xlsx | B27: Tillämpade filter: CG Item är Selected Period Scenario är inte N/A Value är SEK Inkluderade (4) 2024 (Year), 2025 (Year), 2026 (Year) + January (Month), 2023 (Year) + December (Month) Inkluderade (1) VC VGR (Cost Center Type) + VC StorGöteborg (Business Area) + 015 Karlastaden (Name) Scenario är Actual
A28: 102.xlsx | B28: Year Month No | E28: 202312 | F28: 202401 | G28: 202402 | H28: 202403 | I28: 202404 | J28: 202405 | K28: 202406 | L28: 202407 | M28: 202408 | N28: 202409 | O28: 202410 | P28: 202411 | Q28: 202412 | R28: 202501 | S28: 202502 | T28: 202503 | U28: 202504 | V28: 202505 | W28: 202506 | X28: 202507 | Y28: 202508 | Z28: 202509 | AA28: 202510 | AB28: 202511 | AC28: 202512 | AD28: 202601
A29: 102.xlsx | B29: Scenario | E29: Actual | F29: Actual | G29: Actual | H29: Actual | I29: Actual | J29: Actual | K29: Actual | L29: Actual | M29: Actual | N29: Actual | O29: Actual | P29: Actual | Q29: Actual | R29: Actual | S29: Actual | T29: Actual | U29: Actual | V29: Actual | W29: Actual | X29: Actual | Y29: Actual | Z29: Actual | AA29: Actual | AB29: Actual | AC29: Actual | AD29: Actual
A30: 102.xlsx | B30: ElementName | C30: Reference Account | D30: Cluster | E30: Profit and Loss Table | F30: Profit and Loss Table | G30: Profit and Loss Table | H30: Profit and Loss Table | I30: Profit and Loss Table | J30: Profit and Loss Table | K30: Profit and Loss Table | L30: Profit and Loss Table | M30: Profit and Loss Table | N30: Profit and Loss Table | O30: Profit and Loss Table | P30: Profit and Loss Table | Q30: Profit and Loss Table | R30: Profit and Loss Table | S30: Profit and Loss Table | T30: Profit and Loss Table | U30: Profit and Loss Table | V30: Profit and Loss Table | W30: Profit and Loss Table | X30: Profit and Loss Table | Y30: Profit and Loss Table | Z30: Profit and Loss Table | AA30: Profit and Loss Table | AB30: Profit and Loss Table | AC30: Profit and Loss Table | AD30: Profit and Loss Table
A31: 102.xlsx | B31: Revenue | C31: Total | E31: 3539425.8 | F31: 3373216.1 | G31: 3529393.2 | H31: 3533690.3 | I31: 3544853.9 | J31: 3575957.9 | K31: 3492686.3 | L31: 3420694.5 | M31: 3488483.1 | N31: 3710206.4 | O31: 3313629.2 | P31: 3688494.1 | Q31: 3635877.7 | R31: 3670720.6 | S31: 3645688 | T31: 3806362.2 | U31: 3722878.2 | V31: 3756390.2 | W31: 3604808 | X31: 3535541.6 | Y31: 3496710.3 | Z31: 3711019.5 | AA31: 3716153.6 | AB31: 3613652.5 | AC31: 3796178.7 | AD31: 3430029.6
A32: 102.xlsx | B32: Revenue | C32: Revenues | D32: Total | E32: 3487134.3 | F32: 3282060.1 | G32: 3265822.8 | H32: 3370051.3 | I32: 3380354.9 | J32: 3331807.9 | K32: 3325656.3 | L32: 3306954.5 | M32: 3266033.1 | N32: 3476416.9 | O32: 3140180 | P32: 3527794.1 | Q32: 3472382.7 | R32: 3531921.1 | S32: 3493617 | T32: 3583873.2 | U32: 3522200.6 | V32: 3547192.3 | W32: 3529817 | X32: 3484622.2 | Y32: 3432631.4 | Z32: 3538259.1 | AA32: 3489428.6 | AB32: 3506255.3 | AC32: 3688388.7 | AD32: 3342523.4
A33: 102.xlsx | B33: Revenue | C33: Revenues | D33: RG Huvudintäkter | E33: 3387788.5 | F33: 3257986.8 | G33: 3221008.8 | H33: 3302493.1 | I33: 3274832.3 | J33: 3270634.9 | K33: 3300053.1 | L33: 3298555.5 | M33: 3225088.1 | N33: 3426266.9 | O33: 3070676.5 | P33: 3484742.1 | Q33: 3390123 | R33: 3468679.8 | S33: 3499441.8 | T33: 3508258 | U33: 3505660.1 | V33: 3505660.1 | W33: 3483461 | X33: 3481113.6 | Y33: 3429516.4 | Z33: 3456283.5 | AA33: 3469460 | AB33: 3494373.3 | AC33: 3575214.2 | AD33: 3339426.4
A34: 102.xlsx | B34: Revenue | C34: Revenues | D34: Patientintäkter | E34: 63472.83 | F34: 19817.23 | G34: 31049 | H34: 17942.21 | I34: 81305.64 | J34: 12586 | K34: 0.2 | L34: 2775 | M34: 33340 | N34: 42860 | O34: 25662.55 | P34: 3195 | Q34: 34353.7 | R34: 45944.77 | T34: 42104.42 | U34: 10921.9 | V34: 20147.97 | W34: 12403.29 | Z34: 74895.66 | AA34: 14616.61 | AC34: 25998.48
A35: 102.xlsx | B35: Revenue | C35: Revenues | D35: Övriga intäkter | E35: 35873 | F35: 4256 | G35: 13765 | H35: 49616 | I35: 24217 | J35: 48587 | K35: 25603 | L35: 5624 | M35: 7605 | N35: 7290 | O35: 43841 | P35: 39857 | Q35: 47906 | R35: 17296.6 | S35: -5824.8 | T35: 33510.8 | U35: 5618.6 | V35: 21384.2 | W35: 33952.8 | X35: 3508.6 | Y35: 3115 | Z35: 7080 | AA35: 5352 | AB35: 11882 | AC35: 87176 | AD35: 3097
A36: 102.xlsx | B36: Revenue | C36: Other revenues | D36: Total | E36: 52291.5 | F36: 91156 | G36: 263570.5 | H36: 163639.04 | I36: 164499 | J36: 244150 | K36: 167029.95 | L36: 113740 | M36: 222450 | N36: 233789.55 | O36: 173449.21 | P36: 160700 | Q36: 163495.05 | R36: 138799.5 | S36: 152071 | T36: 222488.98 | U36: 200677.62 | V36: 209197.92 | W36: 74991 | X36: 50919.42 | Y36: 64078.84 | Z36: 172760.34 | AA36: 226725 | AB36: 107397.2 | AC36: 107790 | AD36: 87506.22
A37: 102.xlsx | B37: COGS | C37: Total | E37: -2652479.4 | F37: -2518425.9 | G37: -2614019.9 | H37: -2598007.8 | I37: -2775164 | J37: -2842492.1 | K37: -2739042.5 | L37: -2704049.9 | M37: -2754631.7 | N37: -3092039.1 | O37: -2799911.7 | P37: -2775437.5 | Q37: -2821468.3 | R37: -2650299.6 | S37: -2745698.6 | T37: -2724796.3 | U37: -2483183.2 | V37: -2483479 | W37: -2643545.9 | X37: -2543088.5 | Y37: -2539641.3 | Z37: -2633199.2 | AA37: -2701046.7 | AB37: -2474330.4 | AC37: -2660004 | AD37: -2462201.3
A38: 102.xlsx | B38: COGS | C38: Medical staff | D38: Total | E38: -1655124.9 | F38: -1620790.8 | G38: -1702474.1 | H38: -1588865.5 | I38: -1738137.5 | J38: -1844514.8 | K38: -1805177.3 | L38: -1840020.4 | M38: -1902602.4 | N38: -2083027.1 | O38: -1839555.1 | P38: -1841113.5 | Q38: -1966897.1 | R38: -1780154 | S38: -1870192.2 | T38: -1812623.7 | U38: -1585311.1 | V38: -1553251.9 | W38: -1608763.6 | X38: -1636803.4 | Y38: -1721765.3 | Z38: -1702511.7 | AA38: -1630892.8 | AB38: -1583895.1 | AC38: -1687174.7 | AD38: -1639769.8
A39: 102.xlsx | B39: COGS | C39: Other direct costs | D39: Total | E39: -997354.58 | F39: -897635.13 | G39: -911545.79 | H39: -1009142.3 | I39: -1037026.5 | J39: -997977.35 | K39: -933865.22 | L39: -864029.5 | M39: -852029.29 | N39: -1009012 | O39: -960356.63 | P39: -934324.02 | Q39: -854571.17 | R39: -870145.6 | S39: -875506.41 | T39: -912172.6 | U39: -897872.02 | V39: -930227.13 | W39: -1034782.3 | X39: -906285.13 | Y39: -817876.07 | Z39: -930687.45 | AA39: -1070153.9 | AB39: -890435.29 | AC39: -972829.35 | AD39: -822431.49
A40: 102.xlsx | B40: Gross Profit | C40: Total | E40: 886946.41 | F40: 854790.15 | G40: 915373.31 | H40: 935682.5 | I40: 769689.92 | J40: 733465.79 | K40: 753643.75 | L40: 716644.56 | M40: 733851.43 | N40: 618167.28 | O40: 513717.48 | P40: 913056.58 | Q40: 814409.43 | R40: 1020421 | S40: 899989.44 | T40: 1081565.9 | U40: 1239695.1 | V40: 1272911.2 | W40: 961262.18 | X40: 992453.12 | Y40: 957068.92 | Z40: 1077820.3 | AA40: 1015107 | AB40: 1139322.1 | AC40: 1136174.7 | AD40: 967828.26
...

Sheet Info
B4: Antal listade pat | C4: 202312 | D4: 202401 | E4: 202402 | F4: 202403 | G4: 202404 | H4: 202405 | I4: 202406 | J4: 202407 | K4: 202408 | L4: 202409 | M4: 202410 | N4: 202411 | O4: 202412 | P4: 202501 | Q4: 202502 | R4: 202503 | S4: 202504 | T4: 202505 | U4: 202506 | V4: 202507 | W4: 202508 | X4: 202509 | Y4: 202510 | Z4: 202511 | AA4: 202512 | AB4: 202601 | AC4: 202602 | AD4: KST | AE4: Diff
B5: Citysjukhuset Plus 7 vårdcentral | C5: 5094 | D5: 5121 | E5: 5169 | F5: 5181 | G5: 5163 | H5: 5188 | I5: 5209 | J5: 5191 | K5: 5206 | L5: 5220 | M5: 5284 | N5: 5400 | O5: 5493 | P5: 6477 | Q5: 6493 | R5: 6484 | S5: 6465 | T5: 6467 | U5: 6437 | V5: 6417 | W5: 6399 | X5: 6404 | Y5: 6376 | Z5: 6338 | AA5: 6299 | AB5: 6276 | AC5: 6258 | AD5: 4020 | AE5: =AC5-AB5 -> -18
B6: Kvarterskliniken Avenyn | C6: 5557 | D6: 5568 | E6: 5578 | F6: 5589 | G6: 5608 | H6: 5603 | I6: 5580 | J6: 5601 | K6: 5627 | L6: 5653 | M6: 5691 | N6: 5786 | O6: 5872 | P6: 6055 | Q6: 6038 | R6: 6037 | S6: 6036 | T6: 6015 | U6: 6004 | V6: 6018 | W6: 6001 | X6: 5975 | Y6: 5990 | Z6: 5984 | AA6: 5971 | AB6: 5981 | AC6: 5963 | AD6: 302 | AE6: =AC6-AB6 -> -18
B7: Kvarterskliniken Husaren | C7: 4304 | D7: 4262 | E7: 4221 | F7: 4188 | G7: 4176 | H7: 4152 | I7: 4144 | J7: 4155 | K7: 4149 | L7: 4170 | M7: 4145 | N7: 4147 | O7: 4146 | P7: 4422 | Q7: 4403 | R7: 4388 | S7: 4379 | T7: 4379 | U7: 4352 | V7: 4329 | W7: 4320 | X7: 4293 | Y7: 4287 | Z7: 4273 | AA7: 4266 | AB7: 4251 | AC7: 4226 | AD7: 304 | AE7: =AC7-AB7 -> -25
B8: Kvarterskliniken Karlastaden | C8: 0 | D8: 0 | E8: 0 | F8: 0 | G8: 0 | H8: 0 | I8: 0 | J8: 0 | K8: 0 | L8: 195 | M8: 358 | N8: 469 | O8: 546 | P8: 635 | Q8: 705 | R8: 767 | S8: 826 | T8: 878 | U8: 954 | V8: 1025 | W8: 1153 | X8: 1275 | Y8: 1376 | Z8: 1456 | AA8: 1521 | AB8: 1613 | AC8: 1679 | AD8: 15 | AE8: =AC8-AB8 -> 66
B9: Kvarterskliniken Lorensberg | C9: 1621 | D9: 1615 | E9: 1609 | F9: 1604 | G9: 1599 | H9: 1591 | I9: 1577 | J9: 1568 | K9: 1548 | L9: 1546 | M9: 1556 | N9: 1566 | O9: 1570 | P9: 1627 | Q9: 1617 | R9: 1623 | S9: 1609 | T9: 1602 | U9: 1588 | V9: 1573 | W9: 1561 | X9: 1547 | Y9: 1539 | Z9: 1531 | AA9: 1524 | AB9: 1506 | AC9: 1501 | AD9: 303 | AE9: =AC9-AB9 -> -5
B10: Omtanken Vårdcentral Frölunda Torg | C10: 8160 | D10: 8140 | E10: 8115 | F10: 8102 | G10: 8110 | H10: 8098 | I10: 8097 | J10: 8077 | K10: 8085 | L10: 8125 | M10: 8128 | N10: 8130 | O10: 8148 | P10: 8168 | Q10: 8167 | R10: 8191 | S10: 8187 | T10: 8155 | U10: 8133 | V10: 8129 | W10: 8149 | X10: 8158 | Y10: 8143 | Z10: 8124 | AA10: 8088 | AB10: 8033 | AC10: 8009 | AD10: 102 | AE10: =AC10-AB10 -> -24
B11: Omtanken Vårdcentral Grimmered | C11: 6273 | D11: 6299 | E11: 6278 | F11: 6310 | G11: 6311 | H11: 6327 | I11: 6321 | J11: 6371 | K11: 6451 | L11: 6525 | M11: 6612 | N11: 6650 | O11: 6670 | P11: 6731 | Q11: 6754 | R11: 6820 | S11: 6816 | T11: 6869 | U11: 6890 | V11: 6878 | W11: 6918 | X11: 6940 | Y11: 6966 | Z11: 6951 | AA11: 6977 | AB11: 6971 | AC11: 6969 | AD11: 103 | AE11: =AC11-AB11 -> -2
B12: Omtanken Vårdcentral Kviberg | C12: 3982 | D12: 4021 | E12: 4081 | F12: 4136 | G12: 4144 | H12: 4146 | I12: 4073 | J12: 4038 | K12: 4065 | L12: 4093 | M12: 4105 | N12: 4094 | O12: 4106 | P12: 4161 | Q12: 4169 | R12: 4194 | S12: 4180 | T12: 4219 | U12: 4224 | V12: 4223 | W12: 4253 | X12: 4265 | Y12: 4270 | Z12: 4280 | AA12: 4285 | AB12: 4325 | AC12: 4332 | AD12: 110 | AE12: =AC12-AB12 -> 7
B13: Omtanken Vårdcentral Kållered | C13: 1568 | D13: 1565 | E13: 1561 | F13: 1558 | G13: 1552 | H13: 1552 | I13: 1573 | J13: 1584 | K13: 1570 | L13: 1577 | M13: 1578 | N13: 1564 | O13: 1553 | P13: 1556 | Q13: 1558 | R13: 1567 | S13: 1553 | T13: 1541 | U13: 1541 | V13: 1539 | W13: 1539 | X13: 1527 | Y13: 1519 | Z13: 1511 | AA13: 1528 | AB13: 1541 | AC13: 1535 | AD13: 109 | AE13: =AC13-AB13 -> -6
B14: Omtanken Vårdcentral Landala | C14: 6618 | D14: 6636 | E14: 6673 | F14: 6670 | G14: 6649 | H14: 6656 | I14: 6652 | J14: 6631 | K14: 6675 | L14: 6695 | M14: 6725 | N14: 6758 | O14: 6751 | P14: 6992 | Q14: 6983 | R14: 6967 | S14: 6959 | T14: 6866 | U14: 6774 | V14: 6712 | W14: 6696 | X14: 6634 | Y14: 6564 | Z14: 6537 | AA14: 6481 | AB14: 6448 | AC14: 6431 | AD14: 106 | AE14: =AC14-AB14 -> -17
B15: Omtanken Vårdcentral Majorna | C15: 6259 | D15: 6254 | E15: 6241 | F15: 6271 | G15: 6277 | H15: 6292 | I15: 6303 | J15: 6305 | K15: 6353 | L15: 6406 | M15: 6421 | N15: 6425 | O15: 6444 | P15: 6525 | Q15: 6515 | R15: 6537 | S15: 6546 | T15: 6536 | U15: 6520 | V15: 6512 | W15: 6508 | X15: 6490 | Y15: 6477 | Z15: 6446 | AA15: 6420 | AB15: 6381 | AC15: 6372 | AD15: 104 | AE15: =AC15-AB15 -> -9
B16: Omtanken Vårdcentral Olskroken | C16: 3444 | D16: 3486 | E16: 3544 | F16: 3620 | G16: 3666 | H16: 3727 | I16: 3769 | J16: 3827 | K16: 3912 | L16: 4013 | M16: 4114 | N16: 4170 | O16: 4217 | P16: 4374 | Q16: 4451 | R16: 4498 | S16: 4487 | T16: 4503 | U16: 4528 | V16: 4546 | W16: 4619 | X16: 4679 | Y16: 4707 | Z16: 4740 | AA16: 4776 | AB16: 4809 | AC16: 4845 | AD16: 111 | AE16: =AC16-AB16 -> 36
... B18: Omtanken Vårdcentral Åby | C18: 5092 | D18: 5091 | E18: 5085 | F18: 5063 | G18: 5057 | H18: 5057 | I18: 5054 | J18: 5059 | K18: 5045 | L18: 5032 | M18: 5035 | N18: 5061 | O18: 5063 | P18: 5052 | Q18: 5075 | R18: 5063 | S18: 5030 | T18: 5041 | U18: 5030 | V18: 5020 | W18: 5022 | X18: 5013 | Y18: 5009 | Z18: 5019 | AA18: 5028 | AB18: 5043 | AC18: 5034 | AD18: 108 | AE18: =AC18-AB18 -> -9
C19: =SUM(C5:C18) -> 63760 | D19: =SUM(D5:D18) -> 63838 | E19: =SUM(E5:E18) -> 63938 | F19: =SUM(F5:F18) -> 64083 | G19: =SUM(G5:G18) -> 64141 | H19: =SUM(H5:H18) -> 64235 | I19: =SUM(I5:I18) -> 64209 | J19: =SUM(J5:J18) -> 64278 | ... AC19: =SUM(AC5:AC18) -> 68777 | AE19: =AC19-AB19 -> -22
D20: =D19-C19 -> 78 | E20: =E19-D19 -> 100 | F20: =F19-E19 -> 145 | G20: =G19-F19 -> 58 | H20: =H19-G19 -> 94 | I20: =I19-H19 -> -26 | J20: =J19-I19 -> 69 | K20: =K19-J19 -> 284 | ... AC20: =AC19-AB19 -> -22
B21: Antal listningpoäng | C21: 202312 | D21: 202401 | E21: 202402 | F21: 202403 | G21: 202404 | H21: 202405 | I21: 202406 | J21: 202407 | K21: 202408 | L21: 202409 | M21: 202410 | N21: 202411 | O21: 202412 | P21: 202501 | Q21: 202502 | R21: 202503 | S21: 202504 | T21: 202505 | U21: 202506 | V21: 202507 | W21: 202508 | X21: 202509 | Y21: 202510 | Z21: 202511 | AA21: 202512 | AB21: 202601 | AC21: 202602
B22: Citysjukhuset Plus 7 vårdcentral | C22: 1418.148 | D22: 1427.5046 | E22: 1440.5564 | F22: 1453.886 | G22: 1455.1349 | H22: 1463.8688 | I22: 1469.7928 | J22: 1463.9962 | K22: 1474.3264 | L22: 1480.9587 | M22: 1503.829 | N22: 1549.6673 | O22: 1576.4664 | P22: 1819.6745 | Q22: 1818.7075 | R22: 1819.192 | S22: 1811.63 | T22: 1821 | U22: 1809.81 | V22: 1806.84 | W22: 1805.32 | X22: 1804 | Y22: 1792.6021 | Z22: 1785.502 | AA22: 1775.23 | AB22: 1772.6348 | AC22: 1777.8733 | AD22: 4020
B23: Kvarterskliniken Avenyn | C23: 1904.024 | D23: 1903.5358 | E23: 1905.3599 | F23: 1910.7074 | G23: 1916.1973 | H23: 1917.5221 | I23: 1905.9663 | J23: 1908.5777 | K23: 1912.7467 | L23: 1913.7144 | M23: 1935.6688 | N23: 1979.79 | O23: 2017.7743 | P23: 2065.2218 | Q23: 2063.1477 | R23: 2055.7361 | S23: 2062.2038 | T23: 2054 | U23: 2054 | V23: 2067 | W23: 2071.88 | X23: 2057 | Y23: 2059.4543 | Z23: 2057.2127 | AA23: 2055.999 | AB23: 2062.6849 | AC23: 2054.543 | AD23: 302
B24: Kvarterskliniken Husaren | C24: 1295.7489 | D24: 1284.3455 | E24: 1278.0028 | F24: 1270.0322 | G24: 1268.4389 | H24: 1264.1947 | I24: 1259.4946 | J24: 1260.0752 | K24: 1259.9805 | L24: 1256.0942 | M24: 1260.986 | N24: 1249.8487 | O24: 1245.2986 | P24: 1322.6351 | Q24: 1314.5113 | R24: 1313.2617 | S24: 1312.5025 | T24: 1303 | U24: 1303.95 | V24: 1302.35 | W24: 1296.61 | X24: 1288 | Y24: 1276.1561 | Z24: 1276.9972 | AA24: 1277.136 | AB24: 1286.7833 | AC24: 1279.5822 | AD24: 304
B25: Kvarterskliniken Karlastaden | C25: 0 | D25: 0 | E25: 0 | F25: 0 | G25: 0 | H25: 0 | I25: 0 | J25: 0 | K25: 0 | L25: 48.700658 | M25: 96.244616 | N25: 118.65989 | O25: 144.6085 | P25: 169.49809 | Q25: 187.13266 | R25: 207.46878 | S25: 228.67908 | T25: 240 | U25: 263 | V25: 275.84 | W25: 297.61 | X25: 324 | Y25: 348.86238 | Z25: 369.47882 | AA25: 383.641 | AB25: 412.51453 | AC25: 429.35025 | AD25: 15
B26: Kvarterskliniken Lorensberg | C26: 523.81771 | D26: 523.64099 | E26: 524.9131 | F26: 522.29086 | G26: 521.70818 | H26: 522.54421 | I26: 523.50769 | J26: 523.33477 | K26: 518.708 | L26: 520.73776 | M26: 526.60806 | N26: 524.85967 | O26: 526.5664 | P26: 541.18391 | Q26: 538.09678 | R26: 537.57928 | S26: 531.65464 | T26: 532 | U26: 530 | V26: 526 | W26: 529.81 | X26: 528 | Y26: 524.5909 | Z26: 523.32393 | AA26: 522.702 | AB26: 520.10755 | AC26: 518.84278 | AD26: 303
B27: Omtanken Vårdcentral Frölunda Torg | C27: 2666.6628 | D27: 2664.4166 | E27: 2675.5121 | F27: 2670.09 | G27: 2671.9079 | H27: 2656.6497 | I27: 2664.03 | J27: 2659.9214 | K27: 2646.737 | L27: 2661.1881 | M27: 2663.0191 | N27: 2659.3426 | O27: 2674.9092 | P27: 2672.3042 | Q27: 2669.5688 | R27: 2674.2258 | S27: 2676.924 | T27: 2679 | U27: 2667 | V27: 2668.32 | W27: 2678.35 | X27: 2674 | Y27: 2661.4013 | Z27: 2651.7317 | AA27: 2642.123 | AB27: 2621.6264 | AC27: 2604.1029 | AD27: 102
B28: Omtanken Vårdcentral Grimmered | C28: 2014.7678 | D28: 2031.0918 | E28: 2027.6241 | F28: 2028.0519 | G28: 2015.6309 | H28: 2035.5099 | I28: 2047.0257 | J28: 2055.4542 | K28: 2070.4378 | L28: 2081.2006 | M28: 2117.0262 | N28: 2126.3342 | O28: 2131.3652 | P28: 2147.0344 | Q28: 2145.0899 | R28: 2170.8674 | S28: 2168.6043 | T28: 2183 | U28: 2213 | V28: 2201.69 | W28: 2197 | X28: 2193 | Y28: 2210.1801 | Z28: 2210.93 | AA28: 2230.888 | AB28: 2242.4798 | AC28: 2246.9921 | AD28: 103
B29: Omtanken Vårdcentral Kviberg | C29: 1216.0798 | D29: 1238.4741 | E29: 1270.2314 | F29: 1309.579 | G29: 1323.5485 | H29: 1340.2792 | I29: 1239.1595 | J29: 1170.9282 | K29: 1156.9968 | L29: 1173.663 | M29: 1172.8969 | N29: 1155.3642 | O29: 1156.4775 | P29: 1174.5014 | Q29: 1174.608 | R29: 1181.0767 | S29: 1164.85 | T29: 1193 | U29: 1208 | V29: 1202.81 | W29: 1200 | X29: 1193 | Y29: 1197.9489 | Z29: 1212.2265 | AA29: 1218.456 | AB29: 1244.5998 | AC29: 1257.1429 | AD29: 110
B30: Omtanken Vårdcentral Kållered | C30: 453.248 | D30: 449.42548 | E30: 442.21365 | F30: 447.9617 | G30: 442.08169 | H30: 443.4498 | I30: 443.95001 | J30: 449.03375 | K30: 443.24275 | L30: 446.14863 | M30: 440.85267 | N30: 437.70511 | O30: 437.81015 | P30: 434.00445 | Q30: 433.53083 | R30: 438.15103 | S30: 436.7541 | T30: 430 | U30: 433 | V30: 430.43 | W30: 431.76 | X30: 429 | Y30: 427.03265 | Z30: 420.61049 | AA30: 425.142 | AB30: 427.61583 | AC30: 422.71977 | AD30: 109
B31: Omtanken Vårdcentral Landala | C31: 1773.2739 | D31: 1776.9541 | E31: 1789.3903 | F31: 1786.3537 | G31: 1774.7599 | H31: 1780.4125 | I31: 1783.4177 | J31: 1781.4637 | K31: 1792.9008 | L31: 1813.1635 | M31: 1834.1222 | N31: 1871.1094 | O31: 1881.1119 | P31: 1954.7461 | Q31: 1947.7604 | R31: 1946.4839 | S31: 1949.629 | T31: 1917 | U31: 1896 | V31: 1879.57 | W31: 1872.3 | X31: 1856 | Y31: 1840.815 | Z31: 1838.9235 | AA31: 1833.813 | AB31: 1833.3992 | AC31: 1828.9247 | AD31: 106
B32: Omtanken Vårdcentral Majorna | C32: 1891.2464 | D32: 1892.653 | E32: 1910.0853 | F32: 1923.5407 | G32: 1940.3587 | H32: 1950.2907 | I32: 1953.2692 | J32: 1954.5968 | K32: 1978.2504 | L32: 1995.726 | M32: 2012.66 | N32: 2009.3677 | O32: 2014.7344 | P32: 2018.5867 | Q32: 2019.8604 | R32: 2042.2714 | S32: 2045.5672 | T32: 2033 | U32: 2037 | V32: 2031.37 | W32: 2022.83 | X32: 2020 | Y32: 2020.4947 | Z32: 2000.3658 | AA32: 1994.534 | AB32: 1987.2639 | AC32: 1967.0332 | AD32: 104
B33: Omtanken Vårdcentral Olskroken | C33: 1126.1003 | D33: 1144.7968 | E33: 1187.04 | F33: 1213.9066 | G33: 1239.8548 | H33: 1280.8001 | I33: 1305.6438 | J33: 1341.109 | K33: 1358.1993 | L33: 1376.8282 | M33: 1409.3586 | N33: 1443.6362 | O33: 1458.0202 | P33: 1513.4803 | Q33: 1544.0182 | R33: 1578.9385 | S33: 1575.1461 | T33: 1569 | U33: 1595 | V33: 1604.17 | W33: 1624 | X33: 1652 | Y33: 1653.5613 | Z33: 1674.5155 | AA33: 1684.434 | AB33: 1696.9696 | AC33: 1721.5702 | AD33: 111
... B35: Omtanken Vårdcentral Åby | C35: 1592.926 | D35: 1585.0119 | E35: 1595.499 | F35: 1598.5341 | G35: 1613.4864 | H35: 1605.0992 | I35: 1606.2454 | J35: 1617.8121 | K35: 1616.1174 | L35: 1616.337 | M35: 1609.6472 | N35: 1630.4355 | O35: 1622.9446 | P35: 1615.8311 | Q35: 1617.4825 | R35: 1612.9131 | S35: 1603.1143 | T35: 1603 | U35: 1596 | V35: 1586.95 | W35: 1581.42 | X35: 1579 | Y35: 1573.8367 | Z35: 1580.5985 | AA35: 1578.722 | AB35: 1584.594 | AC35: 1587.5775 | AD35: 108
C36: =SUM(C22:C35) -> 19501.258 | D36: =SUM(D22:D35) -> 19548.719 | E36: =SUM(E22:E35) -> 19690.007 | F36: =SUM(F22:F35) -> 19786.079 | G36: =SUM(G22:G35) -> 19847.919 | H36: =SUM(H22:H35) -> 19933.757 | I36: =SUM(I22:I35) -> 19883.608 | J36: =SUM(J22:J35) -> 19871.158 | ... AC36: =SUM(AC22:AC35) -> 21330.334
D37: =D36-C36 -> 47.460234 | E37: =E36-D36 -> 141.28831 | F37: =F36-E36 -> 96.071714 | G37: =G36-F36 -> 61.840846 | H37: =H36-G36 -> 85.837768 | I37: =I36-H36 -> -50.149212 | J37: =J36-I36 -> -12.450405 | K37: =K36-J36 -> 53.111306 | ... AA37: =AA36-Z36 -> 16.989087
B38: ACG casemix | C38: 202312 | D38: 202401 | E38: 202402 | F38: 202403 | G38: 202404 | H38: 202405 | I38: 202406 | J38: 202407 | K38: 202408 | L38: 202409 | M38: 202410 | N38: 202411 | O38: 202412 | P38: 202501 | Q38: 202502 | R38: 202503 | S38: 202504 | T38: 202505 | U38: 202506 | V38: 202507 | W38: 202508 | X38: 202509 | Y38: 202510 | Z38: 202511 | AA38: 202512 | AB38: 202601 | AC38: 202602
B39: Citysjukhuset Plus 7 vårdcentral | C39: 1.0614071 | D39: 0.97451976 | E39: 0.98125772 | F39: 0.98832216 | G39: 0.99099207 | H39: 0.9992378 | I39: 1.007592 | J39: 1.0228048 | K39: 1.0226357 | L39: 1.0334026 | M39: 1.0417446 | N39: 1.0530516 | O39: 1.0716561 | P39: 1.0004408 | Q39: 0.91926722 | R39: 0.93233529 | S39: 0.94249874 | T39: 0.95107248 | U39: 0.95190702 | V39: 0.96322927 | W39: 0.96961355 | X39: 0.98133215 | Y39: 0.99035259 | Z39: 0.99304919 | AA39: 1.0143835 | AB39: 1.0067129 | AC39: 1.0059425 | AD39: 4020
B40: Kvarterskliniken Avenyn | C40: 1.075854 | D40: 1.0382789 | E40: 1.0379765 | F40: 1.0339203 | G40: 1.0373011 | H40: 1.0422695 | I40: 1.0397034 | J40: 1.0388481 | K40: 1.0280763 | L40: 1.0251968 | M40: 1.0338745 | N40: 1.0365646 | O40: 1.0401888 | P40: 1.0275679 | Q40: 0.99454842 | R40: 0.99969372 | S40: 0.99595987 | T40: 0.99771068 | U40: 0.98556347 | V40: 0.98021903 | W40: 0.97543844 | X40: 0.98015176 | Y40: 0.98970981 | Z40: 0.98740021 | AA40: 1.002564 | AB40: 0.99909259 | AC40: 1.0086668 | AD40: 302
B41: Kvarterskliniken Husaren | C41: 1.0128972 | D41: 0.98877368 | E41: 0.99337215 | F41: 0.99566803 | G41: 0.98475143 | H41: 0.98425641 | I41: 0.96612632 | J41: 0.95385616 | K41: 0.93480236 | L41: 0.92254799 | M41: 0.91027484 | N41: 0.90466167 | O41: 0.89559576 | P41: 0.87927581 | Q41: 0.85566579 | R41: 0.86615536 | S41: 0.86974206 | T41: 0.8817445 | U41: 0.88279128 | V41: 0.89443921 | W41: 0.90232456 | X41: 0.90421144 | Y41: 0.91182601 | Z41: 0.91242282 | AA41: 0.93226291 | AB41: 0.935644 | AC41: 0.94237833 | AD41: 304
B42: Kvarterskliniken Karlastaden | C42: 0 | D42: 0 | E42: 0 | F42: 0 | G42: 0 | H42: 0 | I42: 0 | J42: 0 | K42: 0 | L42: 0.63217057 | M42: 0.64730782 | N42: 0.74855712 | O42: 0.8127165 | P42: 0.84829632 | Q42: 0.84788537 | R42: 0.86382487 | S42: 0.87180089 | T42: 0.91030146 | U42: 0.92467725 | V42: 0.9403678 | W42: 0.91189916 | X42: 0.90291571 | Y42: 0.92886065 | Z42: 0.95469265 | AA42: 0.97126983 | AB42: 0.98795358 | AC42: 1.0042477 | AD42: 15
B43: Kvarterskliniken Lorensberg | C43: 0.90236362 | D43: 0.86693574 | E43: 0.87198303 | F43: 0.88203489 | G43: 0.88721764 | H43: 0.89133838 | I43: 0.90970316 | J43: 0.92034375 | K43: 0.91036353 | L43: 0.90250965 | M43: 0.91269318 | N43: 0.89347751 | O43: 0.89242936 | P43: 0.87113736 | Q43: 0.84556546 | R43: 0.84319421 | S43: 0.85260109 | T43: 0.85365011 | U43: 0.85490046 | V43: 0.85275455 | W43: 0.84483907 | X43: 0.84488721 | Y43: 0.83872827 | Z43: 0.83728296 | AA43: 0.83749337 | AB43: 0.84340985 | AC43: 0.85321029 | AD43: 303
B44: Omtanken Vårdcentral Frölunda Torg | C44: 0.99226622 | D44: 0.9941307 | E44: 0.99623528 | F44: 1.0030491 | G44: 1.0080654 | H44: 1.0132702 | I44: 1.0174282 | J44: 1.0211185 | K44: 1.0170662 | L44: 1.0256269 | M44: 1.0241464 | N44: 1.0269294 | O44: 1.0383104 | P44: 1.0379828 | Q44: 1.0431162 | R44: 1.0429832 | S44: 1.0404559 | T44: 1.0298318 | U44: 1.0247453 | V44: 1.0155085 | W44: 1.0142644 | X44: 1.0089771 | Y44: 1.0068867 | Z44: 0.99956986 | AA44: 0.99682261 | AB44: 0.98628166 | AC44: 0.98163636 | AD44: 102
B45: Omtanken Vårdcentral Grimmered | C45: 0.85812144 | D45: 0.85414313 | E45: 0.86510758 | F45: 0.87464203 | G45: 0.88616937 | H45: 0.89976884 | I45: 0.90394198 | J45: 0.90588572 | K45: 0.90158835 | L45: 0.89516811 | M45: 0.89103144 | N45: 0.90164625 | O45: 0.91476237 | P45: 0.91124103 | Q45: 0.91959553 | R45: 0.92111332 | S45: 0.92637996 | T45: 0.9231271 | U45: 0.9236994 | V45: 0.93016302 | W45: 0.9238617 | X45: 0.91179798 | Y45: 0.90559317 | Z45: 0.90304055 | AA45: 0.9001268 | AB45: 0.89803686 | AC45: 0.89683373 | AD45: 103
...

Sheet Data
A3: Intäkter / listad pat | B3: 202312 | C3: 202401 | D3: 202402 | E3: 202403 | F3: 202404 | G3: 202405 | H3: 202406 | I3: 202407 | J3: 202408 | K3: 202409 | L3: 202410 | M3: 202411 | N3: 202412 | O3: 202501 | P3: 202502 | Q3: 202503 | R3: 202504 | S3: 202505 | T3: 202506 | U3: 202507 | V3: 202508 | W3: 202509 | X3: 202510 | Y3: 202511 | Z3: 202512 | AA3: 202601 | AB3: 202602
A4: Citysjukhuset Plus 7 vårdcentral | B4: =Info!C56/Info!C5 -> 345.82843 | C4: =Info!D56/Info!D5 -> 310.27436 | D4: =Info!E56/Info!E5 -> 306.3401 | E4: =Info!F56/Info!F5 -> 313.32581 | F4: =Info!G56/Info!G5 -> 316.53787 | G4: =Info!H56/Info!H5 -> 314.51966 | H4: =Info!I56/Info!I5 -> 314.80015 | I4: =Info!J56/Info!J5 -> 316.73454 | ... AB4: =Info!AC56/Info!AC5 -> 352.79147
A5: Kvarterskliniken Avenyn | B5: =Info!C57/Info!C6 -> 478.04701 | C5: =Info!D57/Info!D6 -> 391.86835 | D5: =Info!E57/Info!E6 -> 392.91149 | E5: =Info!F57/Info!F6 -> 399.38636 | F5: =Info!G57/Info!G6 -> 394.10746 | G5: =Info!H57/Info!H6 -> 400.18571 | H5: =Info!I57/Info!I6 -> 402.94227 | I5: =Info!J57/Info!J6 -> 393.2544 | ... AB5: =Info!AC57/Info!AC6 -> 435.21466
A6: Kvarterskliniken Husaren | B6: =Info!C58/Info!C7 -> 349.05158 | C6: =Info!D58/Info!D7 -> 339.92825 | D6: =Info!E58/Info!E7 -> 328.0571 | E6: =Info!F58/Info!F7 -> 342.00125 | F6: =Info!G58/Info!G7 -> 338.72501 | G6: =Info!H58/Info!H7 -> 340.0054 | H6: =Info!I58/Info!I7 -> 335.1773 | I6: =Info!J58/Info!J7 -> 331.72148 | ... AB6: =Info!AC58/Info!AC7 -> 357.58471
A7: Kvarterskliniken Karlastaden | B7: 0 | C7: 0 | D7: 0 | E7: 0 | F7: 0 | G7: 0 | H7: 0 | I7: 0 | J7: 0 | K7: =Info!L59/Info!L8 -> 220.29344 | L7: =Info!M59/Info!M8 -> 244.05578 | M7: =Info!N59/Info!N8 -> 319.32757 | N7: =Info!O59/Info!O8 -> 287.5567 | O7: =Info!P59/Info!P8 -> 319.1643 | P7: =Info!Q59/Info!Q8 -> 318.91458 | Q7: =Info!R59/Info!R8 -> 323.82446 | R7: =Info!S59/Info!S8 -> 333.53291 | ... AB7: =Info!AC59/Info!AC8 -> 313.33353
A8: Kvarterskliniken Lorensberg | B8: =Info!C60/Info!C9 -> 355.7245 | C8: =Info!D60/Info!D9 -> 333.38693 | D8: =Info!E60/Info!E9 -> 333.42062 | E8: =Info!F60/Info!F9 -> 343.24852 | F8: =Info!G60/Info!G9 -> 339.87729 | G8: =Info!H60/Info!H9 -> 348.70966 | H8: =Info!I60/Info!I9 -> 356.36023 | I8: =Info!J60/Info!J9 -> 358.05825 | ... AB8: =Info!AC60/Info!AC9 -> 375.69354
A9: Omtanken Vårdcentral Frölunda Torg | B9: =Info!C61/Info!C10 -> 415.17016 | C9: =Info!D61/Info!D10 -> 400.24408 | D9: =Info!E61/Info!E10 -> 396.92036 | E9: =Info!F61/Info!F10 -> 407.61455 | F9: =Info!G61/Info!G10 -> 403.80176 | G9: =Info!H61/Info!H10 -> 403.88181 | H9: =Info!I61/Info!I10 -> 407.56492 | I9: =Info!J61/Info!J10 -> 408.3887 | ... AB9: =Info!AC61/Info!AC10 -> 430.23149
A10: Omtanken Vårdcentral Grimmered | B10: =Info!C62/Info!C11 -> 424.89329 | C10: =Info!D62/Info!D11 -> 398.2654 | D10: =Info!E62/Info!E11 -> 395.33695 | E10: =Info!F62/Info!F11 -> 404.29719 | F10: =Info!G62/Info!G11 -> 396.26026 | G10: =Info!H62/Info!H11 -> 408.8493 | H10: =Info!I62/Info!I11 -> 409.00584 | I10: =Info!J62/Info!J11 -> 402.33019 | ... AB10: =Info!AC62/Info!AC11 -> 419.4896
A11: Omtanken Vårdcentral Kviberg | B11: =Info!C63/Info!C12 -> 357.6303 | C11: =Info!D63/Info!D12 -> 348.06378 | D11: =Info!E63/Info!E12 -> 340.62957 | E11: =Info!F63/Info!F12 -> 355.06998 | F11: =Info!G63/Info!G12 -> 353.17005 | G11: =Info!H63/Info!H12 -> 362.04301 | H11: =Info!I63/Info!I12 -> 335.18412 | I11: =Info!J63/Info!J12 -> 322.08084 | ... AB11: =Info!AC63/Info!AC12 -> 324.21445
A12: Omtanken Vårdcentral Kållered | B12: =Info!C64/Info!C13 -> 309.84685 | C12: =Info!D64/Info!D13 -> 305.7038 | D12: =Info!E64/Info!E13 -> 301.92279 | E12: =Info!F64/Info!F13 -> 309.83359 | F12: =Info!G64/Info!G13 -> 305.56799 | G12: =Info!H64/Info!H13 -> 303.6787 | H12: =Info!I64/Info!I13 -> 303.10567 | I12: =Info!J64/Info!J13 -> 303.62883 | ... AB12: =Info!AC64/Info!AC13 -> 327.91596
A13: Omtanken Vårdcentral Landala | B13: =Info!C65/Info!C14 -> 267.41708 | C13: =Info!D65/Info!D14 -> 264.31612 | D13: =Info!E65/Info!E14 -> 261.40537 | E13: =Info!F65/Info!F14 -> 261.39554 | F13: =Info!G65/Info!G14 -> 261.6434 | G13: =Info!H65/Info!H14 -> 262.56311 | H13: =Info!I65/Info!I14 -> 268.13001 | I13: =Info!J65/Info!J14 -> 267.73027 | ... AB13: =Info!AC65/Info!AC14 -> 314.48282
A14: Omtanken Vårdcentral Majorna | B14: =Info!C66/Info!C15 -> 371.51605 | C14: =Info!D66/Info!D15 -> 364.95725 | D14: =Info!E66/Info!E15 -> 365.10276 | E14: =Info!F66/Info!F15 -> 370.98795 | F14: =Info!G66/Info!G15 -> 369.62297 | G14: =Info!H66/Info!H15 -> 367.23963 | H14: =Info!I66/Info!I15 -> 372.22595 | I14: =Info!J66/Info!J15 -> 363.57481 | ... AB14: =Info!AC66/Info!AC15 -> 400.16933
A15: Omtanken Vårdcentral Olskroken | B15: =Info!C67/Info!C16 -> 411.73551 | C15: =Info!D67/Info!D16 -> 381.04036 | D15: =Info!E67/Info!E16 -> 375.08433 | E15: =Info!F67/Info!F16 -> 393.40917 | F15: =Info!G67/Info!G16 -> 392.4096 | G15: =Info!H67/Info!H16 -> 400.06908 | H15: =Info!I67/Info!I16 -> 413.51363 | I15: =Info!J67/Info!J16 -> 403.87099 | ... AB15: =Info!AC67/Info!AC16 -> 428.63282
A16: Omtanken Vårdcentral Pedagogen Park | B16: =Info!C68/Info!C17 -> 305.76473 | C16: =Info!D68/Info!D17 -> 303.46051 | D16: =Info!E68/Info!E17 -> 301.63549 | E16: =Info!F68/Info!F17 -> 301.07205 | F16: =Info!G68/Info!G17 -> 298.45033 | G16: =Info!H68/Info!H17 -> 298.94288 | H16: =Info!I68/Info!I17 -> 304.52464 | I16: =Info!J68/Info!J17 -> 302.38791 | ... AB16: =Info!AC68/Info!AC17 -> 323.03006
A17: Omtanken Vårdcentral Åby | B17: =Info!C69/Info!C18 -> 388.88078 | C17: =Info!D69/Info!D18 -> 365.55023 | D17: =Info!E69/Info!E18 -> 366.44689 | E17: =Info!F69/Info!F18 -> 366.81394 | F17: =Info!G69/Info!G18 -> 370.94588 | G17: =Info!H69/Info!H18 -> 371.04444 | H17: =Info!I69/Info!I18 -> 367.50891 | I17: =Info!J69/Info!J18 -> 367.52213 | ... AB17: =Info!AC69/Info!AC18 -> 390.3969
A18: Medelvärde stor-gbg | B18: =AVERAGE(B4:B17) -> 341.53616 | C18: =AVERAGE(C4:C17) -> 321.93282 | D18: =AVERAGE(D4:D17) -> 318.94384 | E18: =AVERAGE(E4:E17) -> 326.31828 | F18: =AVERAGE(F4:F17) -> 324.3657 | G18: =AVERAGE(G4:G17) -> 327.2666 | H18: =AVERAGE(H4:H17) -> 327.86026 | I18: =AVERAGE(I4:I17) -> 324.37738 | ... AB18: =AVERAGE(AB4:AB17) -> 370.94152
A44: Medical staff cost / listad pat | B44: 202312 | C44: 202401 | D44: 202402 | E44: 202403 | F44: 202404 | G44: 202405 | H44: 202406 | I44: 202407 | J44: 202408 | K44: 202409 | L44: 202410 | M44: 202411 | N44: 202412 | O44: 202501 | P44: 202502 | Q44: 202503 | R44: 202504 | S44: 202505 | T44: 202506 | U44: 202507 | V44: 202508 | W44: 202509 | X44: 202510 | Y44: 202511 | Z44: 202512 | AA44: 202601 | AB44: 202602
A45: Citysjukhuset Plus 7 vårdcentral | B45: =(Info!C73/Info!C5)*-1 -> 198.88857 | C45: =(Info!D73/Info!D5)*-1 -> 164.51235 | D45: =(Info!E73/Info!E5)*-1 -> 185.08675 | E45: =(Info!F73/Info!F5)*-1 -> 149.83031 | F45: =(Info!G73/Info!G5)*-1 -> 204.49428 | G45: =(Info!H73/Info!H5)*-1 -> 175.43274 | H45: =(Info!I73/Info!I5)*-1 -> 152.20292 | I45: =(Info!J73/Info!J5)*-1 -> 170.82705 | ... AB45: =(Info!AC73/Info!AC5)*-1 -> 168.16347
A46: Kvarterskliniken Avenyn | B46: =(Info!C74/(Info!C6+Info!C9))*-1 -> 25.872945 | C46: =(Info!D74/(Info!D6+Info!D9))*-1 -> 0 | D46: =(Info!E74/(Info!E6+Info!E9))*-1 -> 0 | E46: =(Info!F74/(Info!F6+Info!F9))*-1 -> 0 | F46: =(Info!G74/(Info!G6+Info!G9))*-1 -> 0 | G46: =(Info!H74/(Info!H6+Info!H9))*-1 -> 0 | H46: =(Info!I74/(Info!I6+Info!I9))*-1 -> 0 | I46: =(Info!J74/(Info!J6+Info!J9))*-1 -> 0 | ... AB46: =(Info!AC74/(Info!AC6+Info!AC9))*-1 -> 230.76487
A47: Kvarterskliniken Husaren | B47: =(Info!C75/Info!C7)*-1 -> 178.01336 | C47: =(Info!D75/Info!D7)*-1 -> 198.27027 | D47: =(Info!E75/Info!E7)*-1 -> 190.1834 | E47: =(Info!F75/Info!F7)*-1 -> 195.74027 | F47: =(Info!G75/Info!G7)*-1 -> 197.70308 | G47: =(Info!H75/Info!H7)*-1 -> 198.36331 | H47: =(Info!I75/Info!I7)*-1 -> 168.33444 | I47: =(Info!J75/Info!J7)*-1 -> 176.75207 | ... AB47: =(Info!AC75/Info!AC7)*-1 -> 211.71746
A48: Omtanken Vårdcentral Frölunda Torg | B48: =(Info!C78/Info!C10)*-1 -> 202.83393 | C48: =(Info!D78/Info!D10)*-1 -> 199.11435 | D48: =(Info!E78/Info!E10)*-1 -> 209.79349 | E48: =(Info!F78/Info!F10)*-1 -> 196.10781 | F48: =(Info!G78/Info!G10)*-1 -> 214.32028 | G48: =(Info!H78/Info!H10)*-1 -> 227.77411 | H48: =(Info!I78/Info!I10)*-1 -> 222.94397 | I48: =(Info!J78/Info!J10)*-1 -> 227.80988 | ... AB48: =(Info!AC78/Info!AC10)*-1 -> 178.49744
A49: Omtanken Vårdcentral Grimmered | B49: =(Info!C79/Info!C11)*-1 -> 219.33957 | C49: =(Info!D79/Info!D11)*-1 -> 223.93787 | D49: =(Info!E79/Info!E11)*-1 -> 211.79624 | E49: =(Info!F79/Info!F11)*-1 -> 209.56484 | F49: =(Info!G79/Info!G11)*-1 -> 211.40086 | G49: =(Info!H79/Info!H11)*-1 -> 220.80656 | H49: =(Info!I79/Info!I11)*-1 -> 224.19827 | I49: =(Info!J79/Info!J11)*-1 -> 222.07481 | ... AB49: =(Info!AC79/Info!AC11)*-1 -> 221.68963
A50: Omtanken Vårdcentral Kviberg | B50: =(Info!C80/Info!C12)*-1 -> 234.19259 | C50: =(Info!D80/Info!D12)*-1 -> 223.22505 | D50: =(Info!E80/Info!E12)*-1 -> 230.48424 | E50: =(Info!F80/Info!F12)*-1 -> 242.14456 | F50: =(Info!G80/Info!G12)*-1 -> 217.37107 | G50: =(Info!H80/Info!H12)*-1 -> 247.81376 | H50: =(Info!I80/Info!I12)*-1 -> 308.10089 | I50: =(Info!J80/Info!J12)*-1 -> 268.50405 | ... AB50: =(Info!AC80/Info!AC12)*-1 -> 196.70868
A51: Omtanken Vårdcentral Landala | B51: =(Info!C82/Info!C14)*-1 -> 153.28799 | C51: =(Info!D82/Info!D14)*-1 -> 182.50782 | D51: =(Info!E82/Info!E14)*-1 -> 179.11222 | E51: =(Info!F82/Info!F14)*-1 -> 158.06521 | F51: =(Info!G82/Info!G14)*-1 -> 176.30644 | G51: =(Info!H82/Info!H14)*-1 -> 170.9406 | H51: =(Info!I82/Info!I14)*-1 -> 179.08144 | I51: =(Info!J82/Info!J14)*-1 -> 187.61981 | ... AB51: =(Info!AC82/Info!AC14)*-1 -> 185.94324
A52: Omtanken Vårdcentral Majorna | B52: =(Info!C83/Info!C15)*-1 -> 204.51814 | C52: =(Info!D83/Info!D15)*-1 -> 192.34068 | D52: =(Info!E83/Info!E15)*-1 -> 194.39511 | E52: =(Info!F83/Info!F15)*-1 -> 201.10259 | F52: =(Info!G83/Info!G15)*-1 -> 211.43134 | G52: =(Info!H83/Info!H15)*-1 -> 212.50231 | H52: =(Info!I83/Info!I15)*-1 -> 221.61164 | I52: =(Info!J83/Info!J15)*-1 -> 224.18839 | ... AB52: =(Info!AC83/Info!AC15)*-1 -> 223.71532
A53: Omtanken Vårdcentral Olskroken | B53: =(Info!C84/Info!C16)*-1 -> 232.93369 | C53: =(Info!D84/Info!D16)*-1 -> 221.38846 | D53: =(Info!E84/Info!E16)*-1 -> 190.00352 | E53: =(Info!F84/Info!F16)*-1 -> 230.89222 | F53: =(Info!G84/Info!G16)*-1 -> 214.58531 | G53: =(Info!H84/Info!H16)*-1 -> 189.76903 | H53: =(Info!I84/Info!I16)*-1 -> 219.45404 | I53: =(Info!J84/Info!J16)*-1 -> 227.75588 | ... AB53: =(Info!AC84/Info!AC16)*-1 -> 255.84995
A54: Omtanken Vårdcentral Pedagogen Park | B54: =(Info!C85/Info!C17)*-1 -> 168.80747 | C54: =(Info!D85/Info!D17)*-1 -> 150.47725 | D54: =(Info!E85/Info!E17)*-1 -> 177.96928 | E54: =(Info!F85/Info!F17)*-1 -> 145.66894 | F54: =(Info!G85/Info!G17)*-1 -> 156.19765 | G54: =(Info!H85/Info!H17)*-1 -> 213.76344 | H54: =(Info!I85/Info!I17)*-1 -> 187.7943 | I54: =(Info!J85/Info!J17)*-1 -> 222.684 | ... AB54: =(Info!AC85/Info!AC17)*-1 -> 210.65872
A55: Omtanken Vårdcentral Åby | B55: =(Info!C86+Info!C81)/(Info!C18+Info!C13)*-1 -> 193.6015 | C55: =(Info!D86+Info!D81)/(Info!D18+Info!D13)*-1 -> 217.88419 | D55: =(Info!E86+Info!E81)/(Info!E18+Info!E13)*-1 -> 209.3769 | E55: =(Info!F86+Info!F81)/(Info!F18+Info!F13)*-1 -> 204.79344 | F55: =(Info!G86+Info!G81)/(Info!G18+Info!G13)*-1 -> 222.8619 | G55: =(Info!H86+Info!H81)/(Info!H18+Info!H13)*-1 -> 218.24179 | H55: =(Info!I86+Info!I81)/(Info!I18+Info!I13)*-1 -> 222.84596 | I55: =(Info!J86+Info!J81)/(Info!J18+Info!J13)*-1 -> 214.53855 | ... AB55: =(Info!AC86+Info!AC81)/(Info!AC18+Info!AC13)*-1 -> 208.16547
A56: Medelvärde Stor-GBG | B56: =AVERAGE(B45:B55) -> 182.93543 | C56: =AVERAGE(C45:C55) -> 179.42348 | D56: =AVERAGE(D45:D55) -> 179.83647 | E56: =AVERAGE(E45:E55) -> 175.81002 | F56: =AVERAGE(F45:F55) -> 184.24293 | G56: =AVERAGE(G45:G55) -> 188.67342 | H56: =AVERAGE(H45:H55) -> 191.50617 | I56: =AVERAGE(I45:I55) -> 194.79586 | ... AB56: =AVERAGE(AB45:AB55) -> 208.35221
A57: Kvarterskliniken Karlastaden | B57: =(Info!C76/Info!C8)*-1 -> #DIV/0! | C57: =(Info!D76/Info!D8)*-1 -> #DIV/0! | D57: =(Info!E76/Info!E8)*-1 -> #DIV/0! | E57: =(Info!F76/Info!F8)*-1 -> #DIV/0! | F57: =(Info!G76/Info!G8)*-1 -> #DIV/0! | G57: =(Info!H76/Info!H8)*-1 -> #DIV/0! | H57: =(Info!I76/Info!I8)*-1 -> #DIV/0! | I57: =(Info!J76/Info!J8)*-1 -> #DIV/0! | ... AB57: =(Info!AC76/Info!AC8)*-1 -> 394.6891
A82: Other direct costs / listad pat | B82: 202312 | C82: 202401 | D82: 202402 | E82: 202403 | F82: 202404 | G82: 202405 | H82: 202406 | I82: 202407 | J82: 202408 | K82: 202409 | L82: 202410 | M82: 202411 | N82: 202412 | O82: 202501 | P82: 202502 | Q82: 202503 | R82: 202504 | S82: 202505 | T82: 202506 | U82: 202507 | V82: 202508 | W82: 202509 | X82: 202510 | Y82: 202511 | Z82: 202512 | AA82: 202601 | AB82: 202602
A83: Citysjukhuset Plus 7 vårdcentral | B83: =(Info!C90/Info!C5)*-1 -> 114.12647 | C83: =(Info!D90/Info!D5)*-1 -> 116.50834 | D83: =(Info!E90/Info!E5)*-1 -> 95.456289 | E83: =(Info!F90/Info!F5)*-1 -> 86.077458 | F83: =(Info!G90/Info!G5)*-1 -> 114.39613 | G83: =(Info!H90/Info!H5)*-1 -> 106.80336 | H83: =(Info!I90/Info!I5)*-1 -> 114.11768 | I83: =(Info!J90/Info!J5)*-1 -> 91.83958 | ... AB83: =(Info!AC90/Info!AC5)*-1 -> 84.614573
A84: Kvarterskliniken Avenyn | B84: =(Info!C91/Info!C6)*-1 -> -13.098075 | C84: =(Info!D91/Info!D6)*-1 -> 30.098439 | D84: =(Info!E91/Info!E6)*-1 -> 36.961386 | E84: =(Info!F91/Info!F6)*-1 -> 44.371812 | F84: =(Info!G91/Info!G6)*-1 -> 27.57942 | G84: =(Info!H91/Info!H6)*-1 -> 21.11035 | H84: =(Info!I91/Info!I6)*-1 -> 49.272724 | I84: =(Info!J91/Info!J6)*-1 -> 36.625499 | ... AB84: =(Info!AC91/Info!AC6)*-1 -> 92.743921
A85: Kvarterskliniken Husaren | B85: =(Info!C92/Info!C7)*-1 -> 125.66684 | C85: =(Info!D92/Info!D7)*-1 -> 92.390068 | D85: =(Info!E92/Info!E7)*-1 -> 95.704596 | E85: =(Info!F92/Info!F7)*-1 -> 108.85326 | F85: =(Info!G92/Info!G7)*-1 -> 107.72025 | G85: =(Info!H92/Info!H7)*-1 -> 111.46829 | H85: =(Info!I92/Info!I7)*-1 -> 99.482768 | I85: =(Info!J92/Info!J7)*-1 -> 90.305986 | ... AB85: =(Info!AC92/Info!AC7)*-1 -> 77.020114
A86: Kvarterskliniken Lorensberg | B86: =(Info!C94/Info!C9)*-1 -> 64.264837 | C86: =(Info!D94/Info!D9)*-1 -> 49.911635 | D86: =(Info!E94/Info!E9)*-1 -> 41.398943 | E86: =(Info!F94/Info!F9)*-1 -> 50.042363 | F86: =(Info!G94/Info!G9)*-1 -> 45.404659 | G86: =(Info!H94/Info!H9)*-1 -> 52.598014 | H86: =(Info!I94/Info!I9)*-1 -> 59.948675 | I86: =(Info!J94/Info!J9)*-1 -> 46.380497 | ... AB86: =(Info!AC94/Info!AC9)*-1 -> 52.306462
A87: Omtanken Vårdcentral Frölunda Torg | B87: =(Info!C95/Info!C10)*-1 -> 122.22483 | C87: =(Info!D95/Info!D10)*-1 -> 110.27459 | D87: =(Info!E95/Info!E10)*-1 -> 112.3285 | E87: =(Info!F95/Info!F10)*-1 -> 124.55472 | F87: =(Info!G95/Info!G10)*-1 -> 127.8701 | G87: =(Info!H95/Info!H10)*-1 -> 123.23751 | H87: =(Info!I95/Info!I10)*-1 -> 115.33472 | I87: =(Info!J95/Info!J10)*-1 -> 106.97406 | ... AB87: =(Info!AC95/Info!AC10)*-1 -> 114.18829
A88: Omtanken Vårdcentral Grimmered | B88: =(Info!C96/Info!C11)*-1 -> 117.11713 | C88: =(Info!D96/Info!D11)*-1 -> 116.7288 | D88: =(Info!E96/Info!E11)*-1 -> 129.78193 | E88: =(Info!F96/Info!F11)*-1 -> 109.68476 | F88: =(Info!G96/Info!G11)*-1 -> 127.55216 | G88: =(Info!H96/Info!H11)*-1 -> 127.64479 | H88: =(Info!I96/Info!I11)*-1 -> 109.84076 | I88: =(Info!J96/Info!J11)*-1 -> 107.33647 | ... AB88: =(Info!AC96/Info!AC11)*-1 -> 87.07476
A89: Omtanken Vårdcentral Kviberg | B89: =(Info!C97/Info!C12)*-1 -> 81.109864 | C89: =(Info!D97/Info!D12)*-1 -> 77.988257 | D89: =(Info!E97/Info!E12)*-1 -> 85.665954 | E89: =(Info!F97/Info!F12)*-1 -> 75.022384 | F89: =(Info!G97/Info!G12)*-1 -> 88.795241 | G89: =(Info!H97/Info!H12)*-1 -> 89.439465 | H89: =(Info!I97/Info!I12)*-1 -> 74.415284 | I89: =(Info!J97/Info!J12)*-1 -> 90.509178 | ... AB89: =(Info!AC97/Info!AC12)*-1 -> 82.991921
A90: Omtanken Vårdcentral Kållered | B90: =(Info!C98/Info!C13)*-1 -> 80.721575 | C90: =(Info!D98/Info!D13)*-1 -> 83.497137 | D90: =(Info!E98/Info!E13)*-1 -> 79.389045 | E90: =(Info!F98/Info!F13)*-1 -> 78.760616 | F90: =(Info!G98/Info!G13)*-1 -> 82.651843 | G90: =(Info!H98/Info!H13)*-1 -> 72.638022 | H90: =(Info!I98/Info!I13)*-1 -> 68.537991 | I90: =(Info!J98/Info!J13)*-1 -> 75.549242 | ... AB90: =(Info!AC98/Info!AC13)*-1 -> 56.282736
A91: Omtanken Vårdcentral Landala | B91: =(Info!C99/Info!C14)*-1 -> 64.330278 | C91: =(Info!D99/Info!D14)*-1 -> 65.927395 | D91: =(Info!E99/Info!E14)*-1 -> 61.344511 | E91: =(Info!F99/Info!F14)*-1 -> 67.295456 | F91: =(Info!G99/Info!G14)*-1 -> 66.636296 | G91: =(Info!H99/Info!H14)*-1 -> 71.131217 | H91: =(Info!I99/Info!I14)*-1 -> 70.77794 | I91: =(Info!J99/Info!J14)*-1 -> 51.897017 | ... AB91: =(Info!AC99/Info!AC14)*-1 -> 71.882133
...
