Workbook

Sheet Enheterna AO Stor-GBG
A1: Uttag poäng datum; | B1: 46063 | C1: 46086 | D1: 46106
A2: Skillnad poäng (ACT) och poäng (Budget) | B2: Jan | C2: Feb | D2: Mar | E2: Apr | F2: Maj | G2: Jun | H2: Jul | I2: Aug | J2: Sep | K2: Okt | L2: Nov | M2: Dec
A3: Poäng ACTUAL | B3: =SUM('Pedagogen Park:Olskroken'!B18) -> 1958 | C3: =SUM('Pedagogen Park:Olskroken'!C18) -> 2074 | D3: =SUM('Pedagogen Park:Olskroken'!D18) -> 2516 | E3: =SUM('Pedagogen Park:Olskroken'!E18) -> 0 | F3: =SUM('Pedagogen Park:Olskroken'!F18) -> 0 | G3: =SUM('Pedagogen Park:Olskroken'!G18) -> 0 | H3: =SUM('Pedagogen Park:Olskroken'!H18) -> 0 | I3: =SUM('Pedagogen Park:Olskroken'!I18) -> 0 | ... M3: =SUM('Pedagogen Park:Olskroken'!M18) -> 0
A4: Poäng Budget | B4: =SUM('Pedagogen Park:Olskroken'!B39) -> 2115 | C4: =SUM('Pedagogen Park:Olskroken'!C39) -> 2475 | D4: =SUM('Pedagogen Park:Olskroken'!D39) -> 2820 | E4: =SUM('Pedagogen Park:Olskroken'!E39) -> 2590 | F4: =SUM('Pedagogen Park:Olskroken'!F39) -> 2815 | G4: =SUM('Pedagogen Park:Olskroken'!G39) -> 2535 | H4: =SUM('Pedagogen Park:Olskroken'!H39) -> 1220 | I4: =SUM('Pedagogen Park:Olskroken'!I39) -> 2245 | ... M4: =SUM('Pedagogen Park:Olskroken'!M39) -> 2375
A5: Skillnad | B5: =B3-B4 -> -157 | C5: =C3-C4 -> -401 | D5: =D3-D4 -> -304 | E5: =E3-E4 -> -2590 | F5: =F3-F4 -> -2815 | G5: =G3-G4 -> -2535 | H5: =H3-H4 -> -1220 | I5: =I3-I4 -> -2245 | ... M5: =M3-M4 -> -2375
A6: % avvik mot Budget | B6: =SUM(B5/B4) -> -0.074231678 | C6: =SUM(C5/C4) -> -0.1620202 | D6: =SUM(D5/D4) -> -0.10780142 | E6: =SUM(E5/E4) -> -1 | F6: =SUM(F5/F4) -> -1 | G6: =SUM(G5/G4) -> -1 | H6: =SUM(H5/H4) -> -1 | I6: =SUM(I5/I4) -> -1 | ... M6: =SUM(M5/M4) -> -1
A8: Enheterna;
A9: Frölunda Torget | B9: Jan | C9: Feb | D9: Mar | E9: Apr | F9: Maj | G9: Jun | H9: Jul | I9: Aug | J9: Sep | K9: Okt | L9: Nov | M9: Dec
A10: Poäng ACTUAL | B10: ='Frölunda Torg'!B18 -> 783 | C10: ='Frölunda Torg'!C18 -> 900 | D10: ='Frölunda Torg'!D18 -> 875 | E10: ='Frölunda Torg'!E18 -> 0 | F10: ='Frölunda Torg'!F18 -> 0 | G10: ='Frölunda Torg'!G18 -> 0 | H10: ='Frölunda Torg'!H18 -> 0 | I10: ='Frölunda Torg'!I18 -> 0 | ... M10: ='Frölunda Torg'!M18 -> 0
A11: Poäng Budget | B11: ='Frölunda Torg'!B39 -> 1120 | C11: ='Frölunda Torg'!C39 -> 1076 | D11: ='Frölunda Torg'!D39 -> 1106 | E11: ='Frölunda Torg'!E39 -> 1066 | F11: ='Frölunda Torg'!F39 -> 1076 | G11: ='Frölunda Torg'!G39 -> 1010 | H11: ='Frölunda Torg'!H39 -> 456 | I11: ='Frölunda Torg'!I39 -> 720 | ... M11: ='Frölunda Torg'!M39 -> 1040
A12: Skillnad | B12: =B10-B11 -> -337 | C12: =C10-C11 -> -176 | D12: =D10-D11 -> -231 | E12: =E10-E11 -> -1066 | F12: =F10-F11 -> -1076 | G12: =G10-G11 -> -1010 | H12: =H10-H11 -> -456 | I12: =I10-I11 -> -720 | ... M12: =M10-M11 -> -1040
A13: % avvik mot Budget | B13: =SUM(B12/B11) -> -0.30089286 | C13: =SUM(C12/C11) -> -0.16356877 | D13: =SUM(D12/D11) -> -0.20886076 | E13: =SUM(E12/E11) -> -1 | F13: =SUM(F12/F11) -> -1 | G13: =SUM(G12/G11) -> -1 | H13: =SUM(H12/H11) -> -1 | I13: =SUM(I12/I11) -> -1 | ... M13: =SUM(M12/M11) -> -1
A15: Grimmered | B15: Jan | C15: Feb | D15: Mar | E15: Apr | F15: Maj | G15: Jun | H15: Jul | I15: Aug | J15: Sep | K15: Okt | L15: Nov | M15: Dec
A16: Poäng ACTUAL | B16: =SUM(Grimmered!B18) -> 754 | C16: =SUM(Grimmered!C18) -> 884 | D16: =SUM(Grimmered!D18) -> 1064 | E16: =SUM(Grimmered!E18) -> 0 | F16: =SUM(Grimmered!F18) -> 0 | G16: =SUM(Grimmered!G18) -> 0 | H16: =SUM(Grimmered!H18) -> 0 | I16: =SUM(Grimmered!I18) -> 0 | ... M16: =SUM(Grimmered!M18) -> 0
A17: Poäng Budget | B17: =SUM(Grimmered!B39) -> 1005 | C17: =SUM(Grimmered!C39) -> 1045 | D17: =SUM(Grimmered!D39) -> 1045 | E17: =SUM(Grimmered!E39) -> 1020 | F17: =SUM(Grimmered!F39) -> 1025 | G17: =SUM(Grimmered!G39) -> 1045 | H17: =SUM(Grimmered!H39) -> 500 | I17: =SUM(Grimmered!I39) -> 530 | ... M17: =SUM(Grimmered!M39) -> 960
A18: Skillnad | B18: =B16-B17 -> -251 | C18: =C16-C17 -> -161 | D18: =D16-D17 -> 19 | E18: =E16-E17 -> -1020 | F18: =F16-F17 -> -1025 | G18: =G16-G17 -> -1045 | H18: =H16-H17 -> -500 | I18: =I16-I17 -> -530 | ... M18: =M16-M17 -> -960
A19: % avvik mot Budget | B19: =SUM(B18/B17) -> -0.24975124 | C19: =SUM(C18/C17) -> -0.15406699 | D19: =SUM(D18/D17) -> 0.018181818 | E19: =SUM(E18/E17) -> -1 | F19: =SUM(F18/F17) -> -1 | G19: =SUM(G18/G17) -> -1 | H19: =SUM(H18/H17) -> -1 | I19: =SUM(I18/I17) -> -1 | ... M19: =SUM(M18/M17) -> -1
A21: Majorna | B21: Jan | C21: Feb | D21: Mar | E21: Apr | F21: Maj | G21: Jun | H21: Jul | I21: Aug | J21: Sep | K21: Okt | L21: Nov | M21: Dec
A22: Poäng ACTUAL | B22: =SUM(Majorna!B18) -> 894 | C22: =SUM(Majorna!C18) -> 962 | D22: =SUM(Majorna!D18) -> 1003 | E22: =SUM(Majorna!E18) -> 0 | F22: =SUM(Majorna!F18) -> 0 | G22: =SUM(Majorna!G18) -> 0 | H22: =SUM(Majorna!H18) -> 0 | I22: =SUM(Majorna!I18) -> 0 | ... M22: =SUM(Majorna!M18) -> 0
A23: Poäng Budget | B23: =SUM(Majorna!B39) -> 987 | C23: =SUM(Majorna!C39) -> 1132 | D23: =SUM(Majorna!D39) -> 1197 | E23: =SUM(Majorna!E39) -> 1232 | F23: =SUM(Majorna!F39) -> 1242 | G23: =SUM(Majorna!G39) -> 1020 | H23: =SUM(Majorna!H39) -> 560 | I23: =SUM(Majorna!I39) -> 660 | ... M23: =SUM(Majorna!M39) -> 1050
A24: Skillnad | B24: =B22-B23 -> -93 | C24: =C22-C23 -> -170 | D24: =D22-D23 -> -194 | E24: =E22-E23 -> -1232 | F24: =F22-F23 -> -1242 | G24: =G22-G23 -> -1020 | H24: =H22-H23 -> -560 | I24: =I22-I23 -> -660 | ... M24: =M22-M23 -> -1050
A25: % avvik mot Budget | B25: =SUM(B24/B23) -> -0.094224924 | C25: =SUM(C24/C23) -> -0.15017668 | D25: =SUM(D24/D23) -> -0.16207185 | E25: =SUM(E24/E23) -> -1 | F25: =SUM(F24/F23) -> -1 | G25: =SUM(G24/G23) -> -1 | H25: =SUM(H24/H23) -> -1 | I25: =SUM(I24/I23) -> -1 | ... M25: =SUM(M24/M23) -> -1
A27: Pedagogen Park | B27: Jan | C27: Feb | D27: Mar | E27: Apr | F27: Maj | G27: Jun | H27: Jul | I27: Aug | J27: Sep | K27: Okt | L27: Nov | M27: Dec
A28: Poäng ACTUAL | B28: ='Pedagogen Park'!B18 -> 478 | C28: ='Pedagogen Park'!C18 -> 532 | D28: ='Pedagogen Park'!D18 -> 785 | E28: ='Pedagogen Park'!E18 -> 0 | F28: ='Pedagogen Park'!F18 -> 0 | G28: ='Pedagogen Park'!G18 -> 0 | H28: ='Pedagogen Park'!H18 -> 0 | I28: ='Pedagogen Park'!I18 -> 0 | ... M28: ='Pedagogen Park'!M18 -> 0
A29: Poäng Budget | B29: ='Pedagogen Park'!B39 -> 600 | C29: ='Pedagogen Park'!C39 -> 660 | D29: ='Pedagogen Park'!D39 -> 730 | E29: ='Pedagogen Park'!E39 -> 735 | F29: ='Pedagogen Park'!F39 -> 760 | G29: ='Pedagogen Park'!G39 -> 800 | H29: ='Pedagogen Park'!H39 -> 600 | I29: ='Pedagogen Park'!I39 -> 660 | ... M29: ='Pedagogen Park'!M39 -> 675
A30: Skillnad | B30: =B28-B29 -> -122 | C30: =C28-C29 -> -128 | D30: =D28-D29 -> 55 | E30: =E28-E29 -> -735 | F30: =F28-F29 -> -760 | G30: =G28-G29 -> -800 | H30: =H28-H29 -> -600 | I30: =I28-I29 -> -660 | ... M30: =M28-M29 -> -675
A31: % avvik mot Budget | B31: =SUM(B30/B29) -> -0.20333333 | C31: =SUM(C30/C29) -> -0.19393939 | D31: =SUM(D30/D29) -> 0.075342466 | E31: =SUM(E30/E29) -> -1 | F31: =SUM(F30/F29) -> -1 | G31: =SUM(G30/G29) -> -1 | H31: =SUM(H30/H29) -> -1 | I31: =SUM(I30/I29) -> -1 | ... M31: =SUM(M30/M29) -> -1
A33: Åby | B33: Jan | C33: Feb | D33: Mar | E33: Apr | F33: Maj | G33: Jun | H33: Jul | I33: Aug | J33: Sep | K33: Okt | L33: Nov | M33: Dec
A34: Poäng ACTUAL | B34: =SUM(Åby!B18) -> 926 | C34: =SUM(Åby!C18) -> 1054 | D34: =SUM(Åby!D18) -> 1103 | E34: =SUM(Åby!E18) -> 0 | F34: =SUM(Åby!F18) -> 0 | G34: =SUM(Åby!G18) -> 0 | H34: =SUM(Åby!H18) -> 0 | I34: =SUM(Åby!I18) -> 0 | ... M34: =SUM(Åby!M18) -> 0
A35: Poäng Budget | B35: =SUM(Åby!B39) -> 890 | C35: =SUM(Åby!C39) -> 1105 | D35: =SUM(Åby!D39) -> 1295 | E35: =SUM(Åby!E39) -> 1050 | F35: =SUM(Åby!F39) -> 1180 | G35: =SUM(Åby!G39) -> 890 | H35: =SUM(Åby!H39) -> 240 | I35: =SUM(Åby!I39) -> 1040 | ... M35: =SUM(Åby!M39) -> 1040
A36: Skillnad | B36: =B34-B35 -> 36 | C36: =C34-C35 -> -51 | D36: =D34-D35 -> -192 | E36: =E34-E35 -> -1050 | F36: =F34-F35 -> -1180 | G36: =G34-G35 -> -890 | H36: =H34-H35 -> -240 | I36: =I34-I35 -> -1040 | ... M36: =M34-M35 -> -1040
A37: % avvik mot Budget | B37: =SUM(B36/B35) -> 0.040449438 | C37: =SUM(C36/C35) -> -0.046153846 | D37: =SUM(D36/D35) -> -0.14826255 | E37: =SUM(E36/E35) -> -1 | F37: =SUM(F36/F35) -> -1 | G37: =SUM(G36/G35) -> -1 | H37: =SUM(H36/H35) -> -1 | I37: =SUM(I36/I35) -> -1 | ... M37: =SUM(M36/M35) -> -1
A39: Olskroken | B39: Jan | C39: Feb | D39: Mar | E39: Apr | F39: Maj | G39: Jun | H39: Jul | I39: Aug | J39: Sep | K39: Okt | L39: Nov | M39: Dec
A40: Poäng ACTUAL | B40: =SUM(Olskroken!B18) -> 554 | C40: =SUM(Olskroken!C18) -> 488 | D40: =SUM(Olskroken!D18) -> 628 | E40: =SUM(Olskroken!E18) -> 0 | F40: =SUM(Olskroken!F18) -> 0 | G40: =SUM(Olskroken!G18) -> 0 | H40: =SUM(Olskroken!H18) -> 0 | I40: =SUM(Olskroken!I18) -> 0 | ... M40: =SUM(Olskroken!M18) -> 0
A41: Poäng Budget | B41: =SUM(Olskroken!B39) -> 625 | C41: =SUM(Olskroken!C39) -> 710 | D41: =SUM(Olskroken!D39) -> 795 | E41: =SUM(Olskroken!E39) -> 805 | F41: =SUM(Olskroken!F39) -> 875 | G41: =SUM(Olskroken!G39) -> 845 | H41: =SUM(Olskroken!H39) -> 380 | I41: =SUM(Olskroken!I39) -> 545 | ... M41: =SUM(Olskroken!M39) -> 660
A42: Skillnad | B42: =B40-B41 -> -71 | C42: =C40-C41 -> -222 | D42: =D40-D41 -> -167 | E42: =E40-E41 -> -805 | F42: =F40-F41 -> -875 | G42: =G40-G41 -> -845 | H42: =H40-H41 -> -380 | I42: =I40-I41 -> -545 | ... M42: =M40-M41 -> -660
A43: % avvik mot Budget | B43: =SUM(B42/B41) -> -0.1136 | C43: =SUM(C42/C41) -> -0.31267606 | D43: =SUM(D42/D41) -> -0.21006289 | E43: =SUM(E42/E41) -> -1 | F43: =SUM(F42/F41) -> -1 | G43: =SUM(G42/G41) -> -1 | H43: =SUM(H42/H41) -> -1 | I43: =SUM(I42/I41) -> -1 | ... M43: =SUM(M42/M41) -> -1
A45: Avenyn | B45: Jan | C45: Feb | D45: Mar | E45: Apr | F45: Maj | G45: Jun | H45: Jul | I45: Aug | J45: Sep | K45: Okt | L45: Nov | M45: Dec
A46: Poäng ACTUAL | B46: =Avenyn!B18 -> 886 | C46: =Avenyn!C18 -> 910 | D46: =Avenyn!D18 -> 1253 | E46: =Avenyn!E18 -> 0 | F46: =Avenyn!F18 -> 0 | G46: =Avenyn!G18 -> 0 | H46: =Avenyn!H18 -> 0 | I46: =Avenyn!I18 -> 0 | ... M46: =Avenyn!M18 -> 0
A47: Poäng Budget | B47: =Avenyn!B39 -> 1170 | C47: =Avenyn!C39 -> 1175 | D47: =Avenyn!D39 -> 1280 | E47: =Avenyn!E39 -> 1180 | F47: =Avenyn!F39 -> 1290 | G47: =Avenyn!G39 -> 1300 | H47: =Avenyn!H39 -> 660 | I47: =Avenyn!I39 -> 860 | ... M47: =Avenyn!M39 -> 1140
...

Sheet Frölunda Torg
A1: Uttag poäng datum; | B1: 46063 | C1: 46086
B2: Jan | C2: Feb | D2: Mar | E2: Apr | F2: Maj | G2: Jun | H2: Jul | I2: Aug | J2: Sep | K2: Okt | L2: Nov | M2: Dec
B3: Actual | C3: Actual | D3: Actual | E3: Actual | F3: Actual | G3: Actual | H3: Actual | I3: Actual | J3: Actual | K3: Actual | L3: Actual | M3: Actual
A4: Pontus Berglund | B4: 138 | C4: 82
A5: Anders Esko | B5: 178 | C5: 156 | D5: 188
A6: Albert Lindström | B6: 112 | C6: 179 | D6: 181
A7: Rana Baratifar | B7: 91 | C7: 164 | D7: 141
A8: Annelie Corell | B8: 139 | C8: 190 | D8: 194
A9: Louise From | B9: 125 | C9: 52
A10: Simon Lageson | C10: 77 | D10: 171
B18: =SUM(B4:B17) -> 783 | C18: =SUM(C4:C17) -> 900 | D18: =SUM(D4:D17) -> 875 | E18: =SUM(E4:E17) -> 0 | F18: =SUM(F4:F17) -> 0 | G18: =SUM(G4:G17) -> 0 | H18: =SUM(H4:H17) -> 0 | I18: =SUM(I4:I17) -> 0 | ... M18: =SUM(M4:M17) -> 0
B20: Jan | C20: Feb | D20: Mar | E20: Apr | F20: Maj | G20: Jun | H20: Jul | I20: Aug | J20: Sep | K20: Okt | L20: Nov | M20: Dec
B21: Diff | C21: Diff | D21: Diff | E21: Diff | F21: Diff | G21: Diff | H21: Diff | I21: Diff | J21: Diff | K21: Diff | L21: Diff | M21: Diff
A22: Pontus Berglund | B22: =SUM(B4-B40) -> -82 | C22: =SUM(C4-C40) -> -48 | D22: =SUM(D4-D40) -> -140 | E22: =SUM(E4-E40) -> -130 | F22: =SUM(F4-F40) -> 0 | G22: =SUM(G4-G40) -> 0 | H22: =SUM(H4-H40) -> 0 | I22: =SUM(I4-I40) -> 0 | ... M22: =SUM(M4-M40) -> 0
A23: Anders Esko | B23: =SUM(B5-B41) -> -42 | C23: =SUM(C5-C41) -> -74 | D23: =SUM(D5-D41) -> -42 | E23: =SUM(E5-E41) -> -230 | F23: =SUM(F5-F41) -> -230 | G23: =SUM(G5-G41) -> -120 | H23: =SUM(H5-H41) -> -180 | I23: =SUM(I5-I41) -> -120 | ... M23: =SUM(M5-M41) -> -200
A24: Albert Lindström | B24: =SUM(B6-B42) -> -98 | C24: =SUM(C6-C42) -> -51 | D24: =SUM(D6-D42) -> -49 | E24: =SUM(E6-E42) -> -220 | F24: =SUM(F6-F42) -> -220 | G24: =SUM(G6-G42) -> -220 | H24: =SUM(H6-H42) -> 0 | I24: =SUM(I6-I42) -> -220 | ... M24: =SUM(M6-M42) -> -190
A25: Rana Baratifar | B25: =SUM(B7-B43) -> -99 | C25: =SUM(C7-C43) -> -26 | D25: =SUM(D7-D43) -> -69 | E25: =SUM(E7-E43) -> -200 | F25: =SUM(F7-F43) -> -210 | G25: =SUM(G7-G43) -> -210 | H25: =SUM(H7-H43) -> -180 | I25: =SUM(I7-I43) -> 0 | ... M25: =SUM(M7-M43) -> -200
A26: Annelie Corell | B26: =SUM(B8-B44) -> -51 | C26: =SUM(C8-C44) -> -10 | D26: =SUM(D8-D44) -> -6 | E26: =SUM(E8-E44) -> -190 | F26: =SUM(F8-F44) -> -200 | G26: =SUM(G8-G44) -> -200 | H26: =SUM(H8-H44) -> 0 | I26: =SUM(I8-I44) -> -200 | ... M26: =SUM(M8-M44) -> -190
A27: Louise From | B27: =SUM(B9-B45) -> 35 | C27: =SUM(C9-C45) -> -44 | D27: =SUM(D9-D45) -> -96 | E27: =SUM(E9-E45) -> -96 | F27: =SUM(F9-F45) -> -96 | G27: =SUM(G9-G45) -> -80 | H27: =SUM(H9-H45) -> -96 | I27: =SUM(I9-I45) -> 0 | ... M27: =SUM(M9-M45) -> -80
A28: Simon Lageson | B28: =SUM(B10-B46) -> 0 | C28: =SUM(C10-C46) -> 77 | D28: =SUM(D10-D46) -> 171 | E28: =SUM(E10-E46) -> 0 | F28: =SUM(F10-F46) -> -120 | G28: =SUM(G10-G46) -> -180 | H28: =SUM(H10-H46) -> 0 | I28: =SUM(I10-I46) -> -180 | ... M28: =SUM(M10-M46) -> -180
B29: =SUM(B11-B47) -> 0 | C29: =SUM(C11-C47) -> 0 | D29: =SUM(D11-D47) -> 0 | E29: =SUM(E11-E47) -> 0 | F29: =SUM(F11-F47) -> 0 | G29: =SUM(G11-G47) -> 0 | H29: =SUM(H11-H47) -> 0 | I29: =SUM(I11-I47) -> 0 | ... M29: =SUM(M11-M47) -> 0
B30: =SUM(B12-B48) -> 0 | C30: =SUM(C12-C48) -> 0 | D30: =SUM(D12-D48) -> 0 | E30: =SUM(E12-E48) -> 0 | F30: =SUM(F12-F48) -> 0 | G30: =SUM(G12-G48) -> 0 | H30: =SUM(H12-H48) -> 0 | I30: =SUM(I12-I48) -> 0 | ... M30: =SUM(M12-M48) -> 0
B31: =SUM(B13-B49) -> 0 | C31: =SUM(C13-C49) -> 0 | D31: =SUM(D13-D49) -> 0 | E31: =SUM(E13-E49) -> 0 | F31: =SUM(F13-F49) -> 0 | G31: =SUM(G13-G49) -> 0 | H31: =SUM(H13-H49) -> 0 | I31: =SUM(I13-I49) -> 0 | ... M31: =SUM(M13-M49) -> 0
B32: =SUM(B14-B50) -> 0 | C32: =SUM(C14-C50) -> 0 | D32: =SUM(D14-D50) -> 0 | E32: =SUM(E14-E50) -> 0 | F32: =SUM(F14-F50) -> 0 | G32: =SUM(G14-G50) -> 0 | H32: =SUM(H14-H50) -> 0 | I32: =SUM(I14-I50) -> 0 | ... M32: =SUM(M14-M50) -> 0
B33: =SUM(B15-B51) -> 0 | C33: =SUM(C15-C51) -> 0 | D33: =SUM(D15-D51) -> 0 | E33: =SUM(E15-E51) -> 0 | F33: =SUM(F15-F51) -> 0 | G33: =SUM(G15-G51) -> 0 | H33: =SUM(H15-H51) -> 0 | I33: =SUM(I15-I51) -> 0 | ... M33: =SUM(M15-M51) -> 0
B34: =SUM(B16-B52) -> 0 | C34: =SUM(C16-C52) -> 0 | D34: =SUM(D16-D52) -> 0 | E34: =SUM(E16-E52) -> 0 | F34: =SUM(F16-F52) -> 0 | G34: =SUM(G16-G52) -> 0 | H34: =SUM(H16-H52) -> 0 | I34: =SUM(I16-I52) -> 0 | ... M34: =SUM(M16-M52) -> 0
B35: =SUM(B17-B53) -> 0 | C35: =SUM(C17-C53) -> 0 | D35: =SUM(D17-D53) -> 0 | E35: =SUM(E17-E53) -> 0 | F35: =SUM(F17-F53) -> 0 | G35: =SUM(G17-G53) -> 0 | H35: =SUM(H17-H53) -> 0 | I35: =SUM(I17-I53) -> 0 | ... M35: =SUM(M17-M53) -> 0
B36: =SUM(B22:B35) -> -337 | C36: =SUM(C22:C35) -> -176 | D36: =SUM(D22:D35) -> -231 | E36: =SUM(E22:E35) -> -1066 | F36: =SUM(F22:F35) -> -1076 | G36: =SUM(G22:G35) -> -1010 | H36: =SUM(H22:H35) -> -456 | I36: =SUM(I22:I35) -> -720 | ... M36: =SUM(M22:M35) -> -1040
B38: Budget | C38: Budget | D38: Budget | E38: Budget | F38: Budget | G38: Budget | H38: Budget | I38: Budget | J38: Budget | K38: Budget | L38: Budget | M38: Budget
A39: ÅRSBUDGET POÄNG 2026 = | B39: =SUM(B40:B46) -> 1120 | C39: =SUM(C40:C46) -> 1076 | D39: =SUM(D40:D46) -> 1106 | E39: =SUM(E40:E46) -> 1066 | F39: =SUM(F40:F46) -> 1076 | G39: =SUM(G40:G46) -> 1010 | H39: =SUM(H40:H46) -> 456 | I39: =SUM(I40:I46) -> 720 | ... M39: =SUM(M40:M46) -> 1040
A40: Pontus Berglund | B40: 220 | C40: 130 | D40: 140 | E40: 130
A41: Anders Esko | B41: 220 | C41: 230 | D41: 230 | E41: 230 | F41: 230 | G41: 120 | H41: 180 | I41: 120 | J41: 230 | K41: 230 | L41: 230 | M41: 200
A42: Albert Lindström | B42: 210 | C42: 230 | D42: 230 | E42: 220 | F42: 220 | G42: 220 | H42: 0 | I42: 220 | J42: 230 | K42: 230 | L42: 230 | M42: 190
A43: Rana Baratifar | B43: 190 | C43: 190 | D43: 210 | E43: 200 | F43: 210 | G43: 210 | H43: 180 | I43: 0 | J43: 220 | K43: 230 | L43: 230 | M43: 200
A44: Annelie Corell | B44: 190 | C44: 200 | D44: 200 | E44: 190 | F44: 200 | G44: 200 | H44: 0 | I44: 200 | J44: 200 | K44: 200 | L44: 200 | M44: 190
A45: Louise From | B45: 90 | C45: 96 | D45: 96 | E45: 96 | F45: 96 | G45: 80 | H45: 96 | I45: 0 | J45: 96 | K45: 96 | L45: 96 | M45: 80
A46: Simon Lageson | F46: 120 | G46: 180 | H46: 0 | I46: 180 | J46: 200 | K46: 200 | L46: 200 | M46: 180

Sheet Grimmered
A1: Uttag poäng datum; | B1: 46081 | C1: 46086 | D1: 46106
B2: Jan | C2: Feb | D2: Mar | E2: Apr | F2: Maj | G2: Jun | H2: Jul | I2: Aug | J2: Sep | K2: Okt | L2: Nov | M2: Dec
A3: Ta ut från Verksamhetsportalen: | B3: Actual | C3: Actual | D3: Actual | E3: Actual | F3: Actual | G3: Actual | H3: Actual | I3: Actual | J3: Actual | K3: Actual | L3: Actual | M3: Actual
A4: Malin Svensson | B4: 83 | C4: 157 | D4: 164
A5: Hanna Bovin | B5: 179 | C5: 199 | D5: 250
A6: Patricia Palada | B6: 195 | C6: 261 | D6: 217
A7: Caroline Möller | B7: 114 | C7: 97 | D7: 179
A8: Emma Lisjö | B8: 183 | C8: 170 | D8: 254
B18: =SUM(B4:B17) -> 754 | C18: =SUM(C4:C17) -> 884 | D18: =SUM(D4:D17) -> 1064 | E18: =SUM(E4:E17) -> 0 | F18: =SUM(F4:F17) -> 0 | G18: =SUM(G4:G17) -> 0 | H18: =SUM(H4:H17) -> 0 | I18: =SUM(I4:I17) -> 0 | ... M18: =SUM(M4:M17) -> 0
B20: Jan | C20: Feb | D20: Mar | E20: Apr | F20: Maj | G20: Jun | H20: Jul | I20: Aug | J20: Sep | K20: Okt | L20: Nov | M20: Dec
B21: Diff | C21: Diff | D21: Diff | E21: Diff | F21: Diff | G21: Diff | H21: Diff | I21: Diff | J21: Diff | K21: Diff | L21: Diff | M21: Diff
A22: Malin | B22: =SUM(B4-B40) -> -107 | C22: =SUM(C4-C40) -> -33 | D22: =SUM(D4-D40) -> -26 | E22: =SUM(E4-E40) -> -190 | F22: =SUM(F4-F40) -> -190 | G22: =SUM(G4-G40) -> -190 | H22: =SUM(H4-H40) -> 0 | I22: =SUM(I4-I40) -> -190 | ... M22: =SUM(M4-M40) -> -190
A23: Hanna | B23: =SUM(B5-B41) -> -41 | C23: =SUM(C5-C41) -> -31 | D23: =SUM(D5-D41) -> 20 | E23: =SUM(E5-E41) -> -220 | F23: =SUM(F5-F41) -> -220 | G23: =SUM(G5-G41) -> -230 | H23: =SUM(H5-H41) -> -210 | I23: =SUM(I5-I41) -> 0 | ... M23: =SUM(M5-M41) -> -190
A24: Patricia | B24: =SUM(B6-B42) -> -25 | C24: =SUM(C6-C42) -> 31 | D24: =SUM(D6-D42) -> -13 | E24: =SUM(E6-E42) -> -220 | F24: =SUM(F6-F42) -> -220 | G24: =SUM(G6-G42) -> -230 | H24: =SUM(H6-H42) -> 0 | I24: =SUM(I6-I42) -> -230 | ... M24: =SUM(M6-M42) -> -200
A25: Caroline | B25: =SUM(B7-B43) -> -61 | C25: =SUM(C7-C43) -> -98 | D25: =SUM(D7-D43) -> -16 | E25: =SUM(E7-E43) -> -190 | F25: =SUM(F7-F43) -> -195 | G25: =SUM(G7-G43) -> -195 | H25: =SUM(H7-H43) -> -180 | I25: =SUM(I7-I43) -> 0 | ... M25: =SUM(M7-M43) -> -180
A26: Emma | B26: =SUM(B8-B44) -> -17 | C26: =SUM(C8-C44) -> -30 | D26: =SUM(D8-D44) -> 54 | E26: =SUM(E8-E44) -> -200 | F26: =SUM(F8-F44) -> -200 | G26: =SUM(G8-G44) -> -200 | H26: =SUM(H8-H44) -> -110 | I26: =SUM(I8-I44) -> -110 | ... M26: =SUM(M8-M44) -> -200
B27: =SUM(B9-B45) -> 0 | C27: =SUM(C9-C45) -> 0 | D27: =SUM(D9-D45) -> 0 | E27: =SUM(E9-E45) -> 0 | F27: =SUM(F9-F45) -> 0 | G27: =SUM(G9-G45) -> 0 | H27: =SUM(H9-H45) -> 0 | I27: =SUM(I9-I45) -> 0 | ... M27: =SUM(M9-M45) -> 0
B28: =SUM(B10-B46) -> 0 | C28: =SUM(C10-C46) -> 0 | D28: =SUM(D10-D46) -> 0 | E28: =SUM(E10-E46) -> 0 | F28: =SUM(F10-F46) -> 0 | G28: =SUM(G10-G46) -> 0 | H28: =SUM(H10-H46) -> 0 | I28: =SUM(I10-I46) -> 0 | ... M28: =SUM(M10-M46) -> 0
B29: =SUM(B11-B47) -> 0 | C29: =SUM(C11-C47) -> 0 | D29: =SUM(D11-D47) -> 0 | E29: =SUM(E11-E47) -> 0 | F29: =SUM(F11-F47) -> 0 | G29: =SUM(G11-G47) -> 0 | H29: =SUM(H11-H47) -> 0 | I29: =SUM(I11-I47) -> 0 | ... M29: =SUM(M11-M47) -> 0
B30: =SUM(B12-B48) -> 0 | C30: =SUM(C12-C48) -> 0 | D30: =SUM(D12-D48) -> 0 | E30: =SUM(E12-E48) -> 0 | F30: =SUM(F12-F48) -> 0 | G30: =SUM(G12-G48) -> 0 | H30: =SUM(H12-H48) -> 0 | I30: =SUM(I12-I48) -> 0 | ... M30: =SUM(M12-M48) -> 0
B31: =SUM(B13-B49) -> 0 | C31: =SUM(C13-C49) -> 0 | D31: =SUM(D13-D49) -> 0 | E31: =SUM(E13-E49) -> 0 | F31: =SUM(F13-F49) -> 0 | G31: =SUM(G13-G49) -> 0 | H31: =SUM(H13-H49) -> 0 | I31: =SUM(I13-I49) -> 0 | ... M31: =SUM(M13-M49) -> 0
B32: =SUM(B14-B50) -> 0 | C32: =SUM(C14-C50) -> 0 | D32: =SUM(D14-D50) -> 0 | E32: =SUM(E14-E50) -> 0 | F32: =SUM(F14-F50) -> 0 | G32: =SUM(G14-G50) -> 0 | H32: =SUM(H14-H50) -> 0 | I32: =SUM(I14-I50) -> 0 | ... M32: =SUM(M14-M50) -> 0
B33: =SUM(B15-B51) -> 0 | C33: =SUM(C15-C51) -> 0 | D33: =SUM(D15-D51) -> 0 | E33: =SUM(E15-E51) -> 0 | F33: =SUM(F15-F51) -> 0 | G33: =SUM(G15-G51) -> 0 | H33: =SUM(H15-H51) -> 0 | I33: =SUM(I15-I51) -> 0 | ... M33: =SUM(M15-M51) -> 0
B34: =SUM(B16-B52) -> 0 | C34: =SUM(C16-C52) -> 0 | D34: =SUM(D16-D52) -> 0 | E34: =SUM(E16-E52) -> 0 | F34: =SUM(F16-F52) -> 0 | G34: =SUM(G16-G52) -> 0 | H34: =SUM(H16-H52) -> 0 | I34: =SUM(I16-I52) -> 0 | ... M34: =SUM(M16-M52) -> 0
B35: =SUM(B17-B53) -> 0 | C35: =SUM(C17-C53) -> 0 | D35: =SUM(D17-D53) -> 0 | E35: =SUM(E17-E53) -> 0 | F35: =SUM(F17-F53) -> 0 | G35: =SUM(G17-G53) -> 0 | H35: =SUM(H17-H53) -> 0 | I35: =SUM(I17-I53) -> 0 | ... M35: =SUM(M17-M53) -> 0
B36: =SUM(B22:B35) -> -251 | C36: =SUM(C22:C35) -> -161 | D36: =SUM(D22:D35) -> 19 | E36: =SUM(E22:E35) -> -1020 | F36: =SUM(F22:F35) -> -1025 | G36: =SUM(G22:G35) -> -1045 | H36: =SUM(H22:H35) -> -500 | I36: =SUM(I22:I35) -> -530 | ... M36: =SUM(M22:M35) -> -960
B38: Budget | C38: Budget | D38: Budget | E38: Budget | F38: Budget | G38: Budget | H38: Budget | I38: Budget | J38: Budget | K38: Budget | L38: Budget | M38: Budget
A39: ÅRSBUDGET POÄNG 2026 = | B39: =SUM(B40:B47) -> 1005 | C39: =SUM(C40:C47) -> 1045 | D39: =SUM(D40:D47) -> 1045 | E39: =SUM(E40:E47) -> 1020 | F39: =SUM(F40:F47) -> 1025 | G39: =SUM(G40:G47) -> 1045 | H39: =SUM(H40:H47) -> 500 | I39: =SUM(I40:I47) -> 530 | ... M39: =SUM(M40:M47) -> 960
A40: Malin | B40: 190 | C40: 190 | D40: 190 | E40: 190 | F40: 190 | G40: 190 | H40: 0 | I40: 190 | J40: 190 | K40: 190 | L40: 190 | M40: 190
A41: Hanna | B41: 220 | C41: 230 | D41: 230 | E41: 220 | F41: 220 | G41: 230 | H41: 210 | I41: 0 | J41: 230 | K41: 230 | L41: 230 | M41: 190
A42: Patricia | B42: 220 | C42: 230 | D42: 230 | E42: 220 | F42: 220 | G42: 230 | H42: 0 | I42: 230 | J42: 230 | K42: 230 | L42: 230 | M42: 200
A43: Caroline | B43: 175 | C43: 195 | D43: 195 | E43: 190 | F43: 195 | G43: 195 | H43: 180 | I43: 0 | J43: 190 | K43: 190 | L43: 190 | M43: 180
A44: Emma | B44: 200 | C44: 200 | D44: 200 | E44: 200 | F44: 200 | G44: 200 | H44: 110 | I44: 110 | J44: 200 | K44: 200 | L44: 200 | M44: 200

Sheet Majorna
A1: Uttag poäng datum; | B1: 46063 | C1: 46086
B2: Jan | C2: Feb | D2: Mar | E2: Apr | F2: Maj | G2: Jun | H2: Jul | I2: Aug | J2: Sep | K2: Okt | L2: Nov | M2: Dec
A3: Ta ut från Verksamhetsportalen: | B3: Actual | C3: Actual | D3: Actual | E3: Actual | F3: Actual | G3: Actual | H3: Actual | I3: Actual | J3: Actual | K3: Actual | L3: Actual | M3: Actual
A4: Anna-Karin Book | B4: 186 | C4: 206 | D4: 165
A5: Caroline | B5: 170 | C5: 144 | D5: 186
A6: Mattias | B6: 151 | C6: 163 | D6: 216
A7: Anna-Karin S | B7: 211 | C7: 232 | D7: 202
A8: Lena | B8: 88 | C8: 103 | D8: 110
A9: Helen/Ny FT | B9: 88 | C9: 114 | D9: 124
B18: =SUM(B4:B17) -> 894 | C18: =SUM(C4:C17) -> 962 | D18: =SUM(D4:D17) -> 1003 | E18: =SUM(E4:E17) -> 0 | F18: =SUM(F4:F17) -> 0 | G18: =SUM(G4:G17) -> 0 | H18: =SUM(H4:H17) -> 0 | I18: =SUM(I4:I17) -> 0 | ... M18: =SUM(M4:M17) -> 0
B20: Jan | C20: Feb | D20: Mar | E20: Apr | F20: Maj | G20: Jun | H20: Jul | I20: Aug | J20: Sep | K20: Okt | L20: Nov | M20: Dec
B21: Diff | C21: Diff | D21: Diff | E21: Diff | F21: Diff | G21: Diff | H21: Diff | I21: Diff | J21: Diff | K21: Diff | L21: Diff | M21: Diff
A22: Anna-Karin Book | B22: =SUM(B4-B40) -> -6 | C22: =SUM(C4-C40) -> 14 | D22: =SUM(D4-D40) -> -27 | E22: =SUM(E4-E40) -> -192 | F22: =SUM(F4-F40) -> -192 | G22: =SUM(G4-G40) -> -150 | H22: =SUM(H4-H40) -> -100 | I22: =SUM(I4-I40) -> -100 | ... M22: =SUM(M4-M40) -> -165
A23: Caroline | B23: =SUM(B5-B41) -> 0 | C23: =SUM(C5-C41) -> -46 | D23: =SUM(D5-D41) -> -9 | E23: =SUM(E5-E41) -> -190 | F23: =SUM(F5-F41) -> -190 | G23: =SUM(G5-G41) -> -190 | H23: =SUM(H5-H41) -> -90 | I23: =SUM(I5-I41) -> -90 | ... M23: =SUM(M5-M41) -> -165
A24: Mattias | B24: =SUM(B6-B42) -> -64 | C24: =SUM(C6-C42) -> -57 | D24: =SUM(D6-D42) -> -24 | E24: =SUM(E6-E42) -> -240 | F24: =SUM(F6-F42) -> -240 | G24: =SUM(G6-G42) -> -230 | H24: =SUM(H6-H42) -> -60 | I24: =SUM(I6-I42) -> -120 | ... M24: =SUM(M6-M42) -> -200
A25: Anna-Karin S | B25: =SUM(B7-B43) -> 51 | C25: =SUM(C7-C43) -> -8 | D25: =SUM(D7-D43) -> -38 | E25: =SUM(E7-E43) -> -240 | F25: =SUM(F7-F43) -> -240 | G25: =SUM(G7-G43) -> -120 | H25: =SUM(H7-H43) -> -120 | I25: =SUM(I7-I43) -> -120 | ... M25: =SUM(M7-M43) -> -190
A26: Lena | B26: =SUM(B8-B44) -> -72 | C26: =SUM(C8-C44) -> -67 | D26: =SUM(D8-D44) -> -70 | E26: =SUM(E8-E44) -> -180 | F26: =SUM(F8-F44) -> -180 | G26: =SUM(G8-G44) -> -130 | H26: =SUM(H8-H44) -> -90 | I26: =SUM(I8-I44) -> -130 | ... M26: =SUM(M8-M44) -> -150
A27: Helen/Ny FT | B27: =SUM(B9-B45) -> -2 | C27: =SUM(C9-C45) -> -6 | D27: =SUM(D9-D45) -> -26 | E27: =SUM(E9-E45) -> -190 | F27: =SUM(F9-F45) -> -200 | G27: =SUM(G9-G45) -> -200 | H27: =SUM(H9-H45) -> -100 | I27: =SUM(I9-I45) -> -100 | ... M27: =SUM(M9-M45) -> -180
B28: =SUM(B10-B46) -> 0 | C28: =SUM(C10-C46) -> 0 | D28: =SUM(D10-D46) -> 0 | E28: =SUM(E10-E46) -> 0 | F28: =SUM(F10-F46) -> 0 | G28: =SUM(G10-G46) -> 0 | H28: =SUM(H10-H46) -> 0 | I28: =SUM(I10-I46) -> 0 | ... M28: =SUM(M10-M46) -> 0
B29: =SUM(B11-B47) -> 0 | C29: =SUM(C11-C47) -> 0 | D29: =SUM(D11-D47) -> 0 | E29: =SUM(E11-E47) -> 0 | F29: =SUM(F11-F47) -> 0 | G29: =SUM(G11-G47) -> 0 | H29: =SUM(H11-H47) -> 0 | I29: =SUM(I11-I47) -> 0 | ... M29: =SUM(M11-M47) -> 0
B30: =SUM(B12-B48) -> 0 | C30: =SUM(C12-C48) -> 0 | D30: =SUM(D12-D48) -> 0 | E30: =SUM(E12-E48) -> 0 | F30: =SUM(F12-F48) -> 0 | G30: =SUM(G12-G48) -> 0 | H30: =SUM(H12-H48) -> 0 | I30: =SUM(I12-I48) -> 0 | ... M30: =SUM(M12-M48) -> 0
B31: =SUM(B13-B49) -> 0 | C31: =SUM(C13-C49) -> 0 | D31: =SUM(D13-D49) -> 0 | E31: =SUM(E13-E49) -> 0 | F31: =SUM(F13-F49) -> 0 | G31: =SUM(G13-G49) -> 0 | H31: =SUM(H13-H49) -> 0 | I31: =SUM(I13-I49) -> 0 | ... M31: =SUM(M13-M49) -> 0
B32: =SUM(B14-B50) -> 0 | C32: =SUM(C14-C50) -> 0 | D32: =SUM(D14-D50) -> 0 | E32: =SUM(E14-E50) -> 0 | F32: =SUM(F14-F50) -> 0 | G32: =SUM(G14-G50) -> 0 | H32: =SUM(H14-H50) -> 0 | I32: =SUM(I14-I50) -> 0 | ... M32: =SUM(M14-M50) -> 0
B33: =SUM(B15-B51) -> 0 | C33: =SUM(C15-C51) -> 0 | D33: =SUM(D15-D51) -> 0 | E33: =SUM(E15-E51) -> 0 | F33: =SUM(F15-F51) -> 0 | G33: =SUM(G15-G51) -> 0 | H33: =SUM(H15-H51) -> 0 | I33: =SUM(I15-I51) -> 0 | ... M33: =SUM(M15-M51) -> 0
B34: =SUM(B16-B52) -> 0 | C34: =SUM(C16-C52) -> 0 | D34: =SUM(D16-D52) -> 0 | E34: =SUM(E16-E52) -> 0 | F34: =SUM(F16-F52) -> 0 | G34: =SUM(G16-G52) -> 0 | H34: =SUM(H16-H52) -> 0 | I34: =SUM(I16-I52) -> 0 | ... M34: =SUM(M16-M52) -> 0
B35: =SUM(B17-B53) -> 0 | C35: =SUM(C17-C53) -> 0 | D35: =SUM(D17-D53) -> 0 | E35: =SUM(E17-E53) -> 0 | F35: =SUM(F17-F53) -> 0 | G35: =SUM(G17-G53) -> 0 | H35: =SUM(H17-H53) -> 0 | I35: =SUM(I17-I53) -> 0 | ... M35: =SUM(M17-M53) -> 0
B36: =SUM(B22:B35) -> -93 | C36: =SUM(C22:C35) -> -170 | D36: =SUM(D22:D35) -> -194 | E36: =SUM(E22:E35) -> -1232 | F36: =SUM(F22:F35) -> -1242 | G36: =SUM(G22:G35) -> -1020 | H36: =SUM(H22:H35) -> -560 | I36: =SUM(I22:I35) -> -660 | ... M36: =SUM(M22:M35) -> -1050
B38: Budget | C38: Budget | D38: Budget | E38: Budget | F38: Budget | G38: Budget | H38: Budget | I38: Budget | J38: Budget | K38: Budget | L38: Budget | M38: Budget
A39: ÅRSBUDGET POÄNG 2026 = | B39: =SUM(B40:B53) -> 987 | C39: =SUM(C40:C53) -> 1132 | D39: =SUM(D40:D53) -> 1197 | E39: =SUM(E40:E53) -> 1232 | F39: =SUM(F40:F53) -> 1242 | G39: =SUM(G40:G53) -> 1020 | H39: =SUM(H40:H53) -> 560 | I39: =SUM(I40:I53) -> 660 | ... M39: =SUM(M40:M53) -> 1050
A40: Anna-Karin Book | B40: 192 | C40: 192 | D40: 192 | E40: 192 | F40: 192 | G40: 150 | H40: 100 | I40: 100 | J40: 192 | K40: 192 | L40: 192 | M40: 165
A41: Caroline | B41: 170 | C41: 190 | D41: 195 | E41: 190 | F41: 190 | G41: 190 | H41: 90 | I41: 90 | J41: 190 | K41: 190 | L41: 190 | M41: 165
A42: Mattias | B42: 215 | C42: 220 | D42: 240 | E42: 240 | F42: 240 | G42: 230 | H42: 60 | I42: 120 | J42: 240 | K42: 240 | L42: 240 | M42: 200
A43: Anna-Karin S | B43: 160 | C43: 240 | D43: 240 | E43: 240 | F43: 240 | G43: 120 | H43: 120 | I43: 120 | J43: 240 | K43: 240 | L43: 240 | M43: 190
A44: Lena | B44: 160 | C44: 170 | D44: 180 | E44: 180 | F44: 180 | G44: 130 | H44: 90 | I44: 130 | J44: 180 | K44: 180 | L44: 180 | M44: 150
A45: Helen/Ny FT | B45: 90 | C45: 120 | D45: 150 | E45: 190 | F45: 200 | G45: 200 | H45: 100 | I45: 100 | J45: 210 | K45: 210 | L45: 210 | M45: 180

Sheet Pedagogen Park
A1: Uttag poäng datum; | B1: 46081 | C1: 46086 | D1: 46106
B2: Jan | C2: Feb | D2: Mar | E2: Apr | F2: Maj | G2: Jun | H2: Jul | I2: Aug | J2: Sep | K2: Okt | L2: Nov | M2: Dec
A3: Ta ut från Verksamhetsportalen: | B3: Actual | C3: Actual | D3: Actual | E3: Actual | F3: Actual | G3: Actual | H3: Actual | I3: Actual | J3: Actual | K3: Actual | L3: Actual | M3: Actual | N3: Kommentarer;
A4: Arvid Lennartsson | B4: 101 | C4: 140 | D4: 145
A5: Charlotte Alderblad | B5: 167 | C5: 171 | D5: 187
A6: Ida Hasselholm | B6: 111 | C6: 54 | D6: 202
A7: Matilda Saukkorripi | B7: 99 | C7: 167 | D7: 251
A8: Lisa T
B18: =SUM(B4:B17) -> 478 | C18: =SUM(C4:C17) -> 532 | D18: =SUM(D4:D17) -> 785 | E18: =SUM(E4:E17) -> 0 | F18: =SUM(F4:F17) -> 0 | G18: =SUM(G4:G17) -> 0 | H18: =SUM(H4:H17) -> 0 | I18: =SUM(I4:I17) -> 0 | ... M18: =SUM(M4:M17) -> 0
B20: Jan | C20: Feb | D20: Mar | E20: Apr | F20: Maj | G20: Jun | H20: Jul | I20: Aug | J20: Sep | K20: Okt | L20: Nov | M20: Dec
B21: DIFF | C21: DIFF | D21: DIFF | E21: DIFF | F21: DIFF | G21: DIFF | H21: DIFF | I21: DIFF | J21: DIFF | K21: DIFF | L21: DIFF | M21: DIFF | N21: Kommentarer;
A22: Arvid Lennartsson | B22: =SUM(B4-B40) -> 1 | C22: =SUM(C4-C40) -> 40 | D22: =SUM(D4-D40) -> 95 | E22: =SUM(E4-E40) -> -40 | F22: =SUM(F4-F40) -> -50 | G22: =SUM(G4-G40) -> -140 | H22: =SUM(H4-H40) -> -200 | I22: =SUM(I4-I40) -> -200 | ... M22: =SUM(M4-M40) -> -70
A23: Charlotte Alderblad | B23: =SUM(B5-B41) -> -43 | C23: =SUM(C5-C41) -> -69 | D23: =SUM(D5-D41) -> -53 | E23: =SUM(E5-E41) -> -220 | F23: =SUM(F5-F41) -> -220 | G23: =SUM(G5-G41) -> -220 | H23: =SUM(H5-H41) -> -240 | I23: =SUM(I5-I41) -> 0 | ... M23: =SUM(M5-M41) -> -170
A24: Ida Hasselholm | B24: =SUM(B6-B42) -> 11 | C24: =SUM(C6-C42) -> -66 | D24: =SUM(D6-D42) -> -38 | E24: =SUM(E6-E42) -> -210 | F24: =SUM(F6-F42) -> -210 | G24: =SUM(G6-G42) -> -200 | H24: =SUM(H6-H42) -> -160 | I24: =SUM(I6-I42) -> -220 | ... M24: =SUM(M6-M42) -> -200
A25: Matilda Saukkorripi | B25: =SUM(B7-B43) -> -91 | C25: =SUM(C7-C43) -> -33 | D25: =SUM(D7-D43) -> 51 | E25: =SUM(E7-E43) -> -200 | F25: =SUM(F7-F43) -> -200 | G25: =SUM(G7-G43) -> -200 | H25: =SUM(H7-H43) -> 0 | I25: =SUM(I7-I43) -> -200 | ... M25: =SUM(M7-M43) -> -170
A26: Lisa T | B26: =SUM(B8-B44) -> 0 | C26: =SUM(C8-C44) -> 0 | D26: =SUM(D8-D44) -> 0 | E26: =SUM(E8-E44) -> -65 | F26: =SUM(F8-F44) -> -80 | G26: =SUM(G8-G44) -> -40 | H26: =SUM(H8-H44) -> 0 | I26: =SUM(I8-I44) -> -40 | ... M26: =SUM(M8-M44) -> -65
B27: =SUM(B9-B45) -> 0 | C27: =SUM(C9-C45) -> 0 | D27: =SUM(D9-D45) -> 0 | E27: =SUM(E9-E45) -> 0 | F27: =SUM(F9-F45) -> 0 | G27: =SUM(G9-G45) -> 0 | H27: =SUM(H9-H45) -> 0 | I27: =SUM(I9-I45) -> 0 | ... M27: =SUM(M9-M45) -> 0
B28: =SUM(B10-B46) -> 0 | C28: =SUM(C10-C46) -> 0 | D28: =SUM(D10-D46) -> 0 | E28: =SUM(E10-E46) -> 0 | F28: =SUM(F10-F46) -> 0 | G28: =SUM(G10-G46) -> 0 | H28: =SUM(H10-H46) -> 0 | I28: =SUM(I10-I46) -> 0 | ... M28: =SUM(M10-M46) -> 0
B29: =SUM(B11-B47) -> 0 | C29: =SUM(C11-C47) -> 0 | D29: =SUM(D11-D47) -> 0 | E29: =SUM(E11-E47) -> 0 | F29: =SUM(F11-F47) -> 0 | G29: =SUM(G11-G47) -> 0 | H29: =SUM(H11-H47) -> 0 | I29: =SUM(I11-I47) -> 0 | ... M29: =SUM(M11-M47) -> 0
B30: =SUM(B12-B48) -> 0 | C30: =SUM(C12-C48) -> 0 | D30: =SUM(D12-D48) -> 0 | E30: =SUM(E12-E48) -> 0 | F30: =SUM(F12-F48) -> 0 | G30: =SUM(G12-G48) -> 0 | H30: =SUM(H12-H48) -> 0 | I30: =SUM(I12-I48) -> 0 | ... M30: =SUM(M12-M48) -> 0
B31: =SUM(B13-B49) -> 0 | C31: =SUM(C13-C49) -> 0 | D31: =SUM(D13-D49) -> 0 | E31: =SUM(E13-E49) -> 0 | F31: =SUM(F13-F49) -> 0 | G31: =SUM(G13-G49) -> 0 | H31: =SUM(H13-H49) -> 0 | I31: =SUM(I13-I49) -> 0 | ... M31: =SUM(M13-M49) -> 0
B32: =SUM(B14-B50) -> 0 | C32: =SUM(C14-C50) -> 0 | D32: =SUM(D14-D50) -> 0 | E32: =SUM(E14-E50) -> 0 | F32: =SUM(F14-F50) -> 0 | G32: =SUM(G14-G50) -> 0 | H32: =SUM(H14-H50) -> 0 | I32: =SUM(I14-I50) -> 0 | ... M32: =SUM(M14-M50) -> 0
B33: =SUM(B15-B51) -> 0 | C33: =SUM(C15-C51) -> 0 | D33: =SUM(D15-D51) -> 0 | E33: =SUM(E15-E51) -> 0 | F33: =SUM(F15-F51) -> 0 | G33: =SUM(G15-G51) -> 0 | H33: =SUM(H15-H51) -> 0 | I33: =SUM(I15-I51) -> 0 | ... M33: =SUM(M15-M51) -> 0
B34: =SUM(B16-B52) -> 0 | C34: =SUM(C16-C52) -> 0 | D34: =SUM(D16-D52) -> 0 | E34: =SUM(E16-E52) -> 0 | F34: =SUM(F16-F52) -> 0 | G34: =SUM(G16-G52) -> 0 | H34: =SUM(H16-H52) -> 0 | I34: =SUM(I16-I52) -> 0 | ... M34: =SUM(M16-M52) -> 0
B35: =SUM(B17-B53) -> 0 | C35: =SUM(C17-C53) -> 0 | D35: =SUM(D17-D53) -> 0 | E35: =SUM(E17-E53) -> 0 | F35: =SUM(F17-F53) -> 0 | G35: =SUM(G17-G53) -> 0 | H35: =SUM(H17-H53) -> 0 | I35: =SUM(I17-I53) -> 0 | ... M35: =SUM(M17-M53) -> 0
B36: =SUM(B22:B35) -> -122 | C36: =SUM(C22:C35) -> -128 | D36: =SUM(D22:D35) -> 55 | E36: =SUM(E22:E35) -> -735 | F36: =SUM(F22:F35) -> -760 | G36: =SUM(G22:G35) -> -800 | H36: =SUM(H22:H35) -> -600 | I36: =SUM(I22:I35) -> -660 | ... M36: =SUM(M22:M35) -> -675
B38: Budget | C38: Budget | D38: Budget | E38: Budget | F38: Budget | G38: Budget | H38: Budget | I38: Budget | J38: Budget | K38: Budget | L38: Budget | M38: Budget
A39: ÅRSBUDGET POÄNG 2026 = | B39: =SUM(B40:B44) -> 600 | C39: =SUM(C40:C44) -> 660 | D39: =SUM(D40:D44) -> 730 | E39: =SUM(E40:E44) -> 735 | F39: =SUM(F40:F44) -> 760 | G39: =SUM(G40:G44) -> 800 | H39: =SUM(H40:H44) -> 600 | I39: =SUM(I40:I44) -> 660 | ... M39: =SUM(M40:M44) -> 675
A40: Arvid Lennartsson | B40: 100 | C40: 100 | D40: 50 | E40: 40 | F40: 50 | G40: 140 | H40: 200 | I40: 200 | J40: 100 | K40: 100 | L40: 100 | M40: 70
A41: Charlotte Alderblad | B41: 210 | C41: 240 | D41: 240 | E41: 220 | F41: 220 | G41: 220 | H41: 240 | I41: 0 | J41: 200 | K41: 200 | L41: 200 | M41: 170
A42: Ida Hasselholm | B42: 100 | C42: 120 | D42: 240 | E42: 210 | F42: 210 | G42: 200 | H42: 160 | I42: 220 | J42: 220 | K42: 220 | L42: 220 | M42: 200
A43: Matilda Saukkorripi | B43: 190 | C43: 200 | D43: 200 | E43: 200 | F43: 200 | G43: 200 | H43: 0 | I43: 200 | J43: 200 | K43: 200 | L43: 200 | M43: 170
A44: Lisa T | E44: 65 | F44: 80 | G44: 40 | H44: 0 | I44: 40 | J44: 40 | K44: 80 | L44: 80 | M44: 65

Sheet Åby
A1: Uttag poäng datum; | B1: 46063 | C1: 46086
B2: Jan | C2: Feb | D2: Mar | E2: Apr | F2: Maj | G2: Jun | H2: Jul | I2: Aug | J2: Sep | K2: Okt | L2: Nov | M2: Dec
A3: Ta ut från Verksamhetsportalen: | B3: Actual | C3: Actual | D3: Actual | E3: Actual | F3: Actual | G3: Actual | H3: Actual | I3: Actual | J3: Actual | K3: Actual | L3: Actual | M3: Actual
A4: Anna Abrahamsson | B4: 176 | C4: 133 | D4: 180
A5: Caroline Lindahl | B5: 204 | C5: 199 | D5: 219
A6: Catarina Engström | B6: 190 | C6: 251 | D6: 278
A7: Lisa Torell
A8: Michaela Voeler | B8: 204 | C8: 207 | D8: 178
A9: Lisa Edvardsson | B9: 147 | C9: 264 | D9: 248
A10: Anna-Klara Å | B10: 5
B18: =SUM(B4:B17) -> 926 | C18: =SUM(C4:C17) -> 1054 | D18: =SUM(D4:D17) -> 1103 | E18: =SUM(E4:E17) -> 0 | F18: =SUM(F4:F17) -> 0 | G18: =SUM(G4:G17) -> 0 | H18: =SUM(H4:H17) -> 0 | I18: =SUM(I4:I17) -> 0 | ... M18: =SUM(M4:M17) -> 0
B20: Jan | C20: Feb | D20: Mar | E20: Apr | F20: Maj | G20: Jun | H20: Jul | I20: Aug | J20: Sep | K20: Okt | L20: Nov | M20: Dec
B21: Diff | C21: Diff | D21: Diff | E21: Diff | F21: Diff | G21: Diff | H21: Diff | I21: Diff | J21: Diff | K21: Diff | L21: Diff | M21: Diff
A22: Anna Abrahamsson | B22: =SUM(B4-B40) -> -14 | C22: =SUM(C4-C40) -> -71 | D22: =SUM(D4-D40) -> 26 | E22: =SUM(E4-E40) -> -192 | F22: =SUM(F4-F40) -> -192 | G22: =SUM(G4-G40) -> -143 | H22: =SUM(H4-H40) -> -102 | I22: =SUM(I4-I40) -> -153 | ... M22: =SUM(M4-M40) -> -144
A23: Caroline Lindahl | B23: =SUM(B5-B41) -> 41 | C23: =SUM(C5-C41) -> 55 | D23: =SUM(D5-D41) -> 27 | E23: =SUM(E5-E41) -> -154 | F23: =SUM(F5-F41) -> -190 | G23: =SUM(G5-G41) -> -170 | H23: =SUM(H5-H41) -> -48 | I23: =SUM(I5-I41) -> -96 | ... M23: =SUM(M5-M41) -> -144
A24: Catarina Engström | B24: =SUM(B6-B42) -> -2 | C24: =SUM(C6-C42) -> 131 | D24: =SUM(D6-D42) -> 62 | E24: =SUM(E6-E42) -> -175 | F24: =SUM(F6-F42) -> -192 | G24: =SUM(G6-G42) -> -156 | H24: =SUM(H6-H42) -> -120 | I24: =SUM(I6-I42) -> -160 | ... M24: =SUM(M6-M42) -> -168
A25: Lisa Torell | B25: =SUM(B7-B43) -> 0 | C25: =SUM(C7-C43) -> 0 | D25: =SUM(D7-D43) -> -100 | E25: =SUM(E7-E43) -> -90 | F25: =SUM(F7-F43) -> -120 | G25: =SUM(G7-G43) -> -100 | H25: =SUM(H7-H43) -> -30 | I25: =SUM(I7-I43) -> -60 | ... M25: =SUM(M7-M43) -> -90
A26: Michaela Voeler | B26: =SUM(B8-B44) -> 9 | C26: =SUM(C8-C44) -> 52 | D26: =SUM(D8-D44) -> -26 | E26: =SUM(E8-E44) -> -195 | F26: =SUM(F8-F44) -> -195 | G26: =SUM(G8-G44) -> -195 | H26: =SUM(H8-H44) -> -100 | I26: =SUM(I8-I44) -> -154 | ... M26: =SUM(M8-M44) -> -144
A27: Lisa Edvardsson | B27: =SUM(B9-B45) -> 3 | C27: =SUM(C9-C45) -> 74 | D27: =SUM(D9-D45) -> 48 | E27: =SUM(E9-E45) -> -200 | F27: =SUM(F9-F45) -> -156 | G27: =SUM(G9-G45) -> -200 | H27: =SUM(H9-H45) -> -120 | I27: =SUM(I9-I45) -> -120 | ... M27: =SUM(M9-M45) -> -180
A28: Anna-Klara Å | B28: =SUM(B10-B46) -> 5 | C28: =SUM(C10-C46) -> 0 | D28: =SUM(D10-D46) -> 0 | E28: =SUM(E10-E46) -> 0 | F28: =SUM(F10-F46) -> 0 | G28: =SUM(G10-G46) -> 0 | H28: =SUM(H10-H46) -> 0 | I28: =SUM(I10-I46) -> 0 | ... M28: =SUM(M10-M46) -> 0
B29: =SUM(B11-B47) -> 0 | C29: =SUM(C11-C47) -> 0 | D29: =SUM(D11-D47) -> 0 | E29: =SUM(E11-E47) -> 0 | F29: =SUM(F11-F47) -> 0 | G29: =SUM(G11-G47) -> 0 | H29: =SUM(H11-H47) -> 0 | I29: =SUM(I11-I47) -> 0 | ... M29: =SUM(M11-M47) -> 0
B30: =SUM(B12-B48) -> 0 | C30: =SUM(C12-C48) -> 0 | D30: =SUM(D12-D48) -> 0 | E30: =SUM(E12-E48) -> 0 | F30: =SUM(F12-F48) -> 0 | G30: =SUM(G12-G48) -> 0 | H30: =SUM(H12-H48) -> 0 | I30: =SUM(I12-I48) -> 0 | ... M30: =SUM(M12-M48) -> 0
B31: =SUM(B13-B49) -> 0 | C31: =SUM(C13-C49) -> 0 | D31: =SUM(D13-D49) -> 0 | E31: =SUM(E13-E49) -> 0 | F31: =SUM(F13-F49) -> 0 | G31: =SUM(G13-G49) -> 0 | H31: =SUM(H13-H49) -> 0 | I31: =SUM(I13-I49) -> 0 | ... M31: =SUM(M13-M49) -> 0
B32: =SUM(B14-B50) -> 0 | C32: =SUM(C14-C50) -> 0 | D32: =SUM(D14-D50) -> 0 | E32: =SUM(E14-E50) -> 0 | F32: =SUM(F14-F50) -> 0 | G32: =SUM(G14-G50) -> 0 | H32: =SUM(H14-H50) -> 0 | I32: =SUM(I14-I50) -> 0 | ... M32: =SUM(M14-M50) -> 0
B33: =SUM(B15-B51) -> 0 | C33: =SUM(C15-C51) -> 0 | D33: =SUM(D15-D51) -> 0 | E33: =SUM(E15-E51) -> 0 | F33: =SUM(F15-F51) -> 0 | G33: =SUM(G15-G51) -> 0 | H33: =SUM(H15-H51) -> 0 | I33: =SUM(I15-I51) -> 0 | ... M33: =SUM(M15-M51) -> 0
B34: =SUM(B16-B52) -> 0 | C34: =SUM(C16-C52) -> 0 | D34: =SUM(D16-D52) -> 0 | E34: =SUM(E16-E52) -> 0 | F34: =SUM(F16-F52) -> 0 | G34: =SUM(G16-G52) -> 0 | H34: =SUM(H16-H52) -> 0 | I34: =SUM(I16-I52) -> 0 | ... M34: =SUM(M16-M52) -> 0
B35: =SUM(B17-B53) -> 0 | C35: =SUM(C17-C53) -> 0 | D35: =SUM(D17-D53) -> 0 | E35: =SUM(E17-E53) -> 0 | F35: =SUM(F17-F53) -> 0 | G35: =SUM(G17-G53) -> 0 | H35: =SUM(H17-H53) -> 0 | I35: =SUM(I17-I53) -> 0 | ... M35: =SUM(M17-M53) -> 0
B36: =SUM(B22:B35) -> 42 | C36: =SUM(C22:C35) -> 241 | D36: =SUM(D22:D35) -> 37 | E36: =SUM(E22:E35) -> -1006 | F36: =SUM(F22:F35) -> -1045 | G36: =SUM(G22:G35) -> -964 | H36: =SUM(H22:H35) -> -520 | I36: =SUM(I22:I35) -> -743 | ... M36: =SUM(M22:M35) -> -870
B38: Budget | C38: Budget | D38: Budget | E38: Budget | F38: Budget | G38: Budget | H38: Budget | I38: Budget | J38: Budget | K38: Budget | L38: Budget | M38: Budget
A39: ÅRSBUDGET POÄNG 2026 = | B39: 890 | C39: 1105 | D39: 1295 | E39: 1050 | F39: 1180 | G39: 890 | H39: 240 | I39: 1040 | J39: 1285 | K39: 1283 | L39: 1188 | M39: 1040
A40: Anna Abrahamsson | B40: 190 | C40: 204 | D40: 154 | E40: 192 | F40: 192 | G40: 143 | H40: 102 | I40: 153 | J40: 204 | K40: 204 | L40: 153 | M40: 144
A41: Caroline Lindahl | B41: 163 | C41: 144 | D41: 192 | E41: 154 | F41: 190 | G41: 170 | H41: 48 | I41: 96 | J41: 192 | K41: 173 | L41: 192 | M41: 144
A42: Catarina Engström | B42: 192 | C42: 120 | D42: 216 | E42: 175 | F42: 192 | G42: 156 | H42: 120 | I42: 160 | J42: 150 | K42: 180 | L42: 220 | M42: 168
A43: Lisa Torell | B43: 0 | C43: 0 | D43: 100 | E43: 90 | F43: 120 | G43: 100 | H43: 30 | I43: 60 | J43: 100 | K43: 100 | L43: 100 | M43: 90
A44: Michaela Voeler | B44: 195 | C44: 155 | D44: 204 | E44: 195 | F44: 195 | G44: 195 | H44: 100 | I44: 154 | J44: 204 | K44: 204 | L44: 204 | M44: 144
A45: Lisa Edvardsson | B45: 144 | C45: 190 | D45: 200 | E45: 200 | F45: 156 | G45: 200 | H45: 120 | I45: 120 | J45: 220 | K45: 228 | L45: 228 | M45: 180
A46: Anna-Klara Å

Sheet Olskroken
A1: Uttag poäng datum; | B1: 46063 | C1: 46086 | D1: 46106
B2: Jan | C2: Feb | D2: Mar | E2: Apr | F2: Maj | G2: Jun | H2: Jul | I2: Aug | J2: Sep | K2: Okt | L2: Nov | M2: Dec
A3: Ta ut från Verksamhetsportalen: | B3: Actual | C3: Actual | D3: Actual | E3: Actual | F3: Actual | G3: Actual | H3: Actual | I3: Actual | J3: Actual | K3: Actual | L3: Actual | M3: Actual
A4: Malena Ryberg | B4: 184 | C4: 119 | D4: 253
A5: Linnea | B5: 149
A6: Felix W | B6: 8
A7: Ersättare Felix/ Erik S | C7: 122 | D7: 186
A8: Helena Ö | B8: 167 | C8: 148 | D8: 129
A9: Ersättare Linnea/ Isak | C9: 7 | D9: 41
A10: Elin M | B10: 46 | C10: 92 | D10: 19
B18: =SUM(B4:B17) -> 554 | C18: =SUM(C4:C17) -> 488 | D18: =SUM(D4:D17) -> 628 | E18: =SUM(E4:E17) -> 0 | F18: =SUM(F4:F17) -> 0 | G18: =SUM(G4:G17) -> 0 | H18: =SUM(H4:H17) -> 0 | I18: =SUM(I4:I17) -> 0 | ... M18: =SUM(M4:M17) -> 0
B20: Jan | C20: Feb | D20: Mar | E20: Apr | F20: Maj | G20: Jun | H20: Jul | I20: Aug | J20: Sep | K20: Okt | L20: Nov | M20: Dec
B21: Diff | C21: Diff | D21: Diff | E21: Diff | F21: Diff | G21: Diff | H21: Diff | I21: Diff | J21: Diff | K21: Diff | L21: Diff | M21: Diff
A22: Malena | B22: =SUM(B4-B40) -> -6 | C22: =SUM(C4-C40) -> -111 | D22: =SUM(D4-D40) -> 23 | E22: =SUM(E4-E40) -> -200 | F22: =SUM(F4-F40) -> -230 | G22: =SUM(G4-G40) -> -220 | H22: =SUM(H4-H40) -> -120 | I22: =SUM(I4-I40) -> -165 | ... M22: =SUM(M4-M40) -> -180
A23: Linnea | B23: =SUM(B5-B41) -> -41 | C23: =SUM(C5-C41) -> 0 | D23: =SUM(D5-D41) -> 0 | E23: =SUM(E5-E41) -> 0 | F23: =SUM(F5-F41) -> 0 | G23: =SUM(G5-G41) -> 0 | H23: =SUM(H5-H41) -> 0 | I23: =SUM(I5-I41) -> 0 | ... M23: =SUM(M5-M41) -> 0
A24: Felix | B24: =SUM(B6-B42) -> 8 | C24: =SUM(C6-C42) -> 0 | D24: =SUM(D6-D42) -> 0 | E24: =SUM(E6-E42) -> 0 | F24: =SUM(F6-F42) -> 0 | G24: =SUM(G6-G42) -> 0 | H24: =SUM(H6-H42) -> 0 | I24: =SUM(I6-I42) -> 0 | ... M24: =SUM(M6-M42) -> -140
A25: Ersättare Felix | B25: =SUM(B7-B43) -> -80 | C25: =SUM(C7-C43) -> -58 | D25: =SUM(D7-D43) -> -14 | E25: =SUM(E7-E43) -> -200 | F25: =SUM(F7-F43) -> -220 | G25: =SUM(G7-G43) -> -200 | H25: =SUM(H7-H43) -> -40 | I25: =SUM(I7-I43) -> -160 | ... M25: =SUM(M7-M43) -> 0
A26: Helena | B26: =SUM(B8-B44) -> 2 | C26: =SUM(C8-C44) -> -52 | D26: =SUM(D8-D44) -> -76 | E26: =SUM(E8-E44) -> -205 | F26: =SUM(F8-F44) -> -205 | G26: =SUM(G8-G44) -> -205 | H26: =SUM(H8-H44) -> -100 | I26: =SUM(I8-I44) -> -100 | ... M26: =SUM(M8-M44) -> -160
A27: Ersättare Linnea | B27: =SUM(B9-B45) -> 0 | C27: =SUM(C9-C45) -> -93 | D27: =SUM(D9-D45) -> -119 | E27: =SUM(E9-E45) -> -200 | F27: =SUM(F9-F45) -> -220 | G27: =SUM(G9-G45) -> -220 | H27: =SUM(H9-H45) -> -120 | I27: =SUM(I9-I45) -> -120 | ... M27: =SUM(M9-M45) -> -180
A28: Elin M | B28: =SUM(B10-B46) -> 46 | C28: =SUM(C10-C46) -> 92 | D28: =SUM(D10-D46) -> 19 | E28: =SUM(E10-E46) -> 0 | F28: =SUM(F10-F46) -> 0 | G28: =SUM(G10-G46) -> 0 | H28: =SUM(H10-H46) -> 0 | I28: =SUM(I10-I46) -> 0 | ... M28: =SUM(M10-M46) -> 0
B29: =SUM(B11-B47) -> 0 | C29: =SUM(C11-C47) -> 0 | D29: =SUM(D11-D47) -> 0 | E29: =SUM(E11-E47) -> 0 | F29: =SUM(F11-F47) -> 0 | G29: =SUM(G11-G47) -> 0 | H29: =SUM(H11-H47) -> 0 | I29: =SUM(I11-I47) -> 0 | ... M29: =SUM(M11-M47) -> 0
B30: =SUM(B12-B48) -> 0 | C30: =SUM(C12-C48) -> 0 | D30: =SUM(D12-D48) -> 0 | E30: =SUM(E12-E48) -> 0 | F30: =SUM(F12-F48) -> 0 | G30: =SUM(G12-G48) -> 0 | H30: =SUM(H12-H48) -> 0 | I30: =SUM(I12-I48) -> 0 | ... M30: =SUM(M12-M48) -> 0
B31: =SUM(B13-B49) -> 0 | C31: =SUM(C13-C49) -> 0 | D31: =SUM(D13-D49) -> 0 | E31: =SUM(E13-E49) -> 0 | F31: =SUM(F13-F49) -> 0 | G31: =SUM(G13-G49) -> 0 | H31: =SUM(H13-H49) -> 0 | I31: =SUM(I13-I49) -> 0 | ... M31: =SUM(M13-M49) -> 0
B32: =SUM(B14-B50) -> 0 | C32: =SUM(C14-C50) -> 0 | D32: =SUM(D14-D50) -> 0 | E32: =SUM(E14-E50) -> 0 | F32: =SUM(F14-F50) -> 0 | G32: =SUM(G14-G50) -> 0 | H32: =SUM(H14-H50) -> 0 | I32: =SUM(I14-I50) -> 0 | ... M32: =SUM(M14-M50) -> 0
B33: =SUM(B15-B51) -> 0 | C33: =SUM(C15-C51) -> 0 | D33: =SUM(D15-D51) -> 0 | E33: =SUM(E15-E51) -> 0 | F33: =SUM(F15-F51) -> 0 | G33: =SUM(G15-G51) -> 0 | H33: =SUM(H15-H51) -> 0 | I33: =SUM(I15-I51) -> 0 | ... M33: =SUM(M15-M51) -> 0
B34: =SUM(B16-B52) -> 0 | C34: =SUM(C16-C52) -> 0 | D34: =SUM(D16-D52) -> 0 | E34: =SUM(E16-E52) -> 0 | F34: =SUM(F16-F52) -> 0 | G34: =SUM(G16-G52) -> 0 | H34: =SUM(H16-H52) -> 0 | I34: =SUM(I16-I52) -> 0 | ... M34: =SUM(M16-M52) -> 0
B35: =SUM(B17-B53) -> 0 | C35: =SUM(C17-C53) -> 0 | D35: =SUM(D17-D53) -> 0 | E35: =SUM(E17-E53) -> 0 | F35: =SUM(F17-F53) -> 0 | G35: =SUM(G17-G53) -> 0 | H35: =SUM(H17-H53) -> 0 | I35: =SUM(I17-I53) -> 0 | ... M35: =SUM(M17-M53) -> 0
B36: =SUM(B22:B35) -> -71 | C36: =SUM(C22:C35) -> -222 | D36: =SUM(D22:D35) -> -167 | E36: =SUM(E22:E35) -> -805 | F36: =SUM(F22:F35) -> -875 | G36: =SUM(G22:G35) -> -845 | H36: =SUM(H22:H35) -> -380 | I36: =SUM(I22:I35) -> -545 | ... M36: =SUM(M22:M35) -> -660
B38: Budget | C38: Budget | D38: Budget | E38: Budget | F38: Budget | G38: Budget | H38: Budget | I38: Budget | J38: Budget | K38: Budget | L38: Budget | M38: Budget
A39: ÅRSBUDGET POÄNG 2026 = | B39: =SUM(B40:B48) -> 625 | C39: =SUM(C40:C48) -> 710 | D39: =SUM(D40:D48) -> 795 | E39: =SUM(E40:E48) -> 805 | F39: =SUM(F40:F48) -> 875 | G39: =SUM(G40:G48) -> 845 | H39: =SUM(H40:H48) -> 380 | I39: =SUM(I40:I48) -> 545 | ... M39: =SUM(M40:M48) -> 660
A40: Malena | B40: 190 | C40: 230 | D40: 230 | E40: 200 | F40: 230 | G40: 220 | H40: 120 | I40: 165 | J40: 230 | K40: 230 | L40: 230 | M40: 180
A41: Linnea | B41: 190 | C41: 0
A42: Felix | J42: 120 | K42: 180 | L42: 180 | M42: 140
A43: Ersättare Felix | B43: 80 | C43: 180 | D43: 200 | E43: 200 | F43: 220 | G43: 200 | H43: 40 | I43: 160
A44: Helena | B44: 165 | C44: 200 | D44: 205 | E44: 205 | F44: 205 | G44: 205 | H44: 100 | I44: 100 | J44: 220 | K44: 220 | L44: 220 | M44: 160
A45: Ersättare Linnea | C45: 100 | D45: 160 | E45: 200 | F45: 220 | G45: 220 | H45: 120 | I45: 120 | J45: 230 | K45: 230 | L45: 230 | M45: 180
A46: Elin M

Sheet Avenyn
A1: Uttag poäng datum; | B1: 46063 | C1: 46086
B2: Jan | C2: Feb | D2: Mar | E2: Apr | F2: Maj | G2: Jun | H2: Jul | I2: Aug | J2: Sep | K2: Okt | L2: Nov | M2: Dec
A3: Ta ut från Verksamhetsportalen: | B3: Actual | C3: Actual | D3: Actual | E3: Actual | F3: Actual | G3: Actual | H3: Actual | I3: Actual | J3: Actual | K3: Actual | L3: Actual | M3: Actual
A4: Elin Jolsö | B4: 117 | C4: 8 | D4: 57
A5: Linnea Andersson | B5: 139 | C5: 221 | D5: 279
A6: Nina Nexborn | B6: 121 | C6: 148 | D6: 174
A7: Emil Sevestedt | B7: 157 | C7: 177 | D7: 238
A8: Rebecka Svensson | B8: 153 | C8: 207 | D8: 197
A9: Agnes Wykman | B9: 199 | C9: 136 | D9: 220
A10: Elin M | C10: 13 | D10: 88
B18: =SUM(B4:B17) -> 886 | C18: =SUM(C4:C17) -> 910 | D18: =SUM(D4:D17) -> 1253 | E18: =SUM(E4:E17) -> 0 | F18: =SUM(F4:F17) -> 0 | G18: =SUM(G4:G17) -> 0 | H18: =SUM(H4:H17) -> 0 | I18: =SUM(I4:I17) -> 0 | ... M18: =SUM(M4:M17) -> 0
B20: Jan | C20: Feb | D20: Mar | E20: Apr | F20: Maj | G20: Jun | H20: Jul | I20: Aug | J20: Sep | K20: Okt | L20: Nov | M20: Dec
B21: Diff | C21: Diff | D21: Diff | E21: Diff | F21: Diff | G21: Diff | H21: Diff | I21: Diff | J21: Diff | K21: Diff | L21: Diff | M21: Diff
A22: Elin | B22: =SUM(B4-B40) -> -23 | C22: =SUM(C4-C40) -> -132 | D22: =SUM(D4-D40) -> -103 | E22: =SUM(E4-E40) -> -160 | F22: =SUM(F4-F40) -> -160 | G22: =SUM(G4-G40) -> -140 | H22: =SUM(H4-H40) -> -70 | I22: =SUM(I4-I40) -> -70 | ... M22: =SUM(M4-M40) -> -140
A23: Linnea | B23: =SUM(B5-B41) -> -71 | C23: =SUM(C5-C41) -> -4 | D23: =SUM(D5-D41) -> 39 | E23: =SUM(E5-E41) -> -220 | F23: =SUM(F5-F41) -> -240 | G23: =SUM(G5-G41) -> -220 | H23: =SUM(H5-H41) -> -70 | I23: =SUM(I5-I41) -> -180 | ... M23: =SUM(M5-M41) -> -170
A24: Nina | B24: =SUM(B6-B42) -> -79 | C24: =SUM(C6-C42) -> -52 | D24: =SUM(D6-D42) -> -36 | E24: =SUM(E6-E42) -> -170 | F24: =SUM(F6-F42) -> -200 | G24: =SUM(G6-G42) -> -180 | H24: =SUM(H6-H42) -> 0 | I24: =SUM(I6-I42) -> -200 | ... M24: =SUM(M6-M42) -> -150
A25: Emil | B25: =SUM(B7-B43) -> -53 | C25: =SUM(C7-C43) -> -3 | D25: =SUM(D7-D43) -> -2 | E25: =SUM(E7-E43) -> -220 | F25: =SUM(F7-F43) -> -240 | G25: =SUM(G7-G43) -> -200 | H25: =SUM(H7-H43) -> -120 | I25: =SUM(I7-I43) -> -120 | ... M25: =SUM(M7-M43) -> -170
A26: Rebecka | B26: =SUM(B8-B44) -> -47 | C26: =SUM(C8-C44) -> -13 | D26: =SUM(D8-D44) -> -23 | E26: =SUM(E8-E44) -> -200 | F26: =SUM(F8-F44) -> -190 | G26: =SUM(G8-G44) -> -200 | H26: =SUM(H8-H44) -> 0 | I26: =SUM(I8-I44) -> -230 | ... M26: =SUM(M8-M44) -> -170
A27: Agnes | B27: =SUM(B9-B45) -> -11 | C27: =SUM(C9-C45) -> -74 | D27: =SUM(D9-D45) -> 10 | E27: =SUM(E9-E45) -> -210 | F27: =SUM(F9-F45) -> -200 | G27: =SUM(G9-G45) -> -200 | H27: =SUM(H9-H45) -> -200 | I27: =SUM(I9-I45) -> -60 | ... M27: =SUM(M9-M45) -> -170
A28: Johanna | B28: =SUM(B10-B46) -> 0 | C28: =SUM(C10-C46) -> 13 | D28: =SUM(D10-D46) -> 88 | E28: =SUM(E10-E46) -> 0 | F28: =SUM(F10-F46) -> -60 | G28: =SUM(G10-G46) -> -160 | H28: =SUM(H10-H46) -> -200 | I28: =SUM(I10-I46) -> 0 | ... M28: =SUM(M10-M46) -> -170
B29: =SUM(B11-B47) -> 0 | C29: =SUM(C11-C47) -> 0 | D29: =SUM(D11-D47) -> 0 | E29: =SUM(E11-E47) -> 0 | F29: =SUM(F11-F47) -> 0 | G29: =SUM(G11-G47) -> 0 | H29: =SUM(H11-H47) -> 0 | I29: =SUM(I11-I47) -> 0 | ... M29: =SUM(M11-M47) -> 0
B30: =SUM(B12-B48) -> 0 | C30: =SUM(C12-C48) -> 0 | D30: =SUM(D12-D48) -> 0 | E30: =SUM(E12-E48) -> 0 | F30: =SUM(F12-F48) -> 0 | G30: =SUM(G12-G48) -> 0 | H30: =SUM(H12-H48) -> 0 | I30: =SUM(I12-I48) -> 0 | ... M30: =SUM(M12-M48) -> 0
B31: =SUM(B13-B49) -> 0 | C31: =SUM(C13-C49) -> 0 | D31: =SUM(D13-D49) -> 0 | E31: =SUM(E13-E49) -> 0 | F31: =SUM(F13-F49) -> 0 | G31: =SUM(G13-G49) -> 0 | H31: =SUM(H13-H49) -> 0 | I31: =SUM(I13-I49) -> 0 | ... M31: =SUM(M13-M49) -> 0
B32: =SUM(B14-B50) -> 0 | C32: =SUM(C14-C50) -> 0 | D32: =SUM(D14-D50) -> 0 | E32: =SUM(E14-E50) -> 0 | F32: =SUM(F14-F50) -> 0 | G32: =SUM(G14-G50) -> 0 | H32: =SUM(H14-H50) -> 0 | I32: =SUM(I14-I50) -> 0 | ... M32: =SUM(M14-M50) -> 0
B33: =SUM(B15-B51) -> 0 | C33: =SUM(C15-C51) -> 0 | D33: =SUM(D15-D51) -> 0 | E33: =SUM(E15-E51) -> 0 | F33: =SUM(F15-F51) -> 0 | G33: =SUM(G15-G51) -> 0 | H33: =SUM(H15-H51) -> 0 | I33: =SUM(I15-I51) -> 0 | ... M33: =SUM(M15-M51) -> 0
B34: =SUM(B16-B52) -> 0 | C34: =SUM(C16-C52) -> 0 | D34: =SUM(D16-D52) -> 0 | E34: =SUM(E16-E52) -> 0 | F34: =SUM(F16-F52) -> 0 | G34: =SUM(G16-G52) -> 0 | H34: =SUM(H16-H52) -> 0 | I34: =SUM(I16-I52) -> 0 | ... M34: =SUM(M16-M52) -> 0
B35: =SUM(B17-B53) -> 0 | C35: =SUM(C17-C53) -> 0 | D35: =SUM(D17-D53) -> 0 | E35: =SUM(E17-E53) -> 0 | F35: =SUM(F17-F53) -> 0 | G35: =SUM(G17-G53) -> 0 | H35: =SUM(H17-H53) -> 0 | I35: =SUM(I17-I53) -> 0 | ... M35: =SUM(M17-M53) -> 0
B36: =SUM(B22:B35) -> -284 | C36: =SUM(C22:C35) -> -265 | D36: =SUM(D22:D35) -> -27 | E36: =SUM(E22:E35) -> -1180 | F36: =SUM(F22:F35) -> -1290 | G36: =SUM(G22:G35) -> -1300 | H36: =SUM(H22:H35) -> -660 | I36: =SUM(I22:I35) -> -860 | ... M36: =SUM(M22:M35) -> -1140
B38: Budget | C38: Budget | D38: Budget | E38: Budget | F38: Budget | G38: Budget | H38: Budget | I38: Budget | J38: Budget | K38: Budget | L38: Budget | M38: Budget
A39: ÅRSBUDGET POÄNG 2026 = | B39: =SUM(B40:B48) -> 1170 | C39: =SUM(C40:C48) -> 1175 | D39: =SUM(D40:D48) -> 1280 | E39: =SUM(E40:E48) -> 1180 | F39: =SUM(F40:F48) -> 1290 | G39: =SUM(G40:G48) -> 1300 | H39: =SUM(H40:H48) -> 660 | I39: =SUM(I40:I48) -> 860 | ... M39: =SUM(M40:M48) -> 1140
A40: Elin | B40: 140 | C40: 140 | D40: 160 | E40: 160 | F40: 160 | G40: 140 | H40: 70 | I40: 70 | J40: 160 | K40: 160 | L40: 160 | M40: 140
A41: Linnea | B41: 210 | C41: 225 | D41: 240 | E41: 220 | F41: 240 | G41: 220 | H41: 70 | I41: 180 | J41: 230 | K41: 200 | L41: 210 | M41: 170
A42: Nina | B42: 200 | C42: 200 | D42: 210 | E42: 170 | F42: 200 | G42: 180 | H42: 0 | I42: 200 | J42: 200 | K42: 200 | L42: 200 | M42: 150
A43: Emil | B43: 210 | C43: 180 | D43: 240 | E43: 220 | F43: 240 | G43: 200 | H43: 120 | I43: 120 | J43: 220 | K43: 240 | L43: 240 | M43: 170
A44: Rebecka | B44: 200 | C44: 220 | D44: 220 | E44: 200 | F44: 190 | G44: 200 | H44: 0 | I44: 230 | J44: 220 | K44: 220 | L44: 220 | M44: 170
A45: Agnes | B45: 210 | C45: 210 | D45: 210 | E45: 210 | F45: 200 | G45: 200 | H45: 200 | I45: 60 | J45: 240 | K45: 240 | L45: 240 | M45: 170
A46: Johanna | F46: 60 | G46: 160 | H46: 200 | I46: 0 | J46: 200 | K46: 220 | L46: 220 | M46: 170

Sheet Karlastaden
A1: Uttag poäng datum; | B1: 46063 | C1: 46086 | D1: 46106
B2: Jan | C2: Feb | D2: Mar | E2: Apr | F2: Maj | G2: Jun | H2: Jul | I2: Aug | J2: Sep | K2: Okt | L2: Nov | M2: Dec
A3: Ta ut från Verksamhetsportalen: | B3: Actual | C3: Actual | D3: Actual | E3: Actual | F3: Actual | G3: Actual | H3: Actual | I3: Actual | J3: Actual | K3: Actual | L3: Actual | M3: Actual
A4: Molly FT | B4: 109 | C4: 127 | D4: 153
A5: Fredrik FT | B5: 107 | C5: 100 | D5: 54
A6: AT timanst
A7: Agnes | B7: 0 | C7: 8 | D7: 70
A8: Elin M | B8: 2 | C8: 0 | D8: 29
A9: Emilia J | B9: 8
A10: Helena Ö | C10: 9
B18: =SUM(B4:B17) -> 226 | C18: =SUM(C4:C17) -> 244 | D18: =SUM(D4:D17) -> 306 | E18: =SUM(E4:E17) -> 0 | F18: =SUM(F4:F17) -> 0 | G18: =SUM(G4:G17) -> 0 | H18: =SUM(H4:H17) -> 0 | I18: =SUM(I4:I17) -> 0 | ... M18: =SUM(M4:M17) -> 0
B20: Jan | C20: Feb | D20: Mar | E20: Apr | F20: Maj | G20: Jun | H20: Jul | I20: Aug | J20: Sep | K20: Okt | L20: Nov | M20: Dec
B21: Diff | C21: Diff | D21: Diff | E21: Diff | F21: Diff | G21: Diff | H21: Diff | I21: Diff | J21: Diff | K21: Diff | L21: Diff | M21: Diff
A22: Molly FT | B22: =SUM(B4-B40) -> -83 | C22: =SUM(C4-C40) -> -65 | D22: =SUM(D4-D40) -> -63 | E22: =SUM(E4-E40) -> -200 | F22: =SUM(F4-F40) -> -200 | G22: =SUM(G4-G40) -> -180 | H22: =SUM(H4-H40) -> -80 | I22: =SUM(I4-I40) -> -80 | ... M22: =SUM(M4-M40) -> -180
A23: Fredrik FT | B23: =SUM(B5-B41) -> -53 | C23: =SUM(C5-C41) -> -90 | D23: =SUM(D5-D41) -> -156 | E23: =SUM(E5-E41) -> -220 | F23: =SUM(F5-F41) -> -220 | G23: =SUM(G5-G41) -> -200 | H23: =SUM(H5-H41) -> -100 | I23: =SUM(I5-I41) -> -140 | ... M23: =SUM(M5-M41) -> -180
A24: AT timanst | B24: =SUM(B6-B42) -> -100 | C24: =SUM(C6-C42) -> -100 | D24: =SUM(D6-D42) -> -100 | E24: =SUM(E6-E42) -> -100 | F24: =SUM(F6-F42) -> -100 | G24: =SUM(G6-G42) -> -100 | H24: =SUM(H6-H42) -> -45 | I24: =SUM(I6-I42) -> -45 | ... M24: =SUM(M6-M42) -> -80
B25: =SUM(B7-B43) -> 0 | C25: =SUM(C7-C43) -> 8 | D25: =SUM(D7-D43) -> 70 | E25: =SUM(E7-E43) -> 0 | F25: =SUM(F7-F43) -> 0 | G25: =SUM(G7-G43) -> 0 | H25: =SUM(H7-H43) -> 0 | I25: =SUM(I7-I43) -> 0 | ... M25: =SUM(M7-M43) -> 0
B26: =SUM(B8-B44) -> 2 | C26: =SUM(C8-C44) -> 0 | D26: =SUM(D8-D44) -> 29 | E26: =SUM(E8-E44) -> 0 | F26: =SUM(F8-F44) -> 0 | G26: =SUM(G8-G44) -> 0 | H26: =SUM(H8-H44) -> 0 | I26: =SUM(I8-I44) -> 0 | ... M26: =SUM(M8-M44) -> 0
B27: =SUM(B9-B45) -> 8 | C27: =SUM(C9-C45) -> 0 | D27: =SUM(D9-D45) -> 0 | E27: =SUM(E9-E45) -> 0 | F27: =SUM(F9-F45) -> 0 | G27: =SUM(G9-G45) -> 0 | H27: =SUM(H9-H45) -> 0 | I27: =SUM(I9-I45) -> 0 | ... M27: =SUM(M9-M45) -> 0
B28: =SUM(B10-B46) -> 0 | C28: =SUM(C10-C46) -> 9 | D28: =SUM(D10-D46) -> 0 | E28: =SUM(E10-E46) -> 0 | F28: =SUM(F10-F46) -> 0 | G28: =SUM(G10-G46) -> 0 | H28: =SUM(H10-H46) -> 0 | I28: =SUM(I10-I46) -> 0 | ... M28: =SUM(M10-M46) -> 0
B29: =SUM(B11-B47) -> 0 | C29: =SUM(C11-C47) -> 0 | D29: =SUM(D11-D47) -> 0 | E29: =SUM(E11-E47) -> 0 | F29: =SUM(F11-F47) -> 0 | G29: =SUM(G11-G47) -> 0 | H29: =SUM(H11-H47) -> 0 | I29: =SUM(I11-I47) -> 0 | ... M29: =SUM(M11-M47) -> 0
B30: =SUM(B12-B48) -> 0 | C30: =SUM(C12-C48) -> 0 | D30: =SUM(D12-D48) -> 0 | E30: =SUM(E12-E48) -> 0 | F30: =SUM(F12-F48) -> 0 | G30: =SUM(G12-G48) -> 0 | H30: =SUM(H12-H48) -> 0 | I30: =SUM(I12-I48) -> 0 | ... M30: =SUM(M12-M48) -> 0
B31: =SUM(B13-B49) -> 0 | C31: =SUM(C13-C49) -> 0 | D31: =SUM(D13-D49) -> 0 | E31: =SUM(E13-E49) -> 0 | F31: =SUM(F13-F49) -> 0 | G31: =SUM(G13-G49) -> 0 | H31: =SUM(H13-H49) -> 0 | I31: =SUM(I13-I49) -> 0 | ... M31: =SUM(M13-M49) -> 0
B32: =SUM(B14-B50) -> 0 | C32: =SUM(C14-C50) -> 0 | D32: =SUM(D14-D50) -> 0 | E32: =SUM(E14-E50) -> 0 | F32: =SUM(F14-F50) -> 0 | G32: =SUM(G14-G50) -> 0 | H32: =SUM(H14-H50) -> 0 | I32: =SUM(I14-I50) -> 0 | ... M32: =SUM(M14-M50) -> 0
B33: =SUM(B15-B51) -> 0 | C33: =SUM(C15-C51) -> 0 | D33: =SUM(D15-D51) -> 0 | E33: =SUM(E15-E51) -> 0 | F33: =SUM(F15-F51) -> 0 | G33: =SUM(G15-G51) -> 0 | H33: =SUM(H15-H51) -> 0 | I33: =SUM(I15-I51) -> 0 | ... M33: =SUM(M15-M51) -> 0
B34: =SUM(B16-B52) -> 0 | C34: =SUM(C16-C52) -> 0 | D34: =SUM(D16-D52) -> 0 | E34: =SUM(E16-E52) -> 0 | F34: =SUM(F16-F52) -> 0 | G34: =SUM(G16-G52) -> 0 | H34: =SUM(H16-H52) -> 0 | I34: =SUM(I16-I52) -> 0 | ... M34: =SUM(M16-M52) -> 0
B35: =SUM(B17-B53) -> 0 | C35: =SUM(C17-C53) -> 0 | D35: =SUM(D17-D53) -> 0 | E35: =SUM(E17-E53) -> 0 | F35: =SUM(F17-F53) -> 0 | G35: =SUM(G17-G53) -> 0 | H35: =SUM(H17-H53) -> 0 | I35: =SUM(I17-I53) -> 0 | ... M35: =SUM(M17-M53) -> 0
B36: =SUM(B22:B35) -> -226 | C36: =SUM(C22:C35) -> -238 | D36: =SUM(D22:D35) -> -220 | E36: =SUM(E22:E35) -> -520 | F36: =SUM(F22:F35) -> -520 | G36: =SUM(G22:G35) -> -480 | H36: =SUM(H22:H35) -> -225 | I36: =SUM(I22:I35) -> -265 | ... M36: =SUM(M22:M35) -> -440
B38: Budget | C38: Budget | D38: Budget | E38: Budget | F38: Budget | G38: Budget | H38: Budget | I38: Budget | J38: Budget | K38: Budget | L38: Budget | M38: Budget
A39: ÅRSBUDGET POÄNG 2026 = | B39: =SUM(B40:B48) -> 452 | C39: =SUM(C40:C48) -> 482 | D39: =SUM(D40:D48) -> 526 | E39: =SUM(E40:E48) -> 520 | F39: =SUM(F40:F48) -> 520 | G39: =SUM(G40:G48) -> 480 | H39: =SUM(H40:H48) -> 225 | I39: =SUM(I40:I48) -> 265 | ... M39: =SUM(M40:M48) -> 440
A40: Molly FT | B40: 192 | C40: 192 | D40: 216 | E40: 200 | F40: 200 | G40: 180 | H40: 80 | I40: 80 | J40: 200 | K40: 216 | L40: 216 | M40: 180
A41: Fredrik FT | B41: 160 | C41: 190 | D41: 210 | E41: 220 | F41: 220 | G41: 200 | H41: 100 | I41: 140 | J41: 240 | K41: 240 | L41: 240 | M41: 180
A42: AT timanst | B42: 100 | C42: 100 | D42: 100 | E42: 100 | F42: 100 | G42: 100 | H42: 45 | I42: 45 | J42: 100 | K42: 100 | L42: 100 | M42: 80
